Workbook

Sheet UK_PL_EUR
A1: NetSuite Financial Report Export | B1: Helios Software Ltd — management accounts | E1: Exported 13-Jul-2026
G2: ACTUAL — posted / controller adjustments | AF2: BUDGET — approved operating plan
A3: Legal entity | B3: Department | C3: Cost centre | D3: Account code | E3: Account name | F3: Unit | G3: Jan-2024 | H3: Feb-2024 | I3: Mar-2024 | J3: Apr-2024 | K3: May-2024 | L3: Jun-2024 | M3: Jul-2024 | N3: Aug-2024 | O3: Sept-2024 | P3: Oct-2024 | Q3: Nov-2024 | R3: Dec-2024 | S3: Jan-2025 | T3: Feb-2025 | U3: Mar-2025 | V3: Apr-2025 | W3: May-2025 | X3: Jun-2025 | Y3: Jul-2025 | Z3: Aug-2025 | AA3: Sept-2025 | AB3: Oct-2025 | AC3: Nov-2025 | AD3: Dec-2025 | AF3: Jan-2024 | AG3: Feb-2024 | AH3: Mar-2024 | AI3: Apr-2024 | AJ3: May-2024 | AK3: Jun-2024 | AL3: Jul-2024 | AM3: Aug-2024 | AN3: Sept-2024 | AO3: Oct-2024 | AP3: Nov-2024 | AQ3: Dec-2024 | AR3: Jan-2025 | AS3: Feb-2025 | AT3: Mar-2025 | AU3: Apr-2025 | AV3: May-2025 | AW3: Jun-2025 | AX3: Jul-2025 | AY3: Aug-2025 | AZ3: Sept-2025 | BA3: Oct-2025 | BB3: Nov-2025 | BC3: Dec-2025
A4: Helios Software Ltd | B4: Commercial - EMEA | C4: CC-110 | D4: 4000 | E4: SaaS Recurring–EMEA | F4: EUR '000 | G4: 2352 | H4: 2429.5 | I4: 2534.3 | J4: 2565.7 | K4: 2675.9 | L4: 2762.9 | M4: 2715.4 | N4: 2720.4 | O4: 2896.3 | P4: 2990.8 | Q4: 3148 | R4: 3372.1 | S4: 3071.8 | T4: 3173 | U4: 3309.9 | V4: 3350.9 | W4: 3494.8 | X4: 3608.5 | Y4: 3546.4 | Z4: 3552.9 | AA4: 3782.7 | AB4: 3906.1 | AC4: 4111.4 | AD4: 4404.1 | AF4: 2240 | AG4: 2291.9811 | AH4: 2725.0538 | AI4: 2788.8043 | AJ4: 2454.9541 | AK4: 2511.7273 | AL4: 2858.3158 | AM4: 2894.0426 | AN4: 2706.8224 | AO4: 2769.2593 | AP4: 3459.3407 | AQ4: 3746.7778 | AR4: 2925.5238 | AS4: 2993.3962 | AT4: 3559.0323 | AU4: 3642.2826 | AV4: 3206.2385 | AW4: 3280.4545 | AX4: 3733.0526 | AY4: 3779.6809 | AZ4: 3535.2336 | BA4: 3616.7593 | BB4: 4518.022 | BC4: 4893.4444
A5: Helios Software Ltd | B5: Commercial - EMEA | C5: CC-110 | D5: 4000 | E5: SaaS Recurring–EMEA / enterprise | F5: EUR '000 | G5: 509.6 | H5: 526.4 | I5: 549.1 | J5: 555.9 | K5: 579.8 | L5: 598.6 | M5: 588.3 | N5: 589.4 | O5: 627.5 | P5: 648 | Q5: 682.1 | R5: 730.6 | S5: 665.6 | T5: 687.5 | U5: 717.2 | V5: 726 | W5: 757.2 | X5: 781.8 | Y5: 768.4 | Z5: 769.8 | AA5: 819.6 | AB5: 846.3 | AC5: 890.8 | AD5: 954.2 | AF5: 480.75472 | AG5: 491.96262 | AH5: 596.84783 | AI5: 610.87912 | AJ5: 527.09091 | AK5: 570.09524 | AL5: 625.85106 | AM5: 633.76344 | AN5: 581.01852 | AO5: 594.49541 | AP5: 757.88889 | AQ5: 769.05263 | AR5: 627.92453 | AS5: 642.52336 | AT5: 779.56522 | AU5: 797.8022 | AV5: 688.36364 | AW5: 744.57143 | AX5: 817.44681 | AY5: 827.74194 | AZ5: 758.88889 | BA5: 776.42202 | BB5: 989.77778 | BC5: 1004.4211
A6: Helios Software Ltd | B6: Commercial - EMEA | C6: CC-110 | D6: 4100 | E6: Implementation & Onboarding | F6: EUR '000 | G6: 254.8 | H6: 261.3 | I6: 270.5 | J6: 271.9 | K6: 281.5 | L6: 288.5 | M6: 281.5 | N6: 279.9 | O6: 295.8 | P6: 303.2 | Q6: 316.8 | R6: 336.9 | S6: 304.6 | T6: 312.4 | U6: 323.5 | V6: 325.1 | W6: 336.5 | X6: 344.9 | Y6: 336.5 | Z6: 334.7 | AA6: 353.7 | AB6: 362.5 | AC6: 378.8 | AD6: 402.8 | AF6: 238.13084 | AG6: 241.94444 | AH6: 297.25275 | AI6: 302.11111 | AJ6: 268.09524 | AK6: 272.16981 | AL6: 302.68817 | AM6: 304.23913 | AN6: 271.37615 | AO6: 275.63636 | AP6: 333.47368 | AQ6: 358.40426 | AR6: 284.6729 | AS6: 289.25926 | AT6: 355.49451 | AU6: 361.22222 | AV6: 320.47619 | AW6: 325.37736 | AX6: 361.82796 | AY6: 363.80435 | AZ6: 324.49541 | BA6: 329.54545 | BB6: 398.73684 | BC6: 428.51064
A7: Helios Software Ltd | B7: Commercial - EMEA | C7: -- | D7: SUB | E7: Commercial EMEA ledger subtotal | F7: EUR '000 | G7: =SUM(G4:G6) -> 3116.4 | H7: =SUM(H4:H6) -> 3217.2 | I7: =SUM(I4:I6) -> 3353.9 | J7: =SUM(J4:J6) -> 3393.5 | K7: =SUM(K4:K6) -> 3537.2 | L7: =SUM(L4:L6) -> 3650 | M7: =SUM(M4:M6) -> 3585.2 | N7: =SUM(N4:N6) -> 3589.7 | ... AD7: =SUM(AD4:AD6) -> 5761.1 | AF7: =SUM(AF4:AF6) -> 2958.8856 | AG7: =SUM(AG4:AG6) -> 3025.8882 | AH7: =SUM(AH4:AH6) -> 3619.1543 | AI7: =SUM(AI4:AI6) -> 3701.7946 | AJ7: =SUM(AJ4:AJ6) -> 3250.1403 | AK7: =SUM(AK4:AK6) -> 3353.9923 | AL7: =SUM(AL4:AL6) -> 3786.855 | AM7: =SUM(AM4:AM6) -> 3832.0451 | ... BC7: =SUM(BC4:BC6) -> 6326.3761
A9: Helios Software Ltd | B9: Commercial - Americas | C9: CC-120 | D9: 4010 | E9: SaaS Recurring–Americas | F9: EUR '000 | G9: 1097.6 | H9: 1133.7 | I9: 1182.7 | J9: 1197.3 | K9: 1248.7 | L9: 1289.4 | M9: 1267.2 | N9: 1269.5 | O9: 1351.6 | P9: 1395.7 | Q9: 1469.1 | R9: 1573.6 | S9: 1433.5 | T9: 1480.7 | U9: 1544.6 | V9: 1563.8 | W9: 1630.9 | X9: 1684 | Y9: 1655 | Z9: 1658 | AA9: 1765.2 | AB9: 1822.8 | AC9: 1918.7 | AD9: 2055.3 | AF9: 997.81818 | AG9: 1079.7143 | AH9: 1258.1915 | AI9: 1287.4194 | AJ9: 1156.2037 | AK9: 1182.9358 | AL9: 1408 | AM9: 1336.3158 | AN9: 1275.0943 | AO9: 1304.3925 | AP9: 1596.8478 | AQ9: 1729.2308 | AR9: 1303.1818 | AS9: 1410.1905 | AT9: 1643.1915 | AU9: 1681.5054 | AV9: 1510.0926 | AW9: 1544.9541 | AX9: 1838.8889 | AY9: 1745.2632 | AZ9: 1665.283 | BA9: 1703.5514 | BB9: 2085.5435 | BC9: 2258.5714
A10: Helios Software Ltd | B10: Commercial - Americas | C10: CC-120 | D10: 4010 | E10: SaaS Recurring–Americas / enterprise | F10: EUR '000 | G10: 274.4 | H10: 283.4 | I10: 295.7 | J10: 299.3 | K10: 312.2 | L10: 322.3 | M10: 316.8 | N10: 317.4 | O10: 337.9 | P10: 348.9 | Q10: 367.3 | R10: 393.4 | S10: 358.4 | T10: 370.2 | U10: 386.2 | V10: 390.9 | W10: 407.7 | X10: 421 | Y10: 413.7 | Z10: 414.5 | AA10: 441.3 | AB10: 455.7 | AC10: 479.7 | AD10: 513.8 | AF10: 261.33333 | AG10: 267.35849 | AH10: 317.95699 | AI10: 325.32609 | AJ10: 286.42202 | AK10: 293 | AL10: 333.47368 | AM10: 337.65957 | AN10: 315.79439 | AO10: 323.05556 | AP10: 403.62637 | AQ10: 437.11111 | AR10: 341.33333 | AS10: 349.24528 | AT10: 415.26882 | AU10: 424.8913 | AV10: 374.0367 | AW10: 382.72727 | AX10: 435.47368 | AY10: 440.95745 | AZ10: 412.42991 | BA10: 421.94444 | BB10: 527.14286 | BC10: 570.88889
A11: Helios Software Ltd | B11: Commercial - Americas | C11: CC-120 | D11: 4100 | E11: Implementation & Onboarding / Americas | F11: EUR '000 | G11: 93.1 | H11: 95.5 | I11: 98.9 | J11: 99.3 | K11: 102.8 | L11: 105.4 | M11: 102.8 | N11: 102.3 | O11: 108.1 | P11: 110.8 | Q11: 115.8 | R11: 123.1 | S11: 111.3 | T11: 114.1 | U11: 118.2 | V11: 118.8 | W11: 123 | X11: 126 | Y11: 123 | Z11: 122.3 | AA11: 129.2 | AB11: 132.5 | AC11: 138.4 | AD11: 147.2 | AF11: 87.830189 | AG11: 89.252336 | AH11: 107.5 | AI11: 109.12088 | AJ11: 93.454545 | AK11: 100.38095 | AL11: 109.3617 | AM11: 110 | AN11: 100.09259 | AO11: 101.65138 | AP11: 128.66667 | AQ11: 129.57895 | AR11: 105 | AS11: 106.63551 | AT11: 128.47826 | AU11: 130.54945 | AV11: 111.81818 | AW11: 120 | AX11: 130.85106 | AY11: 131.50538 | AZ11: 119.62963 | BA11: 121.55963 | BB11: 153.77778 | BC11: 154.94737
A12: Helios Software Ltd | B12: Commercial - Americas | C12: -- | D12: SUB | E12: Commercial Americas ledger subtotal | F12: EUR '000 | G12: =SUM(G9:G11) -> 1465.1 | H12: =SUM(H9:H11) -> 1512.6 | I12: =SUM(I9:I11) -> 1577.3 | J12: =SUM(J9:J11) -> 1595.9 | K12: =SUM(K9:K11) -> 1663.7 | L12: =SUM(L9:L11) -> 1717.1 | M12: =SUM(M9:M11) -> 1686.8 | N12: =SUM(N9:N11) -> 1689.2 | ... AD12: =SUM(AD9:AD11) -> 2716.3 | AF12: =SUM(AF9:AF11) -> 1346.9817 | AG12: =SUM(AG9:AG11) -> 1436.3251 | AH12: =SUM(AH9:AH11) -> 1683.6485 | AI12: =SUM(AI9:AI11) -> 1721.8663 | AJ12: =SUM(AJ9:AJ11) -> 1536.0803 | AK12: =SUM(AK9:AK11) -> 1576.3167 | AL12: =SUM(AL9:AL11) -> 1850.8354 | AM12: =SUM(AM9:AM11) -> 1783.9754 | ... BC12: =SUM(BC9:BC11) -> 2984.4077
A14: Helios Software Ltd | B14: Commercial - APAC | C14: CC-130 | D14: 4020 | E14: SaaS Recurring–APAC | F14: EUR '000 | G14: 421.4 | H14: 435.3 | I14: 454.1 | J14: 459.7 | K14: 479.4 | L14: 495 | M14: 486.5 | N14: 487.4 | O14: 518.9 | P14: 535.8 | Q14: 564 | R14: 604.2 | S14: 550.4 | T14: 568.5 | U14: 593 | V14: 600.4 | W14: 626.2 | X14: 646.5 | Y14: 635.4 | Z14: 636.6 | AA14: 677.7 | AB14: 699.8 | AC14: 736.6 | AD14: 789.1 | AF14: 386.6055 | AG14: 395.72727 | AH14: 478 | AI14: 489.04255 | AJ14: 448.03738 | AK14: 458.33333 | AL14: 534.61538 | AM14: 541.55556 | AN14: 494.19048 | AO14: 505.4717 | AP14: 606.45161 | AQ14: 656.73913 | AR14: 504.95413 | AS14: 516.81818 | AT14: 624.21053 | AU14: 638.7234 | AV14: 585.23364 | AW14: 598.61111 | AX14: 698.24176 | AY14: 707.33333 | AZ14: 645.42857 | BA14: 660.18868 | BB14: 792.04301 | BC14: 857.71739
A15: Helios Software Ltd | B15: Commercial - APAC | C15: CC-130 | D15: 4100 | E15: Implementation & Onboarding / APAC | F15: EUR '000 | G15: 44.1 | H15: 45.2 | I15: 46.8 | J15: 47.1 | K15: 48.7 | L15: 49.9 | M15: 48.7 | N15: 48.4 | O15: 51.2 | P15: 52.5 | Q15: 54.8 | R15: 58.3 | S15: 52.7 | T15: 54.1 | U15: 56 | V15: 56.3 | W15: 58.2 | X15: 59.7 | Y15: 58.2 | Z15: 57.9 | AA15: 61.2 | AB15: 62.7 | AC15: 65.6 | AD15: 69.7 | AF15: 40.090909 | AG15: 43.047619 | AH15: 49.787234 | AI15: 50.645161 | AJ15: 45.092593 | AK15: 45.779817 | AL15: 54.111111 | AM15: 50.947368 | AN15: 48.301887 | AO15: 49.065421 | AP15: 59.565217 | AQ15: 64.065934 | AR15: 47.909091 | AS15: 51.52381 | AT15: 59.574468 | AU15: 60.537634 | AV15: 53.888889 | AW15: 54.770642 | AX15: 64.666667 | AY15: 60.947368 | AZ15: 57.735849 | BA15: 58.598131 | BB15: 71.304348 | BC15: 76.593407
A16: Helios Software Ltd | B16: Commercial - APAC | C16: -- | D16: SUB | E16: Commercial APAC ledger subtotal | F16: EUR '000 | G16: =SUM(G14:G15) -> 465.5 | H16: =SUM(H14:H15) -> 480.5 | I16: =SUM(I14:I15) -> 500.9 | J16: =SUM(J14:J15) -> 506.8 | K16: =SUM(K14:K15) -> 528.1 | L16: =SUM(L14:L15) -> 544.9 | M16: =SUM(M14:M15) -> 535.2 | N16: =SUM(N14:N15) -> 535.8 | ... AD16: =SUM(AD14:AD15) -> 858.8 | AF16: =SUM(AF14:AF15) -> 426.69641 | AG16: =SUM(AG14:AG15) -> 438.77489 | AH16: =SUM(AH14:AH15) -> 527.78723 | AI16: =SUM(AI14:AI15) -> 539.68771 | AJ16: =SUM(AJ14:AJ15) -> 493.12998 | AK16: =SUM(AK14:AK15) -> 504.11315 | AL16: =SUM(AL14:AL15) -> 588.7265 | AM16: =SUM(AM14:AM15) -> 592.50292 | ... BC16: =SUM(BC14:BC15) -> 934.3108
A18: Helios Software Ltd | B18: Customer Operations | C18: CC-210 | D18: 4110 | E18: Managed Services | F18: EUR '000 | G18: 220.5 | H18: 226.1 | I18: 234.1 | J18: 235.3 | K18: 243.6 | L18: 249.7 | M18: 243.6 | N18: 242.2 | O18: 256 | P18: 262.4 | Q18: 274.2 | R18: 291.5 | S18: 263.6 | T18: 270.3 | U18: 279.9 | V18: 281.3 | W18: 291.2 | X18: 298.5 | Y18: 291.2 | Z18: 289.6 | AA18: 306.1 | AB18: 313.7 | AC18: 327.8 | AD18: 348.6 | AF18: 206.07477 | AG18: 209.35185 | AH18: 257.25275 | AI18: 261.44444 | AJ18: 232 | AK18: 235.56604 | AL18: 261.93548 | AM18: 263.26087 | AN18: 234.86239 | AO18: 238.54545 | AP18: 288.63158 | AQ18: 310.10638 | AR18: 246.35514 | AS18: 250.27778 | AT18: 307.58242 | AU18: 312.55556 | AV18: 277.33333 | AW18: 281.60377 | AX18: 313.11828 | AY18: 314.78261 | AZ18: 280.82569 | BA18: 285.18182 | BB18: 345.05263 | BC18: 370.85106
A19: Helios Software Ltd | B19: Customer Operations | C19: CC-210 | D19: 4200 | E19: Training & Certification | F19: EUR '000 | G19: 60.8 | H19: 62.3 | I19: 64.5 | J19: 64.8 | K19: 67.1 | L19: 68.8 | M19: 67.1 | N19: 66.7 | O19: 70.5 | P19: 72.3 | Q19: 75.6 | R19: 80.3 | S19: 72.6 | T19: 74.5 | U19: 77.1 | V19: 77.5 | W19: 80.3 | X19: 82.3 | Y19: 80.2 | Z19: 79.8 | AA19: 84.3 | AB19: 86.5 | AC19: 90.3 | AD19: 96.1 | AF19: 56.296296 | AG19: 57.155963 | AH19: 71.666667 | AI19: 68.210526 | AJ19: 63.301887 | AK19: 64.299065 | AL19: 72.934783 | AM19: 73.296703 | AN19: 64.090909 | AO19: 68.857143 | AP19: 80.425532 | AQ19: 86.344086 | AR19: 67.222222 | AS19: 68.348624 | AT19: 85.666667 | AU19: 81.578947 | AV19: 75.754717 | AW19: 76.915888 | AX19: 87.173913 | AY19: 87.692308 | AZ19: 76.636364 | BA19: 82.380952 | BB19: 96.06383 | BC19: 103.33333
A20: Helios Software Ltd | B20: Customer Operations | C20: CC-210 | D20: 5200 | E20: Support salaries | F20: EUR '000 | G20: -360 | H20: -366.5 | I20: -373.1 | J20: -379.8 | K20: -386.6 | L20: -393.6 | M20: -400.7 | N20: -407.9 | O20: -415.2 | P20: -422.7 | Q20: -430.3 | R20: -438.1 | S20: -445.9 | T20: -454 | U20: -462.1 | V20: -470.5 | W20: -478.9 | X20: -487.5 | Y20: -496.3 | Z20: -505.3 | AA20: -514.3 | AB20: -523.6 | AC20: -533 | AD20: -542.6 | AF20: -330.27523 | AG20: -333.18182 | AH20: -392.73684 | AI20: -404.04255 | AJ20: -361.30841 | AK20: -364.44444 | AL20: -440.32967 | AM20: -453.22222 | AN20: -395.42857 | AO20: -398.77358 | AP20: -462.68817 | AQ20: -476.19565 | AR20: -409.08257 | AS20: -412.72727 | AT20: -486.42105 | AU20: -500.53191 | AV20: -447.57009 | AW20: -451.38889 | AX20: -545.38462 | AY20: -561.44444 | AZ20: -489.80952 | BA20: -493.96226 | BB20: -573.11828 | BC20: -589.78261
A21: Helios Software Ltd | B21: Customer Operations | C21: CC-210 | D21: 5210 | E21: Support contractors | F21: EUR '000 | G21: -82 | H21: -83 | I21: -84 | J21: -85 | K21: -86 | L21: -87 | M21: -88.1 | N21: -89.1 | O21: -90.2 | P21: -91.3 | Q21: -92.4 | R21: -93.5 | S21: -94.6 | T21: -95.8 | U21: -96.9 | V21: -98.1 | W21: -99.2 | X21: -100.4 | Y21: -101.6 | Z21: -102.9 | AA21: -104.1 | AB21: -105.3 | AC21: -106.6 | AD21: -107.9 | AF21: -74.545455 | AG21: -79.047619 | AH21: -89.361702 | AI21: -91.397849 | AJ21: -79.62963 | AK21: -79.816514 | AL21: -97.888889 | AM21: -93.789474 | AN21: -85.09434 | AO21: -85.327103 | AP21: -100.43478 | AQ21: -102.74725 | AR21: -86 | AS21: -91.238095 | AT21: -103.08511 | AU21: -105.48387 | AV21: -91.851852 | AW21: -92.110092 | AX21: -112.88889 | AY21: -108.31579 | AZ21: -98.207547 | BA21: -98.411215 | BB21: -115.86957 | BC21: -118.57143
A22: Helios Software Ltd | B22: Customer Operations | C22: CC-210 | D22: 5220 | E22: Support tooling & telephony | F22: EUR '000 | G22: -36 | H22: -36.4 | I22: -36.9 | J22: -37.3 | K22: -37.8 | L22: -38.2 | M22: -38.7 | N22: -39.1 | O22: -39.6 | P22: -40.1 | Q22: -40.6 | R22: -41 | S22: -41.5 | T22: -42 | U22: -42.5 | V22: -43.1 | W22: -43.6 | X22: -44.1 | Y22: -44.6 | Z22: -45.2 | AA22: -45.7 | AB22: -46.2 | AC22: -46.8 | AD22: -47.4 | AF22: -34.285714 | AG22: -34.339623 | AH22: -39.677419 | AI22: -40.543478 | AJ22: -34.678899 | AK22: -34.727273 | AL22: -40.736842 | AM22: -41.595745 | AN22: -37.009346 | AO22: -37.12963 | AP22: -44.615385 | AQ22: -45.555556 | AR22: -39.52381 | AS22: -39.622642 | AT22: -45.698925 | AU22: -46.847826 | AV22: -40 | AW22: -40.090909 | AX22: -46.947368 | AY22: -48.085106 | AZ22: -42.71028 | BA22: -42.777778 | BB22: -51.428571 | BC22: -52.666667
A23: Helios Software Ltd | B23: Customer Operations | C23: -- | D23: SUB | E23: Customer Operations ledger subtotal | F23: EUR '000 | G23: =SUM(G18:G22) -> -196.7 | H23: =SUM(H18:H22) -> -197.5 | I23: =SUM(I18:I22) -> -195.4 | J23: =SUM(J18:J22) -> -202 | K23: =SUM(K18:K22) -> -199.7 | L23: =SUM(L18:L22) -> -200.3 | M23: =SUM(M18:M22) -> -216.8 | N23: =SUM(N18:N22) -> -227.2 | ... AD23: =SUM(AD18:AD22) -> -253.2 | AF23: =SUM(AF18:AF22) -> -176.73534 | AG23: =SUM(AG18:AG22) -> -180.06124 | AH23: =SUM(AH18:AH22) -> -192.85655 | AI23: =SUM(AI18:AI22) -> -206.32891 | AJ23: =SUM(AJ18:AJ22) -> -180.31505 | AK23: =SUM(AK18:AK22) -> -179.12313 | AL23: =SUM(AL18:AL22) -> -244.08513 | AM23: =SUM(AM18:AM22) -> -252.04987 | ... BC23: =SUM(BC18:BC22) -> -286.83631
A25: Helios Software Ltd | B25: Alliances | C25: CC-140 | D25: 4300 | E25: Partner/Reseller | F25: EUR '000 | G25: 186.2 | H25: 190.9 | I25: 197.7 | J25: 198.7 | K25: 205.7 | L25: 210.8 | M25: 205.7 | N25: 204.5 | O25: 216.2 | P25: 221.6 | Q25: 231.5 | R25: 246.2 | S25: 222.6 | T25: 228.3 | U25: 236.4 | V25: 237.5 | W25: 245.9 | X25: 252.1 | Y25: 245.9 | Z25: 244.6 | AA25: 258.5 | AB25: 264.9 | AC25: 276.8 | AD25: 294.4 | AF25: 172.40741 | AG25: 175.13761 | AH25: 219.66667 | AI25: 209.15789 | AJ25: 194.0566 | AK25: 197.00935 | AL25: 223.58696 | AM25: 224.72527 | AN25: 196.54545 | AO25: 211.04762 | AP25: 246.2766 | AQ25: 264.73118 | AR25: 206.11111 | AS25: 209.44954 | AT25: 262.66667 | AU25: 250 | AV25: 231.98113 | AW25: 235.60748 | AX25: 267.28261 | AY25: 268.79121 | AZ25: 235 | BA25: 252.28571 | BB25: 294.46809 | BC25: 316.55914
A26: Helios Software Ltd | B26: Alliances | C26: CC-140 | D26: 4900 | E26: Other income | F26: EUR '000 | G26: 28 | H26: 28.1 | I26: 28.2 | J26: 28.3 | K26: 28.5 | L26: 28.6 | M26: 28.7 | N26: 28.8 | O26: 28.9 | P26: 29 | Q26: 29.1 | R26: 29.3 | S26: 29.4 | T26: 29.5 | U26: 29.6 | V26: 29.7 | W26: 29.8 | X26: 30 | Y26: 30.1 | Z26: 30.2 | AA26: 30.3 | AB26: 30.4 | AC26: 30.6 | AD26: 30.7 | AF26: 25.688073 | AG26: 25.545455 | AH26: 29.684211 | AI26: 30.106383 | AJ26: 26.635514 | AK26: 26.481481 | AL26: 31.538462 | AM26: 32 | AN26: 27.52381 | AO26: 27.358491 | AP26: 31.290323 | AQ26: 31.847826 | AR26: 26.972477 | AS26: 26.818182 | AT26: 31.157895 | AU26: 31.595745 | AV26: 27.850467 | AW26: 27.777778 | AX26: 33.076923 | AY26: 33.555556 | AZ26: 28.857143 | BA26: 28.679245 | BB26: 32.903226 | BC26: 33.369565
A27: Helios Software Ltd | B27: Alliances | C27: CC-140 | D27: 6010 | E27: Sales commissions / channel | F27: EUR '000 | G27: -48 | H27: -48.6 | I27: -49.2 | J27: -49.7 | K27: -50.3 | L27: -50.9 | M27: -51.6 | N27: -52.2 | O27: -52.8 | P27: -53.4 | Q27: -54.1 | R27: -54.7 | S27: -55.4 | T27: -56.1 | U27: -56.7 | V27: -57.4 | W27: -58.1 | X27: -58.8 | Y27: -59.5 | Z27: -60.2 | AA27: -60.9 | AB27: -61.7 | AC27: -62.4 | AD27: -63.2 | AF27: -43.636364 | AG27: -46.285714 | AH27: -52.340426 | AI27: -53.44086 | AJ27: -46.574074 | AK27: -46.697248 | AL27: -57.333333 | AM27: -54.947368 | AN27: -49.811321 | AO27: -49.906542 | AP27: -58.804348 | AQ27: -60.10989 | AR27: -50.363636 | AS27: -53.428571 | AT27: -60.319149 | AU27: -61.72043 | AV27: -53.796296 | AW27: -53.944954 | AX27: -66.111111 | AY27: -63.368421 | AZ27: -57.45283 | BA27: -57.663551 | BB27: -67.826087 | BC27: -69.450549
A28: Helios Software Ltd | B28: Alliances | C28: -- | D28: SUB | E28: Alliances ledger subtotal | F28: EUR '000 | G28: =SUM(G25:G27) -> 166.2 | H28: =SUM(H25:H27) -> 170.4 | I28: =SUM(I25:I27) -> 176.7 | J28: =SUM(J25:J27) -> 177.3 | K28: =SUM(K25:K27) -> 183.9 | L28: =SUM(L25:L27) -> 188.5 | M28: =SUM(M25:M27) -> 182.8 | N28: =SUM(N25:N27) -> 181.1 | ... AD28: =SUM(AD25:AD27) -> 261.9 | AF28: =SUM(AF25:AF27) -> 154.45912 | AG28: =SUM(AG25:AG27) -> 154.39735 | AH28: =SUM(AH25:AH27) -> 197.01045 | AI28: =SUM(AI25:AI27) -> 185.82342 | AJ28: =SUM(AJ25:AJ27) -> 174.11804 | AK28: =SUM(AK25:AK27) -> 176.79358 | AL28: =SUM(AL25:AL27) -> 197.79208 | AM28: =SUM(AM25:AM27) -> 201.77791 | ... BC28: =SUM(BC25:BC27) -> 280.47816
A30: Helios Software Ltd | B30: Cloud Operations | C30: CC-220 | D30: 5000 | E30: Cloud hosting–AWS | F30: EUR '000 | G30: -420 | H30: -428.8 | I30: -437.8 | J30: -447 | K30: -456.4 | L30: -466 | M30: -475.8 | N30: -485.8 | O30: -496 | P30: -506.4 | Q30: -517 | R30: -527.9 | S30: -539 | T30: -550.3 | U30: -561.8 | V30: -573.6 | W30: -585.7 | X30: -598 | Y30: -610.5 | Z30: -623.4 | AA30: -636.4 | AB30: -649.8 | AC30: -663.5 | AD30: -677.4 | AF30: -392.52336 | AG30: -397.03704 | AH30: -481.0989 | AI30: -496.66667 | AJ30: -434.66667 | AK30: -439.62264 | AL30: -511.6129 | AM30: -528.04348 | AN30: -455.04587 | AO30: -460.36364 | AP30: -544.21053 | AQ30: -561.59574 | AR30: -503.73832 | AS30: -509.53704 | AT30: -617.36264 | AU30: -637.33333 | AV30: -557.80952 | AW30: -564.15094 | AX30: -656.45161 | AY30: -677.6087 | AZ30: -583.85321 | BA30: -590.72727 | BB30: -698.42105 | BC30: -720.6383
A31: Helios Software Ltd | B31: Cloud Operations | C31: CC-220 | D31: 5010 | E31: Cloud hosting–Azure | F31: EUR '000 | G31: -138 | H31: -140.9 | I31: -143.9 | J31: -146.9 | K31: -150 | L31: -153.1 | M31: -156.3 | N31: -159.6 | O31: -163 | P31: -166.4 | Q31: -169.9 | R31: -173.4 | S31: -177.1 | T31: -180.8 | U31: -184.6 | V31: -188.5 | W31: -192.4 | X31: -196.5 | Y31: -200.6 | Z31: -204.8 | AA31: -209.1 | AB31: -213.5 | AC31: -218 | AD31: -222.6 | AF31: -127.77778 | AG31: -129.26606 | AH31: -159.88889 | AI31: -154.63158 | AJ31: -141.50943 | AK31: -143.08411 | AL31: -169.8913 | AM31: -175.38462 | AN31: -148.18182 | AO31: -158.47619 | AP31: -180.74468 | AQ31: -186.45161 | AR31: -163.98148 | AS31: -165.87156 | AT31: -205.11111 | AU31: -198.42105 | AV31: -181.50943 | AW31: -183.64486 | AX31: -218.04348 | AY31: -225.05495 | AZ31: -190.09091 | BA31: -203.33333 | BB31: -231.91489 | BC31: -239.35484
A32: Helios Software Ltd | B32: Cloud Operations | C32: CC-220 | D32: 5100 | E32: 3rd-party licences | F32: EUR '000 | G32: -172 | H32: -175.6 | I32: -179.3 | J32: -183.1 | K32: -186.9 | L32: -190.8 | M32: -194.8 | N32: -198.9 | O32: -203.1 | P32: -207.4 | Q32: -211.7 | R32: -216.2 | S32: -220.7 | T32: -225.4 | U32: -230.1 | V32: -234.9 | W32: -239.9 | X32: -244.9 | Y32: -250 | Z32: -255.3 | AA32: -260.6 | AB32: -266.1 | AC32: -271.7 | AD32: -277.4 | AF32: -157.79817 | AG32: -159.63636 | AH32: -188.73684 | AI32: -194.78723 | AJ32: -174.6729 | AK32: -176.66667 | AL32: -214.06593 | AM32: -221 | AN32: -193.42857 | AO32: -195.66038 | AP32: -227.63441 | AQ32: -235 | AR32: -202.47706 | AS32: -204.90909 | AT32: -242.21053 | AU32: -249.89362 | AV32: -224.20561 | AW32: -226.75926 | AX32: -274.72527 | AY32: -283.66667 | AZ32: -248.19048 | BA32: -251.03774 | BB32: -292.15054 | BC32: -301.52174
A33: Helios Software Ltd | B33: Cloud Operations | C33: CC-220 | D33: 5110 | E33: Observability & data transfer | F33: EUR '000 | G33: -74 | H33: -75.6 | I33: -77.1 | J33: -78.8 | K33: -80.4 | L33: -82.1 | M33: -83.8 | N33: -85.6 | O33: -87.4 | P33: -89.2 | Q33: -91.1 | R33: -93 | S33: -95 | T33: -97 | U33: -99 | V33: -101.1 | W33: -103.2 | X33: -105.4 | Y33: -107.6 | Z33: -109.8 | AA33: -112.1 | AB33: -114.5 | AC33: -116.9 | AD33: -119.4 | AF33: -67.272727 | AG33: -72 | AH33: -82.021277 | AI33: -84.731183 | AJ33: -74.444444 | AK33: -75.321101 | AL33: -93.111111 | AM33: -90.105263 | AN33: -82.45283 | AO33: -83.364486 | AP33: -99.021739 | AQ33: -102.1978 | AR33: -86.363636 | AS33: -92.380952 | AT33: -105.31915 | AU33: -108.70968 | AV33: -95.555556 | AW33: -96.697248 | AX33: -119.55556 | AY33: -115.57895 | AZ33: -105.75472 | BA33: -107.00935 | BB33: -127.06522 | BC33: -131.20879
A34: Helios Software Ltd | B34: Cloud Operations | C34: CC-220 | D34: 5120 | E34: Security scanning subscriptions | F34: EUR '000 | G34: -31 | H34: -31.7 | I34: -32.3 | J34: -33 | K34: -33.7 | L34: -34.4 | M34: -35.1 | N34: -35.9 | O34: -36.6 | P34: -37.4 | Q34: -38.2 | R34: -39 | S34: -39.8 | T34: -40.6 | U34: -41.5 | V34: -42.3 | W34: -43.2 | X34: -44.1 | Y34: -45.1 | Z34: -46 | AA34: -47 | AB34: -48 | AC34: -49 | AD34: -50 | AF34: -29.52381 | AG34: -29.90566 | AH34: -34.731183 | AI34: -35.869565 | AJ34: -30.917431 | AK34: -31.272727 | AL34: -36.947368 | AM34: -38.191489 | AN34: -34.205607 | AO34: -34.62963 | AP34: -41.978022 | AQ34: -43.333333 | AR34: -37.904762 | AS34: -38.301887 | AT34: -44.623656 | AU34: -45.978261 | AV34: -39.633028 | AW34: -40.090909 | AX34: -47.473684 | AY34: -48.93617 | AZ34: -43.925234 | BA34: -44.444444 | BB34: -53.846154 | BC34: -55.555556
A35: Helios Software Ltd | B35: Cloud Operations | C35: -- | D35: SUB | E35: Cloud Operations ledger subtotal | F35: EUR '000 | G35: =SUM(G30:G34) -> -835 | H35: =SUM(H30:H34) -> -852.6 | I35: =SUM(I30:I34) -> -870.4 | J35: =SUM(J30:J34) -> -888.8 | K35: =SUM(K30:K34) -> -907.4 | L35: =SUM(L30:L34) -> -926.4 | M35: =SUM(M30:M34) -> -945.8 | N35: =SUM(N30:N34) -> -965.8 | ... AD35: =SUM(AD30:AD34) -> -1346.8 | AF35: =SUM(AF30:AF34) -> -774.89584 | AG35: =SUM(AG30:AG34) -> -787.84512 | AH35: =SUM(AH30:AH34) -> -946.47709 | AI35: =SUM(AI30:AI34) -> -966.68623 | AJ35: =SUM(AJ30:AJ34) -> -856.21087 | AK35: =SUM(AK30:AK34) -> -865.96725 | AL35: =SUM(AL30:AL34) -> -1025.6286 | AM35: =SUM(AM30:AM34) -> -1052.7248 | ... BC35: =SUM(BC30:BC34) -> -1448.2792
A37: Helios Software Ltd | B37: Professional Services | C37: CC-230 | D37: 5300 | E37: PS delivery cost | F37: EUR '000 | G37: -218 | H37: -220.6 | I37: -223.3 | J37: -225.9 | K37: -228.7 | L37: -231.4 | M37: -234.2 | N37: -237 | O37: -239.8 | P37: -242.7 | Q37: -245.6 | R37: -248.6 | S37: -251.5 | T37: -254.6 | U37: -257.6 | V37: -260.7 | W37: -263.8 | X37: -267 | Y37: -270.2 | Z37: -273.5 | AA37: -276.7 | AB37: -280.1 | AC37: -283.4 | AD37: -286.8 | AF37: -201.85185 | AG37: -202.38532 | AH37: -248.11111 | AI37: -237.78947 | AJ37: -215.75472 | AK37: -216.26168 | AL37: -254.56522 | AM37: -260.43956 | AN37: -218 | AO37: -231.14286 | AP37: -261.2766 | AQ37: -267.31183 | AR37: -232.87037 | AS37: -233.57798 | AT37: -286.22222 | AU37: -274.42105 | AV37: -248.86792 | AW37: -249.53271 | AX37: -293.69565 | AY37: -300.54945 | AZ37: -251.54545 | BA37: -266.7619 | BB37: -301.48936 | BC37: -308.3871
A38: Helios Software Ltd | B38: Professional Services | C38: CC-230 | D38: 5310 | E38: PS delivery subcontractors | F38: EUR '000 | G38: -96 | H38: -97.2 | I38: -98.3 | J38: -99.5 | K38: -100.7 | L38: -101.9 | M38: -103.1 | N38: -104.4 | O38: -105.6 | P38: -106.9 | Q38: -108.2 | R38: -109.5 | S38: -110.8 | T38: -112.1 | U38: -113.4 | V38: -114.8 | W38: -116.2 | X38: -117.6 | Y38: -119 | Z38: -120.4 | AA38: -121.9 | AB38: -123.3 | AC38: -124.8 | AD38: -126.3 | AF38: -88.073394 | AG38: -88.363636 | AH38: -103.47368 | AI38: -105.85106 | AJ38: -94.11215 | AK38: -94.351852 | AL38: -113.2967 | AM38: -116 | AN38: -100.57143 | AO38: -100.84906 | AP38: -116.34409 | AQ38: -119.02174 | AR38: -101.65138 | AS38: -101.90909 | AT38: -119.36842 | AU38: -122.12766 | AV38: -108.59813 | AW38: -108.88889 | AX38: -130.76923 | AY38: -133.77778 | AZ38: -116.09524 | BA38: -116.32075 | BB38: -134.19355 | BC38: -137.28261
A39: Helios Software Ltd | B39: Professional Services | C39: CC-230 | D39: 5320 | E39: PS travel & project expenses | F39: EUR '000 | G39: -34 | H39: -34.4 | I39: -34.8 | J39: -35.2 | K39: -35.7 | L39: -36.1 | M39: -36.5 | N39: -37 | O39: -37.4 | P39: -37.9 | Q39: -38.3 | R39: -38.8 | S39: -39.2 | T39: -39.7 | U39: -40.2 | V39: -40.7 | W39: -41.1 | X39: -41.6 | Y39: -42.1 | Z39: -42.6 | AA39: -43.2 | AB39: -43.7 | AC39: -44.2 | AD39: -44.7 | AF39: -30.909091 | AG39: -32.761905 | AH39: -37.021277 | AI39: -37.849462 | AJ39: -33.055556 | AK39: -33.119266 | AL39: -40.555556 | AM39: -38.947368 | AN39: -35.283019 | AO39: -35.420561 | AP39: -41.630435 | AQ39: -42.637363 | AR39: -35.636364 | AS39: -37.809524 | AT39: -42.765957 | AU39: -43.763441 | AV39: -38.055556 | AW39: -38.165138 | AX39: -46.777778 | AY39: -44.842105 | AZ39: -40.754717 | BA39: -40.841121 | BB39: -48.043478 | BC39: -49.120879
A40: Helios Software Ltd | B40: Professional Services | C40: -- | D40: SUB | E40: Professional Services ledger subtotal | F40: EUR '000 | G40: =SUM(G37:G39) -> -348 | H40: =SUM(H37:H39) -> -352.2 | I40: =SUM(I37:I39) -> -356.4 | J40: =SUM(J37:J39) -> -360.6 | K40: =SUM(K37:K39) -> -365.1 | L40: =SUM(L37:L39) -> -369.4 | M40: =SUM(M37:M39) -> -373.8 | N40: =SUM(N37:N39) -> -378.4 | ... AD40: =SUM(AD37:AD39) -> -457.8 | AF40: =SUM(AF37:AF39) -> -320.83434 | AG40: =SUM(AG37:AG39) -> -323.51086 | AH40: =SUM(AH37:AH39) -> -388.60607 | AI40: =SUM(AI37:AI39) -> -381.49 | AJ40: =SUM(AJ37:AJ39) -> -342.92242 | AK40: =SUM(AK37:AK39) -> -343.7328 | AL40: =SUM(AL37:AL39) -> -408.41748 | AM40: =SUM(AM37:AM39) -> -415.38693 | ... BC40: =SUM(BC37:BC39) -> -494.79058
A42: Helios Software Ltd | B42: Field Sales - EMEA | C42: CC-310 | D42: 6000 | E42: Sales salaries / EMEA | F42: EUR '000 | G42: -445 | H42: -453 | I42: -461.2 | J42: -469.5 | K42: -477.9 | L42: -486.5 | M42: -495.3 | N42: -504.2 | O42: -513.3 | P42: -522.5 | Q42: -531.9 | R42: -541.5 | S42: -551.2 | T42: -561.2 | U42: -571.3 | V42: -581.5 | W42: -592 | X42: -602.7 | Y42: -613.5 | Z42: -624.6 | AA42: -635.8 | AB42: -647.2 | AC42: -658.9 | AD42: -670.7 | AF42: -415.88785 | AG42: -419.44444 | AH42: -506.81319 | AI42: -521.66667 | AJ42: -455.14286 | AK42: -458.96226 | AL42: -532.58065 | AM42: -548.04348 | AN42: -470.91743 | AO42: -475 | AP42: -559.89474 | AQ42: -576.06383 | AR42: -515.14019 | AS42: -519.62963 | AT42: -627.8022 | AU42: -646.11111 | AV42: -563.80952 | AW42: -568.58491 | AX42: -659.67742 | AY42: -678.91304 | AZ42: -583.30275 | BA42: -588.36364 | BB42: -693.57895 | BC42: -713.51064
A43: Helios Software Ltd | B43: Field Sales - EMEA | C43: CC-310 | D43: 6010 | E43: Sales commissions / EMEA | F43: EUR '000 | G43: -175 | H43: -177.1 | I43: -179.2 | J43: -181.4 | K43: -183.6 | L43: -185.8 | M43: -188 | N43: -190.2 | O43: -192.5 | P43: -194.8 | Q43: -197.2 | R43: -199.5 | S43: -201.9 | T43: -204.4 | U43: -206.8 | V43: -209.3 | W43: -211.8 | X43: -214.3 | Y43: -216.9 | Z43: -219.5 | AA43: -222.2 | AB43: -224.8 | AC43: -227.5 | AD43: -230.2 | AF43: -162.03704 | AG43: -162.47706 | AH43: -199.11111 | AI43: -190.94737 | AJ43: -173.20755 | AK43: -173.64486 | AL43: -204.34783 | AM43: -209.01099 | AN43: -175 | AO43: -185.52381 | AP43: -209.78723 | AQ43: -214.51613 | AR43: -186.94444 | AS43: -187.52294 | AT43: -229.77778 | AU43: -220.31579 | AV43: -199.81132 | AW43: -200.28037 | AX43: -235.76087 | AY43: -241.20879 | AZ43: -202 | BA43: -214.09524 | BB43: -242.02128 | BC43: -247.52688
A44: Helios Software Ltd | B44: Field Sales - EMEA | C44: CC-310 | D44: 6050 | E44: Sales travel & entertainment / EMEA | F44: EUR '000 | G44: -58 | H44: -58.7 | I44: -59.4 | J44: -60.1 | K44: -60.8 | L44: -61.6 | M44: -62.3 | N44: -63.1 | O44: -63.8 | P44: -64.6 | Q44: -65.3 | R44: -66.1 | S44: -66.9 | T44: -67.7 | U44: -68.5 | V44: -69.4 | W44: -70.2 | X44: -71 | Y44: -71.9 | Z44: -72.8 | AA44: -73.6 | AB44: -74.5 | AC44: -75.4 | AD44: -76.3 | AF44: -53.211009 | AG44: -53.363636 | AH44: -62.526316 | AI44: -63.93617 | AJ44: -56.82243 | AK44: -57.037037 | AL44: -68.461538 | AM44: -70.111111 | AN44: -60.761905 | AO44: -60.943396 | AP44: -70.215054 | AQ44: -71.847826 | AR44: -61.376147 | AS44: -61.545455 | AT44: -72.105263 | AU44: -73.829787 | AV44: -65.607477 | AW44: -65.740741 | AX44: -79.010989 | AY44: -80.888889 | AZ44: -70.095238 | BA44: -70.283019 | BB44: -81.075269 | BC44: -82.934783
A45: Helios Software Ltd | B45: Field Sales - EMEA | C45: -- | D45: SUB | E45: Field Sales EMEA ledger subtotal | F45: EUR '000 | G45: =SUM(G42:G44) -> -678 | H45: =SUM(H42:H44) -> -688.8 | I45: =SUM(I42:I44) -> -699.8 | J45: =SUM(J42:J44) -> -711 | K45: =SUM(K42:K44) -> -722.3 | L45: =SUM(L42:L44) -> -733.9 | M45: =SUM(M42:M44) -> -745.6 | N45: =SUM(N42:N44) -> -757.5 | ... AD45: =SUM(AD42:AD44) -> -977.2 | AF45: =SUM(AF42:AF44) -> -631.1359 | AG45: =SUM(AG42:AG44) -> -635.28515 | AH45: =SUM(AH42:AH44) -> -768.45061 | AI45: =SUM(AI42:AI44) -> -776.55021 | AJ45: =SUM(AJ42:AJ44) -> -685.17283 | AK45: =SUM(AK42:AK44) -> -689.64416 | AL45: =SUM(AL42:AL44) -> -805.39001 | AM45: =SUM(AM42:AM44) -> -827.16558 | ... BC45: =SUM(BC42:BC44) -> -1043.9723
A47: Helios Software Ltd | B47: Field Sales - Americas | C47: CC-320 | D47: 6000 | E47: Sales salaries / Americas | F47: EUR '000 | G47: -325 | H47: -330.8 | I47: -336.8 | J47: -342.9 | K47: -349 | L47: -355.3 | M47: -361.7 | N47: -368.2 | O47: -374.9 | P47: -381.6 | Q47: -388.5 | R47: -395.5 | S47: -402.6 | T47: -409.8 | U47: -417.2 | V47: -424.7 | W47: -432.4 | X47: -440.1 | Y47: -448.1 | Z47: -456.1 | AA47: -464.3 | AB47: -472.7 | AC47: -481.2 | AD47: -489.9 | AF47: -306.60377 | AG47: -309.15888 | AH47: -366.08696 | AI47: -376.81319 | AJ47: -317.27273 | AK47: -338.38095 | AL47: -384.78723 | AM47: -395.91398 | AN47: -347.12963 | AO47: -350.09174 | AP47: -431.66667 | AQ47: -416.31579 | AR47: -379.81132 | AS47: -382.99065 | AT47: -453.47826 | AU47: -466.7033 | AV47: -393.09091 | AW47: -419.14286 | AX47: -476.70213 | AY47: -490.43011 | AZ47: -429.90741 | BA47: -433.66972 | BB47: -534.66667 | BC47: -515.68421
A48: Helios Software Ltd | B48: Field Sales - Americas | C48: CC-320 | D48: 6010 | E48: Sales commissions / Americas | F48: EUR '000 | G48: -122 | H48: -123.5 | I48: -124.9 | J48: -126.4 | K48: -128 | L48: -129.5 | M48: -131.1 | N48: -132.6 | O48: -134.2 | P48: -135.8 | Q48: -137.5 | R48: -139.1 | S48: -140.8 | T48: -142.5 | U48: -144.2 | V48: -145.9 | W48: -147.7 | X48: -149.4 | Y48: -151.2 | Z48: -153 | AA48: -154.9 | AB48: -156.7 | AC48: -158.6 | AD48: -160.5 | AF48: -114.01869 | AG48: -114.35185 | AH48: -137.25275 | AI48: -140.44444 | AJ48: -121.90476 | AK48: -122.16981 | AL48: -140.96774 | AM48: -144.13043 | AN48: -123.11927 | AO48: -123.45455 | AP48: -144.73684 | AQ48: -147.97872 | AR48: -131.58879 | AS48: -131.94444 | AT48: -158.46154 | AU48: -162.11111 | AV48: -140.66667 | AW48: -140.9434 | AX48: -162.58065 | AY48: -166.30435 | AZ48: -142.11009 | BA48: -142.45455 | BB48: -166.94737 | BC48: -170.74468
...

Sheet Group_BS_EUR
A1: NetSuite Balance Sheet Export | B1: Helios Software Group — consolidation ledger | E1: Reporting currency: EUR
G2: ACTUAL — month end closing balances | AF2: BUDGET — month end plan balances
A3: Legal entity | B3: Department | C3: Cost centre | D3: Account code | E3: Account name | F3: Unit | G3: Jan-2024 | H3: Feb-2024 | I3: Mar-2024 | J3: Apr-2024 | K3: May-2024 | L3: Jun-2024 | M3: Jul-2024 | N3: Aug-2024 | O3: Sept-2024 | P3: Oct-2024 | Q3: Nov-2024 | R3: Dec-2024 | S3: Jan-2025 | T3: Feb-2025 | U3: Mar-2025 | V3: Apr-2025 | W3: May-2025 | X3: Jun-2025 | Y3: Jul-2025 | Z3: Aug-2025 | AA3: Sept-2025 | AB3: Oct-2025 | AC3: Nov-2025 | AD3: Dec-2025 | AF3: Jan-2024 | AG3: Feb-2024 | AH3: Mar-2024 | AI3: Apr-2024 | AJ3: May-2024 | AK3: Jun-2024 | AL3: Jul-2024 | AM3: Aug-2024 | AN3: Sept-2024 | AO3: Oct-2024 | AP3: Nov-2024 | AQ3: Dec-2024 | AR3: Jan-2025 | AS3: Feb-2025 | AT3: Mar-2025 | AU3: Apr-2025 | AV3: May-2025 | AW3: Jun-2025 | AX3: Jul-2025 | AY3: Aug-2025 | AZ3: Sept-2025 | BA3: Oct-2025 | BB3: Nov-2025 | BC3: Dec-2025
A4: Helios Software Ltd | B4: Treasury | C4: CC-910 | D4: 1000 | E4: Cash | F4: EUR '000 | G4: 12400 | H4: 12833.7 | I4: 13202.8 | J4: 13458.6 | K4: 13580.1 | L4: 13579.2 | M4: 13497.6 | N4: 13397.1 | O4: 13343.8 | P4: 13392.4 | Q4: 13572.6 | R4: 13882 | S4: 14286.3 | T4: 14728.3 | U4: 15141.3 | V4: 15465.9 | W4: 15664.1 | X4: 15729.2 | Y4: 15686.7 | Z4: 15588.7 | AA4: 15500.8 | AB4: 15486.2 | AC4: 15590 | AD4: 15828.5 | AF4: 11780 | AG4: 13603.7 | AH4: 12278.6 | AI4: 14535.3 | AJ4: 12357.9 | AK4: 14937.1 | AL4: 12822.7 | AM4: 14200.9 | AN4: 12409.7 | AO4: 14463.7 | AP4: 12351.1 | AQ4: 15270.1 | AR4: 13572 | AS4: 15612 | AT4: 14081.4 | AU4: 16703.2 | AV4: 14254.4 | AW4: 17302.1 | AX4: 14902.3 | AY4: 16524 | AZ4: 14415.7 | BA4: 16725.1 | BB4: 14186.9 | BC4: 17411.4
A5: Helios Software Ltd | B5: Treasury | C5: CC-910 | D5: 1010 | E5: Restricted cash | F5: EUR '000 | G5: 920 | H5: 920 | I5: 920 | J5: 920 | K5: 920 | L5: 920 | M5: 920 | N5: 920 | O5: 920 | P5: 920 | Q5: 920 | R5: 920 | S5: 920 | T5: 920 | U5: 920 | V5: 920 | W5: 920 | X5: 920 | Y5: 920 | Z5: 920 | AA5: 920 | AB5: 920 | AC5: 920 | AD5: 920 | AF5: 864.8 | AG5: 984.4 | AH5: 846.4 | AI5: 1002.8 | AJ5: 828 | AK5: 966 | AL5: 864.8 | AM5: 984.4 | AN5: 846.4 | AO5: 1002.8 | AP5: 828 | AQ5: 966 | AR5: 864.8 | AS5: 984.4 | AT5: 846.4 | AU5: 1002.8 | AV5: 828 | AW5: 966 | AX5: 864.8 | AY5: 984.4 | AZ5: 846.4 | BA5: 1002.8 | BB5: 828 | BC5: 966
A6: Helios Software Ltd | B6: Treasury | C6: CC-910 | D6: 1020 | E6: Payment processor clearing | F6: EUR '000 | G6: 180 | H6: 183.1 | I6: 186.2 | J6: 189.3 | K6: 192.6 | L6: 195.8 | M6: 199.2 | N6: 202.5 | O6: 206 | P6: 209.5 | Q6: 213.1 | R6: 216.7 | S6: 220.4 | T6: 224.1 | U6: 227.9 | V6: 231.8 | W6: 235.7 | X6: 239.7 | Y6: 243.8 | Z6: 248 | AA6: 252.2 | AB6: 256.5 | AC6: 260.8 | AD6: 265.2 | AF6: 167.4 | AG6: 197.7 | AH6: 169.4 | AI6: 208.3 | AJ6: 182.9 | AK6: 207.6 | AL6: 185.2 | AM6: 218.7 | AN6: 187.4 | AO6: 230.4 | AP6: 202.4 | AQ6: 229.7 | AR6: 204.9 | AS6: 242 | AT6: 207.4 | AU6: 255 | AV6: 223.9 | AW6: 254.1 | AX6: 226.7 | AY6: 267.8 | AZ6: 229.5 | BA6: 282.1 | BB6: 247.8 | BC6: 281.2
A7: Helios Software Ltd | B7: Treasury | C7: -- | D7: SUB | E7: Treasury ledger subtotal | F7: EUR '000 | G7: =SUM(G4:G6) -> 13500 | H7: =SUM(H4:H6) -> 13936.8 | I7: =SUM(I4:I6) -> 14309 | J7: =SUM(J4:J6) -> 14567.9 | K7: =SUM(K4:K6) -> 14692.7 | L7: =SUM(L4:L6) -> 14695 | M7: =SUM(M4:M6) -> 14616.8 | N7: =SUM(N4:N6) -> 14519.6 | ... AD7: =SUM(AD4:AD6) -> 17013.7 | AF7: =SUM(AF4:AF6) -> 12812.2 | AG7: =SUM(AG4:AG6) -> 14785.8 | AH7: =SUM(AH4:AH6) -> 13294.4 | AI7: =SUM(AI4:AI6) -> 15746.4 | AJ7: =SUM(AJ4:AJ6) -> 13368.8 | AK7: =SUM(AK4:AK6) -> 16110.7 | AL7: =SUM(AL4:AL6) -> 13872.7 | AM7: =SUM(AM4:AM6) -> 15404 | ... BC7: =SUM(BC4:BC6) -> 18658.6
A9: Helios Software Ltd | B9: Customer Billing | C9: CC-215 | D9: 1100 | E9: Trade receivables | F9: EUR '000 | G9: 6900 | H9: 7044.9 | I9: 7192.8 | J9: 7343.9 | K9: 7498.1 | L9: 7655.6 | M9: 7816.3 | N9: 7980.5 | O9: 8148.1 | P9: 8319.2 | Q9: 8493.9 | R9: 8672.3 | S9: 8854.4 | T9: 9040.3 | U9: 9230.2 | V9: 9424 | W9: 9621.9 | X9: 9824 | Y9: 10030.3 | Z9: 10240.9 | AA9: 10456 | AB9: 10675.5 | AC9: 10899.7 | AD9: 11128.6 | AF9: 6210 | AG9: 7397.1 | AH9: 6761.3 | AI9: 7858 | AJ9: 6898.3 | AK9: 8344.6 | AL9: 7034.7 | AM9: 8379.5 | AN9: 7659.2 | AO9: 8901.5 | AP9: 7814.4 | AQ9: 9452.8 | AR9: 7968.9 | AS9: 9492.3 | AT9: 8676.4 | AU9: 10083.7 | AV9: 8852.2 | AW9: 10708.1 | AX9: 9027.2 | AY9: 10752.9 | AZ9: 9828.6 | BA9: 11422.8 | BB9: 10027.7 | BC9: 12130.2
A10: Helios Software Ltd | B10: Customer Billing | C10: CC-215 | D10: 1110 | E10: Accrued subscription income | F10: EUR '000 | G10: 1450 | H10: 1480.4 | I10: 1511.5 | J10: 1543.3 | K10: 1575.7 | L10: 1608.8 | M10: 1642.6 | N10: 1677.1 | O10: 1712.3 | P10: 1748.2 | Q10: 1784.9 | R10: 1822.4 | S10: 1860.7 | T10: 1899.8 | U10: 1939.7 | V10: 1980.4 | W10: 2022 | X10: 2064.5 | Y10: 2107.8 | Z10: 2152.1 | AA10: 2197.3 | AB10: 2243.4 | AC10: 2290.5 | AD10: 2338.6 | AF10: 1377.5 | AG10: 1569.3 | AH10: 1405.7 | AI10: 1666.7 | AJ10: 1433.9 | AK10: 1769.7 | AL10: 1560.4 | AM10: 1777.7 | AN10: 1592.4 | AO10: 1888.1 | AP10: 1624.3 | AQ10: 2004.7 | AR10: 1767.7 | AS10: 2013.8 | AT10: 1803.9 | AU10: 2138.8 | AV10: 1840 | AW10: 2270.9 | AX10: 2002.4 | AY10: 2281.2 | AZ10: 2043.5 | BA10: 2422.9 | BB10: 2084.4 | BC10: 2572.5
A11: Helios Software Ltd | B11: Customer Billing | C11: CC-215 | D11: 1120 | E11: Contract assets | F11: EUR '000 | G11: 780 | H11: 796.4 | I11: 813.1 | J11: 830.2 | K11: 847.6 | L11: 865.4 | M11: 883.6 | N11: 902.1 | O11: 921.1 | P11: 940.4 | Q11: 960.2 | R11: 980.3 | S11: 1000.9 | T11: 1021.9 | U11: 1043.4 | V11: 1065.3 | W11: 1087.7 | X11: 1110.5 | Y11: 1133.9 | Z11: 1157.7 | AA11: 1182 | AB11: 1206.8 | AC11: 1232.1 | AD11: 1258 | AF11: 733.2 | AG11: 852.1 | AH11: 748.1 | AI11: 904.9 | AJ11: 762.9 | AK11: 908.7 | AL11: 830.6 | AM11: 965.3 | AN11: 847.4 | AO11: 1025.1 | AP11: 864.2 | AQ11: 1029.4 | AR11: 940.9 | AS11: 1093.5 | AT11: 959.9 | AU11: 1161.2 | AV11: 978.9 | AW11: 1166.1 | AX11: 1065.8 | AY11: 1238.7 | AZ11: 1087.4 | BA11: 1315.4 | BB11: 1108.9 | BC11: 1320.9
A12: Helios Software Ltd | B12: Customer Billing | C12: CC-215 | D12: 1130 | E12: Allowance for doubtful accounts | F12: EUR '000 | G12: -210 | H12: -214.4 | I12: -218.9 | J12: -223.5 | K12: -228.2 | L12: -233 | M12: -237.9 | N12: -242.9 | O12: -248 | P12: -253.2 | Q12: -258.5 | R12: -263.9 | S12: -269.5 | T12: -275.1 | U12: -280.9 | V12: -286.8 | W12: -292.8 | X12: -299 | Y12: -305.3 | Z12: -311.7 | AA12: -318.2 | AB12: -324.9 | AC12: -331.7 | AD12: -338.7 | AF12: -195.3 | AG12: -231.6 | AH12: -199.2 | AI12: -245.9 | AJ12: -216.8 | AK12: -247 | AL12: -221.2 | AM12: -262.3 | AN12: -225.7 | AO12: -278.5 | AP12: -245.6 | AQ12: -279.8 | AR12: -250.6 | AS12: -297.2 | AT12: -255.6 | AU12: -315.5 | AV12: -278.2 | AW12: -316.9 | AX12: -283.9 | AY12: -336.6 | AZ12: -289.6 | BA12: -357.4 | BB12: -315.1 | BC12: -359
A13: Helios Software Ltd | B13: Customer Billing | C13: -- | D13: SUB | E13: Customer Billing ledger subtotal | F13: EUR '000 | G13: =SUM(G9:G12) -> 8920 | H13: =SUM(H9:H12) -> 9107.3 | I13: =SUM(I9:I12) -> 9298.5 | J13: =SUM(J9:J12) -> 9493.9 | K13: =SUM(K9:K12) -> 9693.2 | L13: =SUM(L9:L12) -> 9896.8 | M13: =SUM(M9:M12) -> 10104.6 | N13: =SUM(N9:N12) -> 10316.8 | ... AD13: =SUM(AD9:AD12) -> 14386.5 | AF13: =SUM(AF9:AF12) -> 8125.4 | AG13: =SUM(AG9:AG12) -> 9586.9 | AH13: =SUM(AH9:AH12) -> 8715.9 | AI13: =SUM(AI9:AI12) -> 10183.7 | AJ13: =SUM(AJ9:AJ12) -> 8878.3 | AK13: =SUM(AK9:AK12) -> 10776 | AL13: =SUM(AL9:AL12) -> 9204.5 | AM13: =SUM(AM9:AM12) -> 10860.2 | ... BC13: =SUM(BC9:BC12) -> 15664.6
A15: Helios Software Ltd | B15: Procurement | C15: CC-505 | D15: 1200 | E15: Prepayments | F15: EUR '000 | G15: 1150 | H15: 1169.6 | I15: 1189.4 | J15: 1209.7 | K15: 1230.2 | L15: 1251.1 | M15: 1272.4 | N15: 1294 | O15: 1316 | P15: 1338.4 | Q15: 1361.2 | R15: 1384.3 | S15: 1407.8 | T15: 1431.8 | U15: 1456.1 | V15: 1480.9 | W15: 1506 | X15: 1531.6 | Y15: 1557.7 | Z15: 1584.1 | AA15: 1611.1 | AB15: 1638.5 | AC15: 1666.3 | AD15: 1694.6 | AF15: 1035 | AG15: 1228 | AH15: 1118.1 | AI15: 1294.3 | AJ15: 1131.8 | AK15: 1363.7 | AL15: 1145.2 | AM15: 1358.7 | AN15: 1237.1 | AO15: 1432.1 | AP15: 1252.3 | AQ15: 1508.9 | AR15: 1267 | AS15: 1503.3 | AT15: 1368.7 | AU15: 1584.5 | AV15: 1385.5 | AW15: 1669.5 | AX15: 1401.9 | AY15: 1663.4 | AZ15: 1514.4 | BA15: 1753.2 | BB15: 1533 | BC15: 1847.2
A16: Helios Software Ltd | B16: Procurement | C16: CC-505 | D16: 1210 | E16: Supplier deposits | F16: EUR '000 | G16: 320 | H16: 325.4 | I16: 331 | J16: 336.6 | K16: 342.3 | L16: 348.1 | M16: 354.1 | N16: 360.1 | O16: 366.2 | P16: 372.4 | Q16: 378.8 | R16: 385.2 | S16: 391.7 | T16: 398.4 | U16: 405.2 | V16: 412.1 | W16: 419.1 | X16: 426.2 | Y16: 433.4 | Z16: 440.8 | AA16: 448.3 | AB16: 455.9 | AC16: 463.7 | AD16: 471.6 | AF16: 304 | AG16: 345 | AH16: 307.8 | AI16: 363.5 | AJ16: 311.5 | AK16: 383 | AL16: 336.4 | AM16: 381.7 | AN16: 340.6 | AO16: 402.2 | AP16: 344.7 | AQ16: 423.7 | AR16: 372.2 | AS16: 422.3 | AT16: 376.8 | AU16: 445 | AV16: 381.4 | AW16: 468.8 | AX16: 411.8 | AY16: 467.3 | AZ16: 416.9 | BA16: 492.4 | BB16: 421.9 | BC16: 518.7
A17: Helios Software Ltd | B17: Procurement | C17: CC-505 | D17: 1220 | E17: Inventory/WIP | F17: EUR '000 | G17: 460 | H17: 467.8 | I17: 475.8 | J17: 483.9 | K17: 492.1 | L17: 500.5 | M17: 509 | N17: 517.6 | O17: 526.4 | P17: 535.4 | Q17: 544.5 | R17: 553.7 | S17: 563.1 | T17: 572.7 | U17: 582.4 | V17: 592.3 | W17: 602.4 | X17: 612.7 | Y17: 623.1 | Z17: 633.7 | AA17: 644.4 | AB17: 655.4 | AC17: 666.5 | AD17: 677.9 | AF17: 432.4 | AG17: 500.6 | AH17: 437.7 | AI17: 527.4 | AJ17: 442.9 | AK17: 525.5 | AL17: 478.4 | AM17: 553.8 | AN17: 484.3 | AO17: 583.5 | AP17: 490 | AQ17: 581.4 | AR17: 529.3 | AS17: 612.8 | AT17: 535.8 | AU17: 645.7 | AV17: 542.2 | AW17: 643.3 | AX17: 585.7 | AY17: 678 | AZ17: 592.9 | BA17: 714.4 | BB17: 599.9 | BC17: 711.8
A18: Helios Software Ltd | B18: Procurement | C18: CC-505 | D18: 1230 | E18: VAT & sales tax receivable | F18: EUR '000 | G18: 270 | H18: 274.6 | I18: 279.3 | J18: 284 | K18: 288.8 | L18: 293.7 | M18: 298.7 | N18: 303.8 | O18: 309 | P18: 314.2 | Q18: 319.6 | R18: 325 | S18: 330.5 | T18: 336.2 | U18: 341.9 | V18: 347.7 | W18: 353.6 | X18: 359.6 | Y18: 365.7 | Z18: 371.9 | AA18: 378.3 | AB18: 384.7 | AC18: 391.2 | AD18: 397.9 | AF18: 251.1 | AG18: 296.6 | AH18: 254.1 | AI18: 312.4 | AJ18: 274.4 | AK18: 311.4 | AL18: 277.8 | AM18: 328.1 | AN18: 281.2 | AO18: 345.7 | AP18: 303.6 | AQ18: 344.5 | AR18: 307.4 | AS18: 363 | AT18: 311.1 | AU18: 382.4 | AV18: 335.9 | AW18: 381.2 | AX18: 340.1 | AY18: 401.7 | AZ18: 344.2 | BA18: 423.2 | BB18: 371.7 | BC18: 421.7
A19: Helios Software Ltd | B19: Procurement | C19: -- | D19: SUB | E19: Procurement debit-balance subtotal | F19: EUR '000 | G19: =SUM(G15:G18) -> 2200 | H19: =SUM(H15:H18) -> 2237.4 | I19: =SUM(I15:I18) -> 2275.5 | J19: =SUM(J15:J18) -> 2314.2 | K19: =SUM(K15:K18) -> 2353.4 | L19: =SUM(L15:L18) -> 2393.4 | M19: =SUM(M15:M18) -> 2434.2 | N19: =SUM(N15:N18) -> 2475.5 | ... AD19: =SUM(AD15:AD18) -> 3242 | AF19: =SUM(AF15:AF18) -> 2022.5 | AG19: =SUM(AG15:AG18) -> 2370.2 | AH19: =SUM(AH15:AH18) -> 2117.7 | AI19: =SUM(AI15:AI18) -> 2497.6 | AJ19: =SUM(AJ15:AJ18) -> 2160.6 | AK19: =SUM(AK15:AK18) -> 2583.6 | AL19: =SUM(AL15:AL18) -> 2237.8 | AM19: =SUM(AM15:AM18) -> 2622.3 | ... BC19: =SUM(BC15:BC18) -> 3499.4
A21: Helios Software Ltd | B21: Fixed Assets | C21: CC-900 | D21: 1300 | E21: Computer equipment at cost | F21: EUR '000 | G21: 6200 | H21: 6335 | I21: 6470 | J21: 6605 | K21: 6740 | L21: 6875 | M21: 7010 | N21: 7145 | O21: 7280 | P21: 7415 | Q21: 7550 | R21: 7685 | S21: 7820 | T21: 7955 | U21: 8090 | V21: 8225 | W21: 8360 | X21: 8495 | Y21: 8630 | Z21: 8765 | AA21: 8900 | AB21: 9035 | AC21: 9170 | AD21: 9305 | AF21: 5580 | AG21: 6651.8 | AH21: 6081.8 | AI21: 7067.4 | AJ21: 6200.8 | AK21: 7493.8 | AL21: 6309 | AM21: 7502.3 | AN21: 6843.2 | AO21: 7934.1 | AP21: 6946 | AQ21: 8376.7 | AR21: 7038 | AS21: 8352.8 | AT21: 7604.6 | AU21: 8800.8 | AV21: 7691.2 | AW21: 9259.6 | AX21: 7767 | AY21: 9203.3 | AZ21: 8366 | BA21: 9667.5 | BB21: 8436.4 | BC21: 10142.5
A22: Helios Software Ltd | B22: Fixed Assets | C22: CC-900 | D22: 1310 | E22: Accumulated deprec–equipment | F22: EUR '000 | G22: -2650 | H22: -2725 | I22: -2800 | J22: -2875 | K22: -2950 | L22: -3025 | M22: -3100 | N22: -3175 | O22: -3250 | P22: -3325 | Q22: -3400 | R22: -3475 | S22: -3550 | T22: -3625 | U22: -3700 | V22: -3775 | W22: -3850 | X22: -3925 | Y22: -4000 | Z22: -4075 | AA22: -4150 | AB22: -4225 | AC22: -4300 | AD22: -4375 | AF22: -2517.5 | AG22: -2888.5 | AH22: -2604 | AI22: -3105 | AJ22: -2684.5 | AK22: -3327.5 | AL22: -2945 | AM22: -3365.5 | AN22: -3022.5 | AO22: -3591 | AP22: -3094 | AQ22: -3822.5 | AR22: -3372.5 | AS22: -3842.5 | AT22: -3441 | AU22: -4077 | AV22: -3503.5 | AW22: -4317.5 | AX22: -3800 | AY22: -4319.5 | AZ22: -3859.5 | BA22: -4563 | BB22: -3913 | BC22: -4812.5
A23: Helios Software Ltd | B23: Fixed Assets | C23: CC-900 | D23: 1320 | E23: Leasehold improvements at cost | F23: EUR '000 | G23: 1780 | H23: 1915 | I23: 2050 | J23: 2185 | K23: 2320 | L23: 2455 | M23: 2590 | N23: 2725 | O23: 2860 | P23: 2995 | Q23: 3130 | R23: 3265 | S23: 3400 | T23: 3535 | U23: 3670 | V23: 3805 | W23: 3940 | X23: 4075 | Y23: 4210 | Z23: 4345 | AA23: 4480 | AB23: 4615 | AC23: 4750 | AD23: 4885 | AF23: 1673.2 | AG23: 2049.1 | AH23: 1886 | AI23: 2381.7 | AJ23: 2088 | AK23: 2577.8 | AL23: 2434.6 | AM23: 2915.8 | AN23: 2631.2 | AO23: 3264.6 | AP23: 2817 | AQ23: 3428.3 | AR23: 3196 | AS23: 3782.5 | AT23: 3376.4 | AU23: 4147.5 | AV23: 3546 | AW23: 4278.8 | AX23: 3957.4 | AY23: 4649.2 | AZ23: 4121.6 | BA23: 5030.4 | BB23: 4275 | BC23: 5129.3
A24: Helios Software Ltd | B24: Fixed Assets | C24: CC-900 | D24: 1330 | E24: Accumulated deprec–leasehold | F24: EUR '000 | G24: -640 | H24: -715 | I24: -790 | J24: -865 | K24: -940 | L24: -1015 | M24: -1090 | N24: -1165 | O24: -1240 | P24: -1315 | Q24: -1390 | R24: -1465 | S24: -1540 | T24: -1615 | U24: -1690 | V24: -1765 | W24: -1840 | X24: -1915 | Y24: -1990 | Z24: -2065 | AA24: -2140 | AB24: -2215 | AC24: -2290 | AD24: -2365 | AF24: -595.2 | AG24: -772.2 | AH24: -718.9 | AI24: -951.5 | AJ24: -893 | AK24: -1075.9 | AL24: -1013.7 | AM24: -1258.2 | AN24: -1128.4 | AO24: -1446.5 | AP24: -1320.5 | AQ24: -1552.9 | AR24: -1432.2 | AS24: -1744.2 | AT24: -1537.9 | AU24: -1941.5 | AV24: -1748 | AW24: -2029.9 | AX24: -1850.7 | AY24: -2230.2 | AZ24: -1947.4 | BA24: -2436.5 | BB24: -2175.5 | BC24: -2506.9
A25: Helios Software Ltd | B25: Fixed Assets | C25: CC-900 | D25: 1400 | E25: Purchased intangibles at cost | F25: EUR '000 | G25: 3100 | H25: 3235 | I25: 3370 | J25: 3505 | K25: 3640 | L25: 3775 | M25: 3910 | N25: 4045 | O25: 4180 | P25: 4315 | Q25: 4450 | R25: 4585 | S25: 4720 | T25: 4855 | U25: 4990 | V25: 5125 | W25: 5260 | X25: 5395 | Y25: 5530 | Z25: 5665 | AA25: 5800 | AB25: 5935 | AC25: 6070 | AD25: 6205 | AF25: 2852 | AG25: 3526.2 | AH25: 3033 | AI25: 3680.3 | AJ25: 3421.6 | AK25: 4039.3 | AL25: 3597.2 | AM25: 4409.1 | AN25: 3762 | AO25: 4530.8 | AP25: 4183 | AQ25: 4906 | AR25: 4342.4 | AS25: 5292 | AT25: 4491 | AU25: 5381.3 | AV25: 4944.4 | AW25: 5772.7 | AX25: 5087.6 | AY25: 6174.9 | AZ25: 5220 | BA25: 6231.8 | BB25: 5705.8 | BC25: 6639.4
A26: Helios Software Ltd | B26: Fixed Assets | C26: CC-900 | D26: 1410 | E26: Accumulated amort–intangibles | F26: EUR '000 | G26: -1480 | H26: -1555 | I26: -1630 | J26: -1705 | K26: -1780 | L26: -1855 | M26: -1930 | N26: -2005 | O26: -2080 | P26: -2155 | Q26: -2230 | R26: -2305 | S26: -2380 | T26: -2455 | U26: -2530 | V26: -2605 | W26: -2680 | X26: -2755 | Y26: -2830 | Z26: -2905 | AA26: -2980 | AB26: -3055 | AC26: -3130 | AD26: -3205 | AF26: -1346.8 | AG26: -1710.5 | AH26: -1548.5 | AI26: -1807.3 | AJ26: -1655.4 | AK26: -2003.4 | AL26: -1756.3 | AM26: -2205.5 | AN26: -1976 | AO26: -2284.3 | AP26: -2073.9 | AQ26: -2489.4 | AR26: -2165.8 | AS26: -2700.5 | AT26: -2403.5 | AU26: -2761.3 | AV26: -2492.4 | AW26: -2975.4 | AX26: -2575.3 | AY26: -3195.5 | AZ26: -2831 | BA26: -3238.3 | BB26: -2910.9 | BC26: -3461.4
A27: Helios Software Ltd | B27: Fixed Assets | C27: CC-900 | D27: 1420 | E27: Capitalised development cost | F27: EUR '000 | G27: 7600 | H27: 7735 | I27: 7870 | J27: 8005 | K27: 8140 | L27: 8275 | M27: 8410 | N27: 8545 | O27: 8680 | P27: 8815 | Q27: 8950 | R27: 9085 | S27: 9220 | T27: 9355 | U27: 9490 | V27: 9625 | W27: 9760 | X27: 9895 | Y27: 10030 | Z27: 10165 | AA27: 10300 | AB27: 10435 | AC27: 10570 | AD27: 10705 | AF27: 6840 | AG27: 8121.8 | AH27: 7397.8 | AI27: 8565.4 | AJ27: 7488.8 | AK27: 9019.8 | AL27: 7569 | AM27: 8972.3 | AN27: 8159.2 | AO27: 9432.1 | AP27: 8234 | AQ27: 9902.7 | AR27: 8298 | AS27: 9822.8 | AT27: 8920.6 | AU27: 10298.8 | AV27: 8979.2 | AW27: 10785.6 | AX27: 9027 | AY27: 10673.3 | AZ27: 9682 | BA27: 11165.5 | BB27: 9724.4 | BC27: 11668.5
A28: Helios Software Ltd | B28: Fixed Assets | C28: CC-900 | D28: 1430 | E28: Accumulated amort–capitalised dev | F28: EUR '000 | G28: -2890 | H28: -2965 | I28: -3040 | J28: -3115 | K28: -3190 | L28: -3265 | M28: -3340 | N28: -3415 | O28: -3490 | P28: -3565 | Q28: -3640 | R28: -3715 | S28: -3790 | T28: -3865 | U28: -3940 | V28: -4015 | W28: -4090 | X28: -4165 | Y28: -4240 | Z28: -4315 | AA28: -4390 | AB28: -4465 | AC28: -4540 | AD28: -4615 | AF28: -2745.5 | AG28: -3142.9 | AH28: -2827.2 | AI28: -3364.2 | AJ28: -2902.9 | AK28: -3591.5 | AL28: -3173 | AM28: -3619.9 | AN28: -3245.7 | AO28: -3850.2 | AP28: -3312.4 | AQ28: -4086.5 | AR28: -3600.5 | AS28: -4096.9 | AT28: -3664.2 | AU28: -4336.2 | AV28: -3721.9 | AW28: -4581.5 | AX28: -4028 | AY28: -4573.9 | AZ28: -4082.7 | BA28: -4822.2 | BB28: -4131.4 | BC28: -5076.5
A29: Helios Software Ltd | B29: Fixed Assets | C29: -- | D29: SUB | E29: Fixed Assets register subtotal | F29: EUR '000 | G29: =SUM(G21:G28) -> 11020 | H29: =SUM(H21:H28) -> 11260 | I29: =SUM(I21:I28) -> 11500 | J29: =SUM(J21:J28) -> 11740 | K29: =SUM(K21:K28) -> 11980 | L29: =SUM(L21:L28) -> 12220 | M29: =SUM(M21:M28) -> 12460 | N29: =SUM(N21:N28) -> 12700 | ... AD29: =SUM(AD21:AD28) -> 16540 | AF29: =SUM(AF21:AF28) -> 9740.2 | AG29: =SUM(AG21:AG28) -> 11834.8 | AH29: =SUM(AH21:AH28) -> 10700 | AI29: =SUM(AI21:AI28) -> 12466.8 | AJ29: =SUM(AJ21:AJ28) -> 11063.4 | AK29: =SUM(AK21:AK28) -> 13132.4 | AL29: =SUM(AL21:AL28) -> 11021.8 | AM29: =SUM(AM21:AM28) -> 13350.4 | ... BC29: =SUM(BC21:BC28) -> 17722.4
A31: Helios Software Inc. | B31: US Working Capital | C31: CC-US1 | D31: 1500 | E31: US cash translated to EUR | F31: EUR '000 | G31: 2850 | H31: 3283.7 | I31: 3652.8 | J31: 3908.6 | K31: 4030.1 | L31: 4029.2 | M31: 3947.6 | N31: 3847.1 | O31: 3793.8 | P31: 3842.4 | Q31: 4022.6 | R31: 4332 | S31: 4736.3 | T31: 5178.3 | U31: 5591.3 | V31: 5915.9 | W31: 6114.1 | X31: 6179.2 | Y31: 6136.7 | Z31: 6038.7 | AA31: 5950.8 | AB31: 5936.2 | AC31: 6040 | AD31: 6278.5 | AF31: 2622 | AG31: 3579.2 | AH31: 3287.5 | AI31: 4104.1 | AJ31: 3788.3 | AK31: 4311.2 | AL31: 3631.8 | AM31: 4193.3 | AN31: 3414.4 | AO31: 4034.5 | AP31: 3781.2 | AQ31: 4635.2 | AR31: 4357.4 | AS31: 5644.4 | AT31: 5032.2 | AU31: 6211.7 | AV31: 5747.3 | AW31: 6611.7 | AX31: 5645.7 | AY31: 6582.1 | AZ31: 5355.7 | BA31: 6233 | BB31: 5677.6 | BC31: 6718
A32: Helios Software Inc. | B32: US Working Capital | C32: CC-US1 | D32: 1510 | E32: US trade receivables translated | F32: EUR '000 | G32: 1850 | H32: 1888.9 | I32: 1928.5 | J32: 1969 | K32: 2010.4 | L32: 2052.6 | M32: 2095.7 | N32: 2139.7 | O32: 2184.6 | P32: 2230.5 | Q32: 2277.3 | R32: 2325.2 | S32: 2374 | T32: 2423.9 | U32: 2474.8 | V32: 2526.7 | W32: 2579.8 | X32: 2634 | Y32: 2689.3 | Z32: 2745.7 | AA32: 2803.4 | AB32: 2862.3 | AC32: 2922.4 | AD32: 2983.8 | AF32: 1683.5 | AG32: 2077.7 | AH32: 1832.1 | AI32: 2087.2 | AJ32: 1869.6 | AK32: 2216.8 | AL32: 1907.1 | AM32: 2353.7 | AN32: 2075.4 | AO32: 2364.3 | AP32: 2117.9 | AQ32: 2511.2 | AR32: 2160.3 | AS32: 2666.2 | AT32: 2351 | AU32: 2678.3 | AV32: 2399.2 | AW32: 2844.7 | AX32: 2447.2 | AY32: 3020.3 | AZ32: 2663.2 | BA32: 3034 | BB32: 2717.8 | BC32: 3222.5
A33: Helios Software Inc. | B33: US Working Capital | C33: CC-US1 | D33: 1520 | E33: US intercompany receivable | F33: EUR '000 | G33: 1120 | H33: 1120 | I33: 1120 | J33: 1120 | K33: 1120 | L33: 1120 | M33: 1120 | N33: 1120 | O33: 1120 | P33: 1120 | Q33: 1120 | R33: 1120 | S33: 1120 | T33: 1120 | U33: 1120 | V33: 1120 | W33: 1120 | X33: 1120 | Y33: 1120 | Z33: 1120 | AA33: 1120 | AB33: 1120 | AC33: 1120 | AD33: 1120 | AF33: 1008 | AG33: 1176 | AH33: 1052.8 | AI33: 1198.4 | AJ33: 1030.4 | AK33: 1220.8 | AL33: 1008 | AM33: 1176 | AN33: 1052.8 | AO33: 1198.4 | AP33: 1030.4 | AQ33: 1220.8 | AR33: 1008 | AS33: 1176 | AT33: 1052.8 | AU33: 1198.4 | AV33: 1030.4 | AW33: 1220.8 | AX33: 1008 | AY33: 1176 | AZ33: 1052.8 | BA33: 1198.4 | BB33: 1030.4 | BC33: 1220.8
A34: Helios Software Inc. | B34: US Working Capital | C34: CC-US1 | D34: 1530 | E34: US lease right-of-use asset | F34: EUR '000 | G34: 940 | H34: 895 | I34: 850 | J34: 805 | K34: 760 | L34: 715 | M34: 670 | N34: 625 | O34: 580 | P34: 535 | Q34: 490 | R34: 445 | S34: 400 | T34: 355 | U34: 310 | V34: 265 | W34: 220 | X34: 175 | Y34: 130 | Z34: 85 | AA34: 40 | AB34: -5 | AC34: -50 | AD34: -95 | AF34: 893 | AG34: 948.7 | AH34: 790.5 | AI34: 869.4 | AJ34: 691.6 | AK34: 786.5 | AL34: 636.5 | AM34: 662.5 | AN34: 539.4 | AO34: 577.8 | AP34: 445.9 | AQ34: 489.5 | AR34: 380 | AS34: 376.3 | AT34: 288.3 | AU34: 286.2 | AV34: 200.2 | AW34: 192.5 | AX34: 123.5 | AY34: 90.1 | AZ34: 37.2 | BA34: -5.4 | BB34: -45.5 | BC34: -104.5
A35: Helios Software Inc. | B35: US Working Capital | C35: -- | D35: SUB | E35: US consolidation debit subtotal | F35: EUR '000 | G35: =SUM(G31:G34) -> 6760 | H35: =SUM(H31:H34) -> 7187.6 | I35: =SUM(I31:I34) -> 7551.3 | J35: =SUM(J31:J34) -> 7802.6 | K35: =SUM(K31:K34) -> 7920.5 | L35: =SUM(L31:L34) -> 7916.8 | M35: =SUM(M31:M34) -> 7833.3 | N35: =SUM(N31:N34) -> 7731.8 | ... AD35: =SUM(AD31:AD34) -> 10287.3 | AF35: =SUM(AF31:AF34) -> 6206.5 | AG35: =SUM(AG31:AG34) -> 7781.6 | AH35: =SUM(AH31:AH34) -> 6962.9 | AI35: =SUM(AI31:AI34) -> 8259.1 | AJ35: =SUM(AJ31:AJ34) -> 7379.9 | AK35: =SUM(AK31:AK34) -> 8535.3 | AL35: =SUM(AL31:AL34) -> 7183.4 | AM35: =SUM(AM31:AM34) -> 8385.5 | ... BC35: =SUM(BC31:BC34) -> 11056.8
A37: Helios Software Ltd | B37: Accounts Payable | C37: CC-506 | D37: 2000 | E37: Trade payables | F37: EUR '000 | G37: -3480 | H37: -3539.2 | I37: -3599.3 | J37: -3660.5 | K37: -3722.7 | L37: -3786 | M37: -3850.4 | N37: -3915.8 | O37: -3982.4 | P37: -4050.1 | Q37: -4119 | R37: -4189 | S37: -4260.2 | T37: -4332.6 | U37: -4406.3 | V37: -4481.2 | W37: -4557.4 | X37: -4634.8 | Y37: -4713.6 | Z37: -4793.8 | AA37: -4875.3 | AB37: -4958.1 | AC37: -5042.4 | AD37: -5128.2 | AF37: -3201.6 | AG37: -3857.7 | AH37: -3239.4 | AI37: -3843.5 | AJ37: -3499.4 | AK37: -4051.1 | AL37: -3542.4 | AM37: -4268.3 | AN37: -3584.2 | AO37: -4252.6 | AP37: -3871.8 | AQ37: -4482.2 | AR37: -3919.4 | AS37: -4722.6 | AT37: -3965.7 | AU37: -4705.3 | AV37: -4283.9 | AW37: -4959.3 | AX37: -4336.5 | AY37: -5225.2 | AZ37: -4387.7 | BA37: -5206.1 | BB37: -4739.9 | BC37: -5487.1
A38: Helios Software Ltd | B38: Accounts Payable | C38: CC-506 | D38: 2010 | E38: Accrued hosting costs | F38: EUR '000 | G38: -1280 | H38: -1301.8 | I38: -1323.9 | J38: -1346.4 | K38: -1369.3 | L38: -1392.6 | M38: -1416.2 | N38: -1440.3 | O38: -1464.8 | P38: -1489.7 | Q38: -1515 | R38: -1540.8 | S38: -1567 | T38: -1593.6 | U38: -1620.7 | V38: -1648.3 | W38: -1676.3 | X38: -1704.8 | Y38: -1733.8 | Z38: -1763.2 | AA38: -1793.2 | AB38: -1823.7 | AC38: -1854.7 | AD38: -1886.2 | AF38: -1164.8 | AG38: -1431.9 | AH38: -1257.7 | AI38: -1427.2 | AJ38: -1273.4 | AK38: -1504 | AL38: -1288.8 | AM38: -1584.3 | AN38: -1391.6 | AO38: -1579.1 | AP38: -1409 | AQ38: -1664 | AR38: -1425.9 | AS38: -1753 | AT38: -1539.7 | AU38: -1747.1 | AV38: -1558.9 | AW38: -1841.2 | AX38: -1577.7 | AY38: -1939.5 | AZ38: -1703.5 | BA38: -1933.1 | BB38: -1724.9 | BC38: -2037.1
A39: Helios Software Ltd | B39: Accounts Payable | C39: CC-506 | D39: 2020 | E39: Payroll & commission accruals | F39: EUR '000 | G39: -2380 | H39: -2420.5 | I39: -2461.6 | J39: -2503.5 | K39: -2546 | L39: -2589.3 | M39: -2633.3 | N39: -2678.1 | O39: -2723.6 | P39: -2769.9 | Q39: -2817 | R39: -2864.9 | S39: -2913.6 | T39: -2963.1 | U39: -3013.5 | V39: -3064.7 | W39: -3116.8 | X39: -3169.8 | Y39: -3223.7 | Z39: -3278.5 | AA39: -3334.2 | AB39: -3390.9 | AC39: -3448.6 | AD39: -3507.2 | AF39: -2142 | AG39: -2541.5 | AH39: -2313.9 | AI39: -2678.7 | AJ39: -2342.3 | AK39: -2822.3 | AL39: -2370 | AM39: -2812 | AN39: -2560.2 | AO39: -2963.8 | AP39: -2591.6 | AQ39: -3122.7 | AR39: -2622.2 | AS39: -3111.3 | AT39: -2832.7 | AU39: -3279.3 | AV39: -2867.5 | AW39: -3455.1 | AX39: -2901.3 | AY39: -3442.4 | AZ39: -3134.2 | BA39: -3628.3 | BB39: -3172.7 | BC39: -3822.8
A40: Helios Software Ltd | B40: Accounts Payable | C40: CC-506 | D40: 2030 | E40: VAT & payroll taxes payable | F40: EUR '000 | G40: -620 | H40: -630.5 | I40: -641.3 | J40: -652.2 | K40: -663.2 | L40: -674.5 | M40: -686 | N40: -697.7 | O40: -709.5 | P40: -721.6 | Q40: -733.8 | R40: -746.3 | S40: -759 | T40: -771.9 | U40: -785 | V40: -798.4 | W40: -811.9 | X40: -825.7 | Y40: -839.8 | Z40: -854.1 | AA40: -868.6 | AB40: -883.3 | AC40: -898.4 | AD40: -913.6 | AF40: -589 | AG40: -668.4 | AH40: -596.4 | AI40: -704.3 | AJ40: -603.6 | AK40: -742 | AL40: -651.7 | AM40: -739.5 | AN40: -659.8 | AO40: -779.3 | AP40: -667.8 | AQ40: -820.9 | AR40: -721.1 | AS40: -818.2 | AT40: -730.1 | AU40: -862.2 | AV40: -738.9 | AW40: -908.3 | AX40: -797.8 | AY40: -905.3 | AZ40: -807.8 | BA40: -954 | BB40: -817.5 | BC40: -1005
A41: Helios Software Ltd | B41: Accounts Payable | C41: CC-506 | D41: 2040 | E41: Deferred subscription billings | F41: EUR '000 | G41: -7850 | H41: -7983.4 | I41: -8119.2 | J41: -8257.2 | K41: -8397.6 | L41: -8540.3 | M41: -8685.5 | N41: -8833.2 | O41: -8983.3 | P41: -9136 | Q41: -9291.4 | R41: -9449.3 | S41: -9609.9 | T41: -9773.3 | U41: -9939.5 | V41: -10108.4 | W41: -10280.3 | X41: -10455 | Y41: -10632.8 | Z41: -10813.5 | AA41: -10997.4 | AB41: -11184.3 | AC41: -11374.5 | AD41: -11567.8 | AF41: -7379 | AG41: -8542.3 | AH41: -7469.6 | AI41: -9000.3 | AJ41: -7557.8 | AK41: -8967.3 | AL41: -8164.4 | AM41: -9451.5 | AN41: -8264.7 | AO41: -9958.3 | AP41: -8362.2 | AQ41: -9921.8 | AR41: -9033.4 | AS41: -10457.5 | AT41: -9144.3 | AU41: -11018.2 | AV41: -9252.3 | AW41: -10977.8 | AX41: -9994.8 | AY41: -11570.5 | AZ41: -10117.6 | BA41: -12190.9 | BB41: -10237 | BC41: -12146.2
A42: Helios Software Ltd | B42: Accounts Payable | C42: CC-506 | D42: 2050 | E42: Other accruals | F42: EUR '000 | G42: -940 | H42: -956 | I42: -972.2 | J42: -988.8 | K42: -1005.6 | L42: -1022.7 | M42: -1040 | N42: -1057.7 | O42: -1075.7 | P42: -1094 | Q42: -1112.6 | R42: -1131.5 | S42: -1150.7 | T42: -1170.3 | U42: -1190.2 | V42: -1210.4 | W42: -1231 | X42: -1251.9 | Y42: -1273.2 | Z42: -1294.9 | AA42: -1316.9 | AB42: -1339.3 | AC42: -1362 | AD42: -1385.2 | AF42: -874.2 | AG42: -1032.5 | AH42: -884.7 | AI42: -1087.6 | AJ42: -955.3 | AK42: -1084 | AL42: -967.2 | AM42: -1142.3 | AN42: -978.9 | AO42: -1203.4 | AP42: -1057 | AQ42: -1199.4 | AR42: -1070.2 | AS42: -1263.9 | AT42: -1083.1 | AU42: -1331.5 | AV42: -1169.5 | AW42: -1327.1 | AX42: -1184.1 | AY42: -1398.5 | AZ42: -1198.4 | BA42: -1473.2 | BB42: -1293.9 | BC42: -1468.3
