Workbook

Sheet P&L
B2: P&L Flash Input
B3: [Company Name]
C4: 45658 | D4: 45689 | E4: 45717 | F4: 45748 | G4: 45778 | H4: 45809 | I4: 45839 | J4: 45870 | K4: 45901 | L4: 45931 | M4: 45962 | N4: 45992
B5: Revenue | C5: 1 | D5: 1 | E5: 1 | F5: 1 | G5: 1 | H5: 1 | I5: 1 | J5: 1 | K5: 1 | L5: 1 | M5: 1 | N5: 1
B6: Budget | C6: 1 | D6: 1 | E6: 1 | F6: 1 | G6: 1 | H6: 1 | I6: 1 | J6: 1 | K6: 1 | L6: 1 | M6: 1 | N6: 1
B7: Cost of Goods Sold | C7: 1 | D7: 1 | E7: 1 | F7: 1 | G7: 1 | H7: 1 | I7: 1 | J7: 1 | K7: 1 | L7: 1 | M7: 1 | N7: 1
B8: Budget | C8: 1 | D8: 1 | E8: 1 | F8: 1 | G8: 1 | H8: 1 | I8: 1 | J8: 1 | K8: 1 | L8: 1 | M8: 1 | N8: 1
B9: Gross Profit | C9: =C5-C7 -> 0 | D9: =D5-D7 -> 0 | E9: =E5-E7 -> 0 | F9: =F5-F7 -> 0 | G9: =G5-G7 -> 0 | H9: =H5-H7 -> 0 | I9: =I5-I7 -> 0 | J9: =J5-J7 -> 0 | ... N9: =N5-N7 -> 0
B10: Budget | C10: =C6-C8 -> 0 | D10: =D6-D8 -> 0 | E10: =E6-E8 -> 0 | F10: =F6-F8 -> 0 | G10: =G6-G8 -> 0 | H10: =H6-H8 -> 0 | I10: =I6-I8 -> 0 | J10: =J6-J8 -> 0 | ... N10: =N6-N8 -> 0
B12: Operating Expenses | C12: 1 | D12: 1 | E12: 1 | F12: 1 | G12: 1 | H12: 1 | I12: 1 | J12: 1 | K12: 1 | L12: 1 | M12: 1 | N12: 1
B13: Budget | C13: 1 | D13: 1 | E13: 1 | F13: 1 | G13: 1 | H13: 1 | I13: 1 | J13: 1 | K13: 1 | L13: 1 | M13: 1 | N13: 1
B15: EBITDA | C15: =C9-C12 -> -1 | D15: =D9-D12 -> -1 | E15: =E9-E12 -> -1 | F15: =F9-F12 -> -1 | G15: =G9-G12 -> -1 | H15: =H9-H12 -> -1 | I15: =I9-I12 -> -1 | J15: =J9-J12 -> -1 | ... N15: =N9-N12 -> -1
B16: Budget | C16: =C10-C13 -> -1 | D16: =D10-D13 -> -1 | E16: =E10-E13 -> -1 | F16: =F10-F13 -> -1 | G16: =G10-G13 -> -1 | H16: =H10-H13 -> -1 | I16: =I10-I13 -> -1 | J16: =J10-J13 -> -1 | ... N16: =N10-N13 -> -1
B18: EBITDA Adjustments
B19: Adj Type | C19: 45658 | D19: 45689 | E19: 45717 | F19: 45748 | G19: 45778 | H19: 45809 | I19: 45839 | J19: 45870 | K19: 45901 | L19: 45931 | M19: 45962 | N19: 45992 | O19: YTD
B20: One-Time Restructuring | C20: 25 | D20: 30 | E20: 20 | F20: 15 | G20: 10 | H20: 5 | I20: 0 | J20: 0 | K20: 0 | L20: 0 | M20: 0 | O20: =SUM(C20:N20) -> 105
B21: Transaction Costs | C21: 0 | D21: 0 | E21: 0 | F21: 50 | G21: 75 | H21: 100 | I21: 50 | J21: 25 | K21: 10 | L21: 5 | M21: 0 | O21: =SUM(C21:N21) -> 315
B22: Non-Cash Stock Comp | C22: 12 | D22: 12 | E22: 12 | F22: 15 | G22: 15 | H22: 15 | I22: 18 | J22: 18 | K22: 18 | L22: 20 | M22: 20 | O22: =SUM(C22:N22) -> 175
B23: Management Fees | C23: 8 | D23: 8 | E23: 8 | F23: 8 | G23: 8 | H23: 8 | I23: 8 | J23: 8 | K23: 8 | L23: 8 | M23: 8 | O23: =SUM(C23:N23) -> 88
B24: Integration Costs | C24: 0 | D24: 0 | E24: 0 | F24: 0 | G24: 0 | H24: 0 | I24: 35 | J24: 45 | K24: 40 | L24: 30 | M24: 20 | O24: =SUM(C24:N24) -> 170
O25: =SUM(C25:N25) -> 0
O26: =SUM(C26:N26) -> 0
O27: =SUM(C27:N27) -> 0
B28: Total Adjustments | C28: =SUM(C20:C27) -> 45 | D28: =SUM(D20:D27) -> 50 | E28: =SUM(E20:E27) -> 40 | F28: =SUM(F20:F27) -> 88 | G28: =SUM(G20:G27) -> 108 | H28: =SUM(H20:H27) -> 128 | I28: =SUM(I20:I27) -> 111 | J28: =SUM(J20:J27) -> 96 | ... O28: =SUM(O20:O27) -> 853
B29: Adjusted EBITDA | C29: =C15+C28 -> 44 | D29: =D15+D28 -> 49 | E29: =E15+E28 -> 39 | F29: =F15+F28 -> 87 | G29: =G15+G28 -> 107 | H29: =H15+H28 -> 127 | I29: =I15+I28 -> 110 | J29: =J15+J28 -> 95 | ... N29: =N15+N28 -> -1 | O29: =SUM(C29:N29) -> 841
B31: Depreciation | C31: 30 | D31: 30 | E31: 30 | F31: 32 | G31: 32 | H31: 32 | I31: 35 | J31: 35 | K31: 35 | L31: 38 | M31: 38
B32: Budget
B33: Amortization | C33: 15 | D33: 15 | E33: 15 | F33: 16 | G33: 16 | H33: 16 | I33: 18 | J33: 18 | K33: 18 | L33: 20 | M33: 20
B34: Budget
B35: EBIT | C35: =C15-C31-C33 -> -46 | D35: =C29-D31-D33 -> -1 | E35: =D29-E31-E33 -> 4 | F35: =E29-F31-F33 -> -9 | G35: =F29-G31-G33 -> 39 | H35: =G29-H31-H33 -> 59 | I35: =H29-I31-I33 -> 74 | J35: =I29-J31-J33 -> 57 | K35: =J29-K31-K33 -> 42 | ... M35: =L29-M31-M33 -> 4 | N35: =N29-N31-N33 -> -1
B36: Budget | C36: =C16-C32-C34 -> -1 | D36: =D16-D32-D34 -> -1 | E36: =E16-E32-E34 -> -1 | F36: =F16-F32-F34 -> -1 | G36: =G16-G32-G34 -> -1 | H36: =H16-H32-H34 -> -1 | I36: =I16-I32-I34 -> -1 | J36: =J16-J32-J34 -> -1 | ... N36: =N16-N32-N34 -> -1
B38: Interest Expense | C38: 45 | D38: 44 | E38: 43 | F38: 42 | G38: 41 | H38: 40 | I38: 39 | J38: 38 | K38: 37 | L38: 36 | M38: 35
B39: Budget
B40: Other Income / (Expense) | C40: 5 | D40: 3 | E40: 8 | F40: 4 | G40: 6 | H40: 2 | I40: 7 | J40: 5 | K40: 9 | L40: 3 | M40: 6
B41: Budget
B42: EBT | C42: =C35-C38+C40 -> -86 | D42: =D35-D38+D40 -> -42 | E42: =E35-E38+E40 -> -31 | F42: =F35-F38+F40 -> -47 | G42: =G35-G38+G40 -> 4 | H42: =H35-H38+H40 -> 21 | I42: =I35-I38+I40 -> 42 | J42: =J35-J38+J40 -> 24 | ... N42: =N35-N38+N40 -> -1
B43: Budget | C43: =C36-C39+C41 -> -1 | D43: =D36-D39+D41 -> -1 | E43: =E36-E39+E41 -> -1 | F43: =F36-F39+F41 -> -1 | G43: =G36-G39+G41 -> -1 | H43: =H36-H39+H41 -> -1 | I43: =I36-I39+I41 -> -1 | J43: =J36-J39+J41 -> -1 | ... N43: =N36-N39+N41 -> -1
B44: Tax Expense | C44: =C42*0.25 -> -21.5 | D44: =D42*0.25 -> -10.5 | E44: =E42*0.25 -> -7.75 | F44: =F42*0.25 -> -11.75 | G44: =G42*0.25 -> 1 | H44: =H42*0.25 -> 5.25 | I44: =I42*0.25 -> 10.5 | J44: =J42*0.25 -> 6 | ... N44: =N42*0.25 -> -0.25
B45: Budget | C45: =C43*0.25 -> -0.25 | D45: =D43*0.25 -> -0.25 | E45: =E43*0.25 -> -0.25 | F45: =F43*0.25 -> -0.25 | G45: =G43*0.25 -> -0.25 | H45: =H43*0.25 -> -0.25 | I45: =I43*0.25 -> -0.25 | J45: =J43*0.25 -> -0.25 | ... N45: =N43*0.25 -> -0.25
B46: Net Income | C46: =C42-C44 -> -64.5 | D46: =D42-D44 -> -31.5 | E46: =E42-E44 -> -23.25 | F46: =F42-F44 -> -35.25 | G46: =G42-G44 -> 3 | H46: =H42-H44 -> 15.75 | I46: =I42-I44 -> 31.5 | J46: =J42-J44 -> 18 | ... N46: =N42-N44 -> -0.75
...

Sheet BS
B2: Balance Sheet Flash Input
B3: [Company Name]
C4: 45658 | D4: 45689 | E4: 45717 | F4: 45748 | G4: 45778 | H4: 45809 | I4: 45839 | J4: 45870 | K4: 45901 | L4: 45931 | M4: 45962 | N4: 45992
B5: ASSETS
B6: Cash & Cash Equivalents | C6: 850 | D6: 920 | E6: 880 | F6: 950 | G6: 1020 | H6: 980 | I6: 1100 | J6: 1150 | K6: 1080 | L6: 1200 | M6: 1280
B7: Budget
B8: Accounts Receivable | C8: 620 | D8: 650 | E8: 610 | F8: 680 | G8: 710 | H8: 660 | I8: 740 | J8: 760 | K8: 720 | L8: 780 | M8: 810
B9: Budget
B10: Inventory | C10: 380 | D10: 400 | E10: 390 | F10: 420 | G10: 440 | H10: 410 | I10: 460 | J10: 480 | K10: 450 | L10: 490 | M10: 510
B11: Budget
B12: Prepaid Expenses | C12: 45 | D12: 48 | E12: 42 | F12: 50 | G12: 52 | H12: 48 | I12: 55 | J12: 58 | K12: 54 | L12: 60 | M12: 62
B13: Budget
B14: Total Current Assets | C14: =SUM(C6,C8,C10,C12) -> 1895 | D14: =SUM(D6,D8,D10,D12) -> 2018 | E14: =SUM(E6,E8,E10,E12) -> 1922 | F14: =SUM(F6,F8,F10,F12) -> 2100 | G14: =SUM(G6,G8,G10,G12) -> 2222 | H14: =SUM(H6,H8,H10,H12) -> 2098 | I14: =SUM(I6,I8,I10,I12) -> 2355 | J14: =SUM(J6,J8,J10,J12) -> 2448 | ... N14: =SUM(N6,N8,N10,N12) -> 0
B15: Budget | C15: =SUM(C7,C9,C11,C13) -> 0 | D15: =SUM(D7,D9,D11,D13) -> 0 | E15: =SUM(E7,E9,E11,E13) -> 0 | F15: =SUM(F7,F9,F11,F13) -> 0 | G15: =SUM(G7,G9,G11,G13) -> 0 | H15: =SUM(H7,H9,H11,H13) -> 0 | I15: =SUM(I7,I9,I11,I13) -> 0 | J15: =SUM(J7,J9,J11,J13) -> 0 | ... N15: =SUM(N7,N9,N11,N13) -> 0
B17: PP&E (Net) | C17: 2200 | D17: 2180 | E17: 2160 | F17: 2140 | G17: 2120 | H17: 2100 | I17: 2080 | J17: 2060 | K17: 2040 | L17: 2020 | M17: 2000
B18: Budget
B19: Intangibles | C19: 450 | D19: 445 | E19: 440 | F19: 435 | G19: 430 | H19: 425 | I19: 420 | J19: 415 | K19: 410 | L19: 405 | M19: 400
B20: Budget
B21: Goodwill | C21: 1200 | D21: 1200 | E21: 1200 | F21: 1200 | G21: 1200 | H21: 1200 | I21: 1200 | J21: 1200 | K21: 1200 | L21: 1200 | M21: 1200
B22: Budget
B23: Total Assets | C23: =C14+C17+C19+C21 -> 5745 | D23: =D14+D17+D19+D21 -> 5843 | E23: =E14+E17+E19+E21 -> 5722 | F23: =F14+F17+F19+F21 -> 5875 | G23: =G14+G17+G19+G21 -> 5972 | H23: =H14+H17+H19+H21 -> 5823 | I23: =I14+I17+I19+I21 -> 6055 | J23: =J14+J17+J19+J21 -> 6123 | ... N23: =N14+N17+N19+N21 -> 0
B24: Budget | C24: =C15+C18+C20+C22 -> 0 | D24: =D15+D18+D20+D22 -> 0 | E24: =E15+E18+E20+E22 -> 0 | F24: =F15+F18+F20+F22 -> 0 | G24: =G15+G18+G20+G22 -> 0 | H24: =H15+H18+H20+H22 -> 0 | I24: =I15+I18+I20+I22 -> 0 | J24: =J15+J18+J20+J22 -> 0 | ... N24: =N15+N18+N20+N22 -> 0
B26: LIABILITIES
B27: Accounts Payable | C27: 280 | D27: 295 | E27: 275 | F27: 310 | G27: 325 | H27: 300 | I27: 340 | J27: 355 | K27: 330 | L27: 370 | M27: 385
B28: Budget
B29: Accrued Expenses | C29: 180 | D29: 190 | E29: 175 | F29: 200 | G29: 210 | H29: 195 | I29: 220 | J29: 230 | K29: 215 | L29: 240 | M29: 250
B30: Budget
B31: Short-Term Debt | C31: 250 | D31: 250 | E31: 250 | F31: 250 | G31: 250 | H31: 250 | I31: 250 | J31: 250 | K31: 250 | L31: 250 | M31: 250
B32: Budget
B33: Total Current Liabilities | C33: =SUM(C27,C29,C31) -> 710 | D33: =SUM(D27,D29,D31) -> 735 | E33: =SUM(E27,E29,E31) -> 700 | F33: =SUM(F27,F29,F31) -> 760 | G33: =SUM(G27,G29,G31) -> 785 | H33: =SUM(H27,H29,H31) -> 745 | I33: =SUM(I27,I29,I31) -> 810 | J33: =SUM(J27,J29,J31) -> 835 | ... N33: =SUM(N27,N29,N31) -> 0
B34: Budget | C34: =SUM(C28,C30,C32) -> 0 | D34: =SUM(D28,D30,D32) -> 0 | E34: =SUM(E28,E30,E32) -> 0 | F34: =SUM(F28,F30,F32) -> 0 | G34: =SUM(G28,G30,G32) -> 0 | H34: =SUM(H28,H30,H32) -> 0 | I34: =SUM(I28,I30,I32) -> 0 | J34: =SUM(J28,J30,J32) -> 0 | ... N34: =SUM(N28,N30,N32) -> 0
B36: Long-Term Debt | C36: 2800 | D36: 2750 | E36: 2700 | F36: 2650 | G36: 2600 | H36: 2550 | I36: 2500 | J36: 2450 | K36: 2400 | L36: 2350 | M36: 2300
B37: Budget
B38: Total Liabilities | C38: =C33+C36 -> 3510 | D38: =D33+D36 -> 3485 | E38: =E33+E36 -> 3400 | F38: =F33+F36 -> 3410 | G38: =G33+G36 -> 3385 | H38: =H33+H36 -> 3295 | I38: =I33+I36 -> 3310 | J38: =J33+J36 -> 3285 | ... N38: =N33+N36 -> 0
B39: Budget | C39: =C34+C37 -> 0 | D39: =D34+D37 -> 0 | E39: =E34+E37 -> 0 | F39: =F34+F37 -> 0 | G39: =G34+G37 -> 0 | H39: =H34+H37 -> 0 | I39: =I34+I37 -> 0 | J39: =J34+J37 -> 0 | ... N39: =N34+N37 -> 0
B41: EQUITY
B42: Total Equity | C42: =C23-C38 -> 2235 | D42: =D23-D38 -> 2358 | E42: =E23-E38 -> 2322 | F42: =F23-F38 -> 2465 | G42: =G23-G38 -> 2587 | H42: =H23-H38 -> 2528 | I42: =I23-I38 -> 2745 | J42: =J23-J38 -> 2838 | ... N42: =N23-N38 -> 0
B43: Budget | C43: =C24-C39 -> 0 | D43: =D24-D39 -> 0 | E43: =E24-E39 -> 0 | F43: =F24-F39 -> 0 | G43: =G24-G39 -> 0 | H43: =H24-H39 -> 0 | I43: =I24-I39 -> 0 | J43: =J24-J39 -> 0 | ... N43: =N24-N39 -> 0
B44: Total Liabilities & Equity | C44: =C38+C42 -> 5745 | D44: =D38+D42 -> 5843 | E44: =E38+E42 -> 5722 | F44: =F38+F42 -> 5875 | G44: =G38+G42 -> 5972 | H44: =H38+H42 -> 5823 | I44: =I38+I42 -> 6055 | J44: =J38+J42 -> 6123 | ... N44: =N38+N42 -> 0
B45: Budget | C45: =C39+C43 -> 0 | D45: =D39+D43 -> 0 | E45: =E39+E43 -> 0 | F45: =F39+F43 -> 0 | G45: =G39+G43 -> 0 | H45: =H39+H43 -> 0 | I45: =I39+I43 -> 0 | J45: =J39+J43 -> 0 | ... N45: =N39+N43 -> 0

Sheet Cash-Flow
B2: Cash Flow Flash Input
B3: [Company Name]
C4: 45658 | D4: 45689 | E4: 45717 | F4: 45748 | G4: 45778 | H4: 45809 | I4: 45839 | J4: 45870 | K4: 45901 | L4: 45931 | M4: 45962 | N4: 45992
B5: OPERATING ACTIVITIES
B6: Net Income | C6: 266 | D6: 281 | E6: 268 | F6: 296 | G6: 314 | H6: 291 | I6: 328 | J6: 329 | K6: 326 | L6: 332 | M6: 341
B7: Budget
B8: (+) Depreciation & Amort | C8: 45 | D8: 45 | E8: 45 | F8: 48 | G8: 48 | H8: 48 | I8: 53 | J8: 53 | K8: 53 | L8: 58 | M8: 58
B9: Budget
B10: (+/-) Working Capital Changes | C10: -10 | D10: -15 | E10: 25 | F10: -40 | G10: -25 | H10: 30 | I10: -50 | J10: -20 | K10: 35 | L10: -45 | M10: -25
B11: Budget
B12: Cash from Operations | C12: =SUM(C6,C8,C10) -> 301 | D12: =SUM(D6,D8,D10) -> 311 | E12: =SUM(E6,E8,E10) -> 338 | F12: =SUM(F6,F8,F10) -> 304 | G12: =SUM(G6,G8,G10) -> 337 | H12: =SUM(H6,H8,H10) -> 369 | I12: =SUM(I6,I8,I10) -> 331 | J12: =SUM(J6,J8,J10) -> 362 | ... N12: =SUM(N6,N8,N10) -> 0
B13: Budget | C13: =SUM(C7,C9,C11) -> 0 | D13: =SUM(D7,D9,D11) -> 0 | E13: =SUM(E7,E9,E11) -> 0 | F13: =SUM(F7,F9,F11) -> 0 | G13: =SUM(G7,G9,G11) -> 0 | H13: =SUM(H7,H9,H11) -> 0 | I13: =SUM(I7,I9,I11) -> 0 | J13: =SUM(J7,J9,J11) -> 0 | ... N13: =SUM(N7,N9,N11) -> 0
B15: INVESTING ACTIVITIES
B16: CapEx | C16: -50 | D16: -55 | E16: -45 | F16: -60 | G16: -65 | H16: -50 | I16: -70 | J16: -75 | K16: -55 | L16: -80 | M16: -85
B17: Budget
B18: Acquisitions / Disposals | C18: 0 | D18: 0 | E18: 0 | F18: 0 | G18: 0 | H18: 0 | I18: 0 | J18: 0 | K18: 0 | L18: 0 | M18: 0
B19: Budget
B20: Cash from Investing | C20: =SUM(C16,C18) -> -50 | D20: =SUM(D16,D18) -> -55 | E20: =SUM(E16,E18) -> -45 | F20: =SUM(F16,F18) -> -60 | G20: =SUM(G16,G18) -> -65 | H20: =SUM(H16,H18) -> -50 | I20: =SUM(I16,I18) -> -70 | J20: =SUM(J16,J18) -> -75 | ... N20: =SUM(N16,N18) -> 0
B21: Budget | C21: =SUM(C17,C19) -> 0 | D21: =SUM(D17,D19) -> 0 | E21: =SUM(E17,E19) -> 0 | F21: =SUM(F17,F19) -> 0 | G21: =SUM(G17,G19) -> 0 | H21: =SUM(H17,H19) -> 0 | I21: =SUM(I17,I19) -> 0 | J21: =SUM(J17,J19) -> 0 | ... N21: =SUM(N17,N19) -> 0
B23: FINANCING ACTIVITIES
B24: Debt Draws / (Repayments) | C24: -50 | D24: -50 | E24: -50 | F24: -50 | G24: -50 | H24: -50 | I24: -50 | J24: -50 | K24: -50 | L24: -50 | M24: -50
B25: Budget
B26: Dividends / Distributions | C26: 0 | D26: 0 | E26: 0 | F26: -100 | G26: 0 | H26: 0 | I26: -100 | J26: 0 | K26: 0 | L26: -100 | M26: 0
B27: Budget
B28: Cash from Financing | C28: =SUM(C24,C26) -> -50 | D28: =SUM(D24,D26) -> -50 | E28: =SUM(E24,E26) -> -50 | F28: =SUM(F24,F26) -> -150 | G28: =SUM(G24,G26) -> -50 | H28: =SUM(H24,H26) -> -50 | I28: =SUM(I24,I26) -> -150 | J28: =SUM(J24,J26) -> -50 | ... N28: =SUM(N24,N26) -> 0
B29: Budget | C29: =SUM(C25,C27) -> 0 | D29: =SUM(D25,D27) -> 0 | E29: =SUM(E25,E27) -> 0 | F29: =SUM(F25,F27) -> 0 | G29: =SUM(G25,G27) -> 0 | H29: =SUM(H25,H27) -> 0 | I29: =SUM(I25,I27) -> 0 | J29: =SUM(J25,J27) -> 0 | ... N29: =SUM(N25,N27) -> 0
B31: Net Change in Cash | C31: =C12+C20+C28 -> 201 | D31: =D12+D20+D28 -> 206 | E31: =E12+E20+E28 -> 243 | F31: =F12+F20+F28 -> 94 | G31: =G12+G20+G28 -> 222 | H31: =H12+H20+H28 -> 269 | I31: =I12+I20+I28 -> 111 | J31: =J12+J20+J28 -> 237 | ... N31: =N12+N20+N28 -> 0
B32: Budget | C32: =C13+C21+C29 -> 0 | D32: =D13+D21+D29 -> 0 | E32: =E13+E21+E29 -> 0 | F32: =F13+F21+F29 -> 0 | G32: =G13+G21+G29 -> 0 | H32: =H13+H21+H29 -> 0 | I32: =I13+I21+I29 -> 0 | J32: =J13+J21+J29 -> 0 | ... N32: =N13+N21+N29 -> 0
B33: Beginning Cash | C33: 800 | D33: 851 | E33: 886 | F33: 929 | G33: 973 | H33: 1095 | I33: 1264 | J33: 1325 | K33: 1462 | L33: 1671 | M33: 1686
B34: Budget
B35: Ending Cash | C35: =C33+C31 -> 1001 | D35: =D33+D31 -> 1057 | E35: =E33+E31 -> 1129 | F35: =F33+F31 -> 1023 | G35: =G33+G31 -> 1195 | H35: =H33+H31 -> 1364 | I35: =I33+I31 -> 1375 | J35: =J33+J31 -> 1562 | ... N35: =N33+N31 -> 0
B36: Budget | C36: =C34+C32 -> 0 | D36: =D34+D32 -> 0 | E36: =E34+E32 -> 0 | F36: =F34+F32 -> 0 | G36: =G34+G32 -> 0 | H36: =H34+H32 -> 0 | I36: =I34+I32 -> 0 | J36: =J34+J32 -> 0 | ... N36: =N34+N32 -> 0

Sheet KPI
B2: KPI Flash Input
B3: [Company Name]
C4: 45658 | D4: 45689 | E4: 45717 | F4: 45748 | G4: 45778 | H4: 45809 | I4: 45839 | J4: 45870 | K4: 45901 | L4: 45931 | M4: 45962 | N4: 45992
B5: FINANCIAL KPIs
B6: Revenue Growth (MoM %) | C6: 0.02 | D6: 0.04 | E6: -0.06 | F6: 0.1 | G6: 0.04 | H6: -0.05 | I6: 0.09 | J6: 0.01 | K6: -0.03 | L6: 0.05 | M6: 0.02
B7: Gross Margin (%) | C7: 0.6 | D7: 0.6 | E7: 0.6 | F7: 0.6 | G7: 0.6 | H7: 0.6 | I7: 0.6 | J7: 0.6 | K7: 0.6 | L7: 0.6 | M7: 0.6
B8: EBITDA Margin (%) | C8: 0.37 | D8: 0.37 | E8: 0.36 | F8: 0.38 | G8: 0.38 | H8: 0.37 | I8: 0.39 | J8: 0.39 | K8: 0.38 | L8: 0.4 | M8: 0.37
B9: Net Income Margin (%) | C9: 0.22 | D9: 0.22 | E9: 0.23 | F9: 0.23 | G9: 0.23 | H9: 0.23 | I9: 0.25 | J9: 0.25 | K9: 0.24 | L9: 0.28 | M9: 0.23
B10: Revenue per Employee ($K) | C10: 12 | D10: 12.3 | E10: 11.5 | F10: 12.6 | G10: 12.8 | H10: 11.9 | I10: 13.1 | J10: 13.2 | K10: 12.5 | L10: 13 | M10: 13.1
B11: 0
B12: OPERATIONAL KPIs
B13: Headcount (FTEs) | C13: 100 | D13: 102 | E13: 103 | F13: 103 | G13: 106 | H13: 108 | I13: 107 | J13: 108 | K13: 110 | L13: 112 | M13: 113
B14: New Hires | C14: 4 | D14: 5 | E14: 3 | F14: 2 | G14: 6 | H14: 4 | I14: 2 | J14: 3 | K14: 5 | L14: 4 | M14: 3
B15: Voluntary Attrition | C15: 2 | D15: 3 | E15: 2 | F15: 2 | G15: 3 | H15: 2 | I15: 3 | J15: 2 | K15: 3 | L15: 2 | M15: 2
B16: Customer Count | C16: 450 | D16: 458 | E16: 462 | F16: 470 | G16: 480 | H16: 485 | I16: 495 | J16: 502 | K16: 510 | L16: 520 | M16: 528
B17: New Customers | C17: 12 | D17: 14 | E17: 10 | F17: 15 | G17: 18 | H17: 12 | I17: 16 | J17: 14 | K17: 15 | L17: 18 | M17: 14
B18: Churned Customers | C18: 4 | D18: 6 | E18: 6 | F18: 7 | G18: 8 | H18: 7 | I18: 6 | J18: 7 | K18: 7 | L18: 8 | M18: 6
B19: Net Revenue Retention (%) | C19: 1.05 | D19: 1.06 | E19: 1.04 | F19: 1.08 | G19: 1.07 | H19: 1.05 | I19: 1.09 | J19: 1.08 | K19: 1.06 | L19: 1.1 | M19: 1.07
B20: 0
B21: WORKING CAPITAL KPIs
B22: Days Sales Outstanding (DSO) | C22: 45 | D22: 48 | E22: 47 | F22: 50 | G22: 52 | H22: 49 | I22: 55 | J22: 56 | K22: 53 | L22: 58 | M22: 60
B23: Days Inventory Outstanding (DIO) | C23: 28 | D23: 30 | E23: 29 | F23: 32 | G23: 33 | H23: 31 | I23: 35 | J23: 36 | K23: 34 | L23: 38 | M23: 39
B24: Days Payable Outstanding (DPO) | C24: 35 | D24: 37 | E24: 36 | F24: 40 | G24: 42 | H24: 38 | I24: 44 | J24: 45 | K24: 42 | L24: 48 | M24: 50
B25: Cash Conversion Cycle | C25: =C22+C23-C24 -> 38 | D25: =D22+D23-D24 -> 41 | E25: =E22+E23-E24 -> 40 | F25: =F22+F23-F24 -> 42 | G25: =G22+G23-G24 -> 43 | H25: =H22+H23-H24 -> 42 | I25: =I22+I23-I24 -> 46 | J25: =J22+J23-J24 -> 47 | ... M25: =M22+M23-M24 -> 49

Sheet Debt-Ratio
B2: Debt Ratio Flash Input
B3: [Company Name]
C4: 45658 | D4: 45689 | E4: 45717 | F4: 45748 | G4: 45778 | H4: 45809 | I4: 45839 | J4: 45870 | K4: 45901 | L4: 45931 | M4: 45962 | N4: 45992
B5: DEBT & CAPITAL METRICS
B6: Total Debt Outstanding | C6: {='Debt-Overview'!C25} -> 3050 | D6: {='Debt-Overview'!D25} -> 3000 | E6: {='Debt-Overview'!E25} -> 3000 | F6: {='Debt-Overview'!F25} -> 2925 | G6: {='Debt-Overview'!G25} -> 2850 | H6: {='Debt-Overview'!H25} -> 2850 | I6: {='Debt-Overview'!I25} -> 2775 | J6: {='Debt-Overview'!J25} -> 2750 | ... N6: {='Debt-Overview'!N25} -> 0
B7: Cash & Cash Equivalents | C7: {=BS!C6} -> 850 | D7: {=BS!D6} -> 920 | E7: {=BS!E6} -> 880 | F7: {=BS!F6} -> 950 | G7: {=BS!G6} -> 1020 | H7: {=BS!H6} -> 980 | I7: {=BS!I6} -> 1100 | J7: {=BS!J6} -> 1150 | ... N7: {=BS!N6} -> 0
B8: Net Debt | C8: =C6-C7 -> 2200 | D8: =D6-D7 -> 2080 | E8: =E6-E7 -> 2120 | F8: =F6-F7 -> 1975 | G8: =G6-G7 -> 1830 | H8: =H6-H7 -> 1870 | I8: =I6-I7 -> 1675 | J8: =J6-J7 -> 1600 | ... N8: =N6-N7 -> 0
B9: Total Enterprise Value (TEV) | C9: 8500 | D9: 8600 | E9: 8700 | F9: 8800 | G9: 8900 | H9: 9000 | I9: 9100 | J9: 9200 | K9: 9300 | L9: 9400 | M9: 9500
B10: Equity Value (TEV - Net Debt) | C10: =C9-C8 -> 6300 | D10: =D9-D8 -> 6520 | E10: =E9-E8 -> 6580 | F10: =F9-F8 -> 6825 | G10: =G9-G8 -> 7070 | H10: =H9-H8 -> 7130 | I10: =I9-I8 -> 7425 | J10: =J9-J8 -> 7600 | ... N10: =N9-N8 -> 0
B12: EBITDA METRICS (Monthly)
B13: EBITDA (Reported) | C13: {='P&L'!C15} -> -1 | D13: {='P&L'!D15} -> -1 | E13: {='P&L'!E15} -> -1 | F13: {='P&L'!F15} -> -1 | G13: {='P&L'!G15} -> -1 | H13: {='P&L'!H15} -> -1 | I13: {='P&L'!I15} -> -1 | J13: {='P&L'!J15} -> -1 | ... N13: {='P&L'!N15} -> -1
B14: Adjusted EBITDA | C14: {='P&L'!C29} -> 44 | D14: {='P&L'!D29} -> 49 | E14: {='P&L'!E29} -> 39 | F14: {='P&L'!F29} -> 87 | G14: {='P&L'!G29} -> 107 | H14: {='P&L'!H29} -> 127 | I14: {='P&L'!I29} -> 110 | J14: {='P&L'!J29} -> 95 | ... N14: {='P&L'!N29} -> -1
B15: Run-Rate EBITDA (Input) | C15: 5300 | D15: 5400 | E15: 5450 | F15: 5550 | G15: 5650 | H15: 5700 | I15: 5850 | J15: 5950 | K15: 6000 | L15: 6150 | M15: 6250
B16: Revenue | C16: {='P&L'!C5} -> 1 | D16: {='P&L'!D5} -> 1 | E16: {='P&L'!E5} -> 1 | F16: {='P&L'!F5} -> 1 | G16: {='P&L'!G5} -> 1 | H16: {='P&L'!H5} -> 1 | I16: {='P&L'!I5} -> 1 | J16: {='P&L'!J5} -> 1 | ... N16: {='P&L'!N5} -> 1
B18: LEVERAGE RATIOS
B19: Gross Leverage (Debt / Adj EBITDA) | C19: =IF(C14=0,"",C6/C14) -> 69.318182 | D19: =IF(D14=0,"",D6/D14) -> 61.22449 | E19: =IF(E14=0,"",E6/E14) -> 76.923077 | F19: =IF(F14=0,"",F6/F14) -> 33.62069 | G19: =IF(G14=0,"",G6/G14) -> 26.635514 | H19: =IF(H14=0,"",H6/H14) -> 22.440945 | I19: =IF(I14=0,"",I6/I14) -> 25.227273 | J19: =IF(J14=0,"",J6/J14) -> 28.947368 | ... N19: =IF(N14=0,"",N6/N14) -> 0
B20: Net Leverage (Net Debt / Adj EBITDA) | C20: =IF(C14=0,"",C8/C14) -> 50 | D20: =IF(D14=0,"",D8/D14) -> 42.44898 | E20: =IF(E14=0,"",E8/E14) -> 54.358974 | F20: =IF(F14=0,"",F8/F14) -> 22.701149 | G20: =IF(G14=0,"",G8/G14) -> 17.102804 | H20: =IF(H14=0,"",H8/H14) -> 14.724409 | I20: =IF(I14=0,"",I8/I14) -> 15.227273 | J20: =IF(J14=0,"",J8/J14) -> 16.842105 | ... N20: =IF(N14=0,"",N8/N14) -> 0
B21: Senior Leverage (if applicable) | C21: 2.8 | D21: 2.7 | E21: 2.6 | F21: 2.5 | G21: 2.4 | H21: 2.3 | I21: 2.2 | J21: 2.1 | K21: 2 | L21: 1.9 | M21: 1.8
B22: First Lien Leverage | C22: 2.2 | D22: 2.1 | E22: 2 | F22: 1.9 | G22: 1.8 | H22: 1.7 | I22: 1.6 | J22: 1.5 | K22: 1.4 | L22: 1.3 | M22: 1.2
B23: Secured Leverage | C23: 2.5 | D23: 2.4 | E23: 2.3 | F23: 2.2 | G23: 2.1 | H23: 2 | I23: 1.9 | J23: 1.8 | K23: 1.7 | L23: 1.6 | M23: 1.5
B25: COVERAGE RATIOS
B26: Est. Monthly Cash Interest | C26: ='Debt-Overview'!C25*'Debt-Overview'!C33/12 -> 16.614969 | D26: ='Debt-Overview'!D25*'Debt-Overview'!D33/12 -> 16.343868 | E26: ='Debt-Overview'!E25*'Debt-Overview'!E33/12 -> 16.344811 | F26: ='Debt-Overview'!F25*'Debt-Overview'!F33/12 -> 15.93841 | G26: ='Debt-Overview'!G25*'Debt-Overview'!G33/12 -> 15.531089 | H26: ='Debt-Overview'!H25*'Debt-Overview'!H33/12 -> 15.53203 | I26: ='Debt-Overview'!I25*'Debt-Overview'!I33/12 -> 15.125638 | J26: ='Debt-Overview'!J25*'Debt-Overview'!J33/12 -> 14.989863 | ... N26: ='Debt-Overview'!N25*'Debt-Overview'!N33/12 -> 0
B27: Monthly Principal Amortization | C27: 100 | D27: 100 | E27: 100 | F27: 100 | G27: 100 | H27: 100 | I27: 100 | J27: 100 | K27: 100 | L27: 100 | M27: 100
B28: Total Debt Service | C28: =C26+C27 -> 116.61497 | D28: =D26+D27 -> 116.34387 | E28: =E26+E27 -> 116.34481 | F28: =F26+F27 -> 115.93841 | G28: =G26+G27 -> 115.53109 | H28: =H26+H27 -> 115.53203 | I28: =I26+I27 -> 115.12564 | J28: =J26+J27 -> 114.98986 | ... N28: =N26+N27 -> 0
B29: Interest Coverage (EBITDA / Int) | C29: =IF(C26=0,"",C14/C26) -> 2.6482144 | D29: =IF(D26=0,"",D14/D26) -> 2.9980663 | E29: =IF(E26=0,"",E14/E26) -> 2.3860783 | F29: =IF(F26=0,"",F14/F26) -> 5.4585118 | G29: =IF(G26=0,"",G14/G26) -> 6.8894074 | H29: =IF(H26=0,"",H14/H26) -> 8.1766519 | I29: =IF(I26=0,"",I14/I26) -> 7.2724206 | J29: =IF(J26=0,"",J14/J26) -> 6.3376165 | ... N29: =IF(N26=0,"",N14/N26)
B30: Fixed Charge Coverage (EBITDA-CapEx)/DS | C30: =IF(C28=0,"",(C14-C35)/C28) -> -0.051451371 | D30: =IF(D28=0,"",(D14-D35)/D28) -> -0.051571261 | E30: =IF(E28=0,"",(E14-E35)/E28) -> -0.051570843 | F30: =IF(F28=0,"",(F14-F35)/F28) -> 0.23288227 | G30: =IF(G28=0,"",(G14-G35)/G28) -> 0.36353851 | H30: =IF(H28=0,"",(H14-H35)/H28) -> 0.66648184 | I30: =IF(I28=0,"",(I14-I35)/I28) -> 0.3474465 | J30: =IF(J28=0,"",(J14-J35)/J28) -> 0.17392838 | ... N30: =IF(N28=0,"",(N14-N35)/N28)
B31: Cash Interest / EBITDA (%) | C31: =IF(C14=0,"",C26/C14) -> 0.37761293 | D31: =IF(D14=0,"",D26/D14) -> 0.33354832 | E31: =IF(E14=0,"",E26/E14) -> 0.41909773 | F31: =IF(F14=0,"",F26/F14) -> 0.18320012 | G31: =IF(G14=0,"",G26/G14) -> 0.14515037 | H31: =IF(H14=0,"",H26/H14) -> 0.12229945 | I31: =IF(I14=0,"",I26/I14) -> 0.1375058 | J31: =IF(J14=0,"",J26/J14) -> 0.15778803 | ... N31: =IF(N14=0,"",N26/N14) -> 0
B33: CASH FLOW METRICS
B34: Operating Cash Flow | C34: {='Cash-Flow'!C12} -> 301 | D34: {='Cash-Flow'!D12} -> 311 | E34: {='Cash-Flow'!E12} -> 338 | F34: {='Cash-Flow'!F12} -> 304 | G34: {='Cash-Flow'!G12} -> 337 | H34: {='Cash-Flow'!H12} -> 369 | I34: {='Cash-Flow'!I12} -> 331 | J34: {='Cash-Flow'!J12} -> 362 | ... N34: {='Cash-Flow'!N12} -> 0
B35: CapEx | C35: =ABS('Cash-Flow'!C16) -> 50 | D35: =ABS('Cash-Flow'!D16) -> 55 | E35: =ABS('Cash-Flow'!E16) -> 45 | F35: =ABS('Cash-Flow'!F16) -> 60 | G35: =ABS('Cash-Flow'!G16) -> 65 | H35: =ABS('Cash-Flow'!H16) -> 50 | I35: =ABS('Cash-Flow'!I16) -> 70 | J35: =ABS('Cash-Flow'!J16) -> 75 | ... N35: =ABS('Cash-Flow'!N16) -> 0
B36: Free Cash Flow (OCF - CapEx) | C36: =C34-C35 -> 251 | D36: =D34-D35 -> 256 | E36: =E34-E35 -> 293 | F36: =F34-F35 -> 244 | G36: =G34-G35 -> 272 | H36: =H34-H35 -> 319 | I36: =I34-I35 -> 261 | J36: =J34-J35 -> 287 | ... N36: =N34-N35 -> 0
B37: FCF / Debt Service (%) | C37: =IF(C28=0,"",C36/C28) -> 2.1523823 | D37: =IF(D28=0,"",D36/D28) -> 2.2003738 | E37: =IF(E28=0,"",E36/E28) -> 2.5183762 | F37: =IF(F28=0,"",F36/F28) -> 2.1045657 | G37: =IF(G28=0,"",G36/G28) -> 2.3543446 | H37: =IF(H28=0,"",H36/H28) -> 2.7611391 | I37: =IF(I28=0,"",I36/I28) -> 2.2670884 | J37: =IF(J28=0,"",J36/J28) -> 2.4958722 | ... N37: =IF(N28=0,"",N36/N28)
B38: Cash Conversion (FCF / Adj EBITDA) | C38: =IF(C14=0,"",C36/C14) -> 5.7045455 | D38: =IF(D14=0,"",D36/D14) -> 5.2244898 | E38: =IF(E14=0,"",E36/E14) -> 7.5128205 | F38: =IF(F14=0,"",F36/F14) -> 2.8045977 | G38: =IF(G14=0,"",G36/G14) -> 2.5420561 | H38: =IF(H14=0,"",H36/H14) -> 2.511811 | I38: =IF(I14=0,"",I36/I14) -> 2.3727273 | J38: =IF(J14=0,"",J36/J14) -> 3.0210526 | ... N38: =IF(N14=0,"",N36/N14) -> 0
B39: Debt Paydown Capacity (FCF / Debt) | C39: =IF(C6=0,"",C36/C6) -> 0.082295082 | D39: =IF(D6=0,"",D36/D6) -> 0.085333333 | E39: =IF(E6=0,"",E36/E6) -> 0.097666667 | F39: =IF(F6=0,"",F36/F6) -> 0.083418803 | G39: =IF(G6=0,"",G36/G6) -> 0.095438596 | H39: =IF(H6=0,"",H36/H6) -> 0.11192982 | I39: =IF(I6=0,"",I36/I6) -> 0.094054054 | J39: =IF(J6=0,"",J36/J6) -> 0.10436364 | ... N39: =IF(N6=0,"",N36/N6)
B41: VALUATION METRICS
B42: TEV / Adj EBITDA | C42: =IF(C14=0,"",C9/C14) -> 193.18182 | D42: =IF(D14=0,"",D9/D14) -> 175.5102 | E42: =IF(E14=0,"",E9/E14) -> 223.07692 | F42: =IF(F14=0,"",F9/F14) -> 101.14943 | G42: =IF(G14=0,"",G9/G14) -> 83.17757 | H42: =IF(H14=0,"",H9/H14) -> 70.866142 | I42: =IF(I14=0,"",I9/I14) -> 82.727273 | J42: =IF(J14=0,"",J9/J14) -> 96.842105 | ... N42: =IF(N14=0,"",N9/N14) -> 0
B43: TEV / Run-Rate EBITDA | C43: =IF(C15=0,"",C9/C15) -> 1.6037736 | D43: =IF(D15=0,"",D9/D15) -> 1.5925926 | E43: =IF(E15=0,"",E9/E15) -> 1.5963303 | F43: =IF(F15=0,"",F9/F15) -> 1.5855856 | G43: =IF(G15=0,"",G9/G15) -> 1.5752212 | H43: =IF(H15=0,"",H9/H15) -> 1.5789474 | I43: =IF(I15=0,"",I9/I15) -> 1.5555556 | J43: =IF(J15=0,"",J9/J15) -> 1.5462185 | ... N43: =IF(N15=0,"",N9/N15)
B44: TEV / Revenue | C44: =IF(C16=0,"",C9/C16) -> 8500 | D44: =IF(D16=0,"",D9/D16) -> 8600 | E44: =IF(E16=0,"",E9/E16) -> 8700 | F44: =IF(F16=0,"",F9/F16) -> 8800 | G44: =IF(G16=0,"",G9/G16) -> 8900 | H44: =IF(H16=0,"",H9/H16) -> 9000 | I44: =IF(I16=0,"",I9/I16) -> 9100 | J44: =IF(J16=0,"",J9/J16) -> 9200 | ... N44: =IF(N16=0,"",N9/N16) -> 0
B45: Equity / Adj EBITDA | C45: =IF(C14=0,"",C10/C14) -> 143.18182 | D45: =IF(D14=0,"",D10/D14) -> 133.06122 | E45: =IF(E14=0,"",E10/E14) -> 168.71795 | F45: =IF(F14=0,"",F10/F14) -> 78.448276 | G45: =IF(G14=0,"",G10/G14) -> 66.074766 | H45: =IF(H14=0,"",H10/H14) -> 56.141732 | I45: =IF(I14=0,"",I10/I14) -> 67.5 | J45: =IF(J14=0,"",J10/J14) -> 80 | ... N45: =IF(N14=0,"",N10/N14) -> 0
B47: COVENANT COMPLIANCE
...

Sheet Debt-Overview
B2: Debt Overview Flash Input
B3: [Company Name]
C4: 45658 | D4: 45689 | E4: 45717 | F4: 45748 | G4: 45778 | H4: 45809 | I4: 45839 | J4: 45870 | K4: 45901 | L4: 45931 | M4: 45962 | N4: 45992
B5: SENIOR SECURED DEBT
B6: Revolver - Commitment | C6: 500 | D6: 500 | E6: 500 | F6: 500 | G6: 500 | H6: 500 | I6: 500 | J6: 500 | K6: 500 | L6: 500 | M6: 500
B7: Revolver - Drawn | C7: 100 | D7: 75 | E7: 100 | F7: 50 | G7: 25 | H7: 50 | I7: 0 | J7: 0 | K7: 25 | L7: 0 | M7: 0
B8: Revolver - Available | C8: =C6-C7 -> 400 | D8: =D6-D7 -> 425 | E8: =E6-E7 -> 400 | F8: =F6-F7 -> 450 | G8: =G6-G7 -> 475 | H8: =H6-H7 -> 450 | I8: =I6-I7 -> 500 | J8: =J6-J7 -> 500 | ... M8: =M6-M7 -> 500
B9: Term Loan A - Outstanding | C9: 800 | D9: 792 | E9: 783 | F9: 775 | G9: 767 | H9: 758 | I9: 750 | J9: 742 | K9: 733 | L9: 725 | M9: 717
B10: Term Loan B - Outstanding | C10: 1800 | D10: 1783 | E10: 1767 | F10: 1750 | G10: 1733 | H10: 1717 | I10: 1700 | J10: 1683 | K10: 1667 | L10: 1650 | M10: 1633
B11: Total Senior Secured | C11: =C7+C9+C10 -> 2700 | D11: =D7+D9+D10 -> 2650 | E11: =E7+E9+E10 -> 2650 | F11: =F7+F9+F10 -> 2575 | G11: =G7+G9+G10 -> 2525 | H11: =H7+H9+H10 -> 2525 | I11: =I7+I9+I10 -> 2450 | J11: =J7+J9+J10 -> 2425 | ... M11: =M7+M9+M10 -> 2350
B13: SUBORDINATED / MEZZ DEBT
B14: Second Lien - Outstanding | C14: 250 | D14: 250 | E14: 250 | F14: 250 | G14: 250 | H14: 250 | I14: 250 | J14: 250 | K14: 250 | L14: 250 | M14: 250
B15: Mezzanine - Outstanding | C15: 0 | D15: 0 | E15: 0 | F15: 0 | G15: 0 | H15: 0 | I15: 0 | J15: 0 | K15: 0 | L15: 0 | M15: 0
B16: Total Subordinated | C16: =C14+C15 -> 250 | D16: =D14+D15 -> 250 | E16: =E14+E15 -> 250 | F16: =F14+F15 -> 250 | G16: =G14+G15 -> 250 | H16: =H14+H15 -> 250 | I16: =I14+I15 -> 250 | J16: =J14+J15 -> 250 | ... M16: =M14+M15 -> 250
B18: OTHER DEBT
B19: Capital Lease Obligations | C19: 50 | D19: 50 | E19: 50 | F19: 50 | G19: 50 | H19: 50 | I19: 50 | J19: 50 | K19: 50 | L19: 50 | M19: 50
B20: Seller Notes | C20: 50 | D20: 50 | E20: 50 | F20: 50 | G20: 25 | H20: 25 | I20: 25 | J20: 25 | K20: 25 | L20: 25 | M20: 25
B21: Other Debt | C21: 0 | D21: 0 | E21: 0 | F21: 0 | G21: 0 | H21: 0 | I21: 0 | J21: 0 | K21: 0 | L21: 0 | M21: 0
B22: Total Other Debt | C22: =SUM(C19:C21) -> 100 | D22: =SUM(D19:D21) -> 100 | E22: =SUM(E19:E21) -> 100 | F22: =SUM(F19:F21) -> 100 | G22: =SUM(G19:G21) -> 75 | H22: =SUM(H19:H21) -> 75 | I22: =SUM(I19:I21) -> 75 | J22: =SUM(J19:J21) -> 75 | ... M22: =SUM(M19:M21) -> 75
B24: TOTAL DEBT SUMMARY
B25: Total Debt Outstanding | C25: =C11+C16+C22 -> 3050 | D25: =D11+D16+D22 -> 3000 | E25: =E11+E16+E22 -> 3000 | F25: =F11+F16+F22 -> 2925 | G25: =G11+G16+G22 -> 2850 | H25: =H11+H16+H22 -> 2850 | I25: =I11+I16+I22 -> 2775 | J25: =J11+J16+J22 -> 2750 | ... M25: =M11+M16+M22 -> 2675
B26: (-) Cash & Equivalents | C26: {=BS!C6} -> 850 | D26: {=BS!D6} -> 920 | E26: {=BS!E6} -> 880 | F26: {=BS!F6} -> 950 | G26: {=BS!G6} -> 1020 | H26: {=BS!H6} -> 980 | I26: {=BS!I6} -> 1100 | J26: {=BS!J6} -> 1150 | ... N26: {=BS!N6} -> 0
B27: Net Debt | C27: =C25-C26 -> 2200 | D27: =D25-D26 -> 2080 | E27: =E25-E26 -> 2120 | F27: =F25-F26 -> 1975 | G27: =G25-G26 -> 1830 | H27: =H25-H26 -> 1870 | I27: =I25-I26 -> 1675 | J27: =J25-J26 -> 1600 | ... M27: =M25-M26 -> 1395
B29: INTEREST RATE SUMMARY
B30: Revolver Rate (%) | C30: 0.065 | D30: 0.065 | E30: 0.065 | F30: 0.065 | G30: 0.065 | H30: 0.065 | I30: 0.065 | J30: 0.065 | K30: 0.065 | L30: 0.065 | M30: 0.065
B31: TLA Rate (%) | C31: 0.055 | D31: 0.055 | E31: 0.055 | F31: 0.055 | G31: 0.055 | H31: 0.055 | I31: 0.055 | J31: 0.055 | K31: 0.055 | L31: 0.055 | M31: 0.055
B32: TLB Rate (%) | C32: 0.07 | D32: 0.07 | E32: 0.07 | F32: 0.07 | G32: 0.07 | H32: 0.07 | I32: 0.07 | J32: 0.07 | K32: 0.07 | L32: 0.07 | M32: 0.07
B33: Blended Interest Rate (%) | C33: =(C7*C30+C9*C31+C10*C32)/C11 -> 0.06537037 | D33: =(D7*D30+D9*D31+D10*D32)/D11 -> 0.065375472 | E33: =(E7*E30+E9*E31+E10*E32)/E11 -> 0.065379245 | F33: =(F7*F30+F9*F31+F10*F32)/F11 -> 0.06538835 | G33: =(G7*G30+G9*G31+G10*G32)/G11 -> 0.065394059 | H33: =(H7*H30+H9*H31+H10*H32)/H11 -> 0.06539802 | I33: =(I7*I30+I9*I31+I10*I32)/I11 -> 0.065408163 | J33: =(J7*J30+J9*J31+J10*J32)/J11 -> 0.065410309 | ... M33: =(M7*M30+M9*M31+M10*M32)/M11 -> 0.065423404

Sheet Adjustment-Types
B2: EBITDA Adjustment Types Reference
B4: Adjustment Code | C4: Adjustment Type | D4: Description | E4: Direction
B5: ADD-01 | C5: One-Time Restructuring | D5: Severance, facility closure costs, reorganization expenses | E5: Add-back (+)
B6: ADD-02 | C6: Transaction Costs | D6: M&A fees, legal, accounting, due diligence costs | E6: Add-back (+)
B7: ADD-03 | C7: Non-Cash Stock Comp | D7: Stock-based compensation expense | E7: Add-back (+)
B8: ADD-04 | C8: Management Fees | D8: Sponsor management/monitoring fees | E8: Add-back (+)
B9: ADD-05 | C9: Non-Recurring Legal | D9: Litigation settlements, unusual legal costs | E9: Add-back (+)
B10: ADD-06 | C10: Asset Impairment | D10: Non-cash goodwill/asset write-downs | E10: Add-back (+)
B11: ADD-07 | C11: FX Losses (Non-Cash) | D11: Unrealized foreign exchange losses | E11: Add-back (+)
B12: ADD-08 | C12: Integration Costs | D12: Post-acquisition integration expenses | E12: Add-back (+)
B13: ADD-09 | C13: Start-Up Costs | D13: New facility/product launch expenses | E13: Add-back (+)
B14: ADD-10 | C14: Natural Disaster | D14: One-time costs from floods, fires, etc. | E14: Add-back (+)
B15: DED-01 | C15: One-Time Gains | D15: Non-recurring income or gains | E15: Deduction (-)
... B33: MA2-06 | C33: Carve-Out Costs | D33: One-time separation costs for divestitures | E33: Add-back (+)
B35: Note: LFL = Like-for-Like (organic growth analysis). MA2 = M&A Type 2 (credit agreement / covenant adjustments).

Sheet Input-Summary
B2: PE Portfolio Company Flash Input Summary
B3: [Company Name]
B5: Sheet | C5: Metric | D5: December Cell Ref | E5: Description
B6: P&L | C6: Revenue | D6: P&L!N5 | E6: Monthly revenue from sales/services
B7: P&L | C7: Revenue Budget | D7: P&L!N6 | E7: Budgeted monthly revenue
B8: P&L | C8: Cost of Goods Sold | D8: P&L!N7 | E8: Direct costs of products/services sold
B9: P&L | C9: COGS Budget | D9: P&L!N8 | E9: Budgeted COGS
B10: P&L | C10: Operating Expenses | D10: P&L!N12 | E10: SG&A, R&D, and other operating costs
B11: P&L | C11: OpEx Budget | D11: P&L!N13 | E11: Budgeted operating expenses
B12: P&L | C12: EBITDA Adj Type | D12: P&L!B20:B27 | E12: Select adjustment type from dropdown (One-Time Restructuring, Transaction Costs, etc.)
B13: P&L | C13: EBITDA Adj Description | D13: P&L!C20:C27 | E13: Brief description of adjustment
B14: P&L | C14: EBITDA Adj Values | D14: P&L!D20:O27 | E14: Monthly adjustment amounts (positive = add-back, negative = deduction)
B15: P&L | C15: Depreciation | D15: P&L!N31 | E15: Monthly depreciation expense
B16: P&L | C16: Depreciation Budget | D16: P&L!N32 | E16: Budgeted depreciation
... B99: Debt-Overview | C99: TLB Rate (%) | D99: Debt-Overview!N32 | E99: Interest rate on Term Loan B
