Workbook

Sheet EVAL LEGEND
B1: Classification eval — 2026-02-01-pe-portco-flash-template
B2: Every cell you marked (1/2) is coloured by what the system did with it:
B4: GREEN | C4: agreement — system fills this marked cell | E4: 1008
B5: RED | C5: MISSED — invisible to the system (no fact, no region) | E5: 50
B6: ORANGE | C6: marked but holds a FORMULA — system never writes formulas | E6: 165
B7: BLUE | C7: recognized as extensible-region slot (add-line path) | E7: 25
B8: PURPLE | C8: seen but classified config/staging (control/placeholder) | E8: 0
B9: YELLOW | C9: NOT marked by you, but the system would fill it | E9: 0
B11: Note: YELLOW skips cells whose marking collides with a placeholder value (CLASSIFIED == NORMAL == 1/2) — ground truth is ambiguous there.
B12: Marked cells scored: 1248

Sheet P&L
B2: P&L Flash Input
B3: [Company Name]
C4: 45658 | D4: 45689 | E4: 45717 | F4: 45748 | G4: 45778 | H4: 45809 | I4: 45839 | J4: 45870 | K4: 45901 | L4: 45931 | M4: 45962 | N4: 45992
B5: Revenue | C5: 1 | D5: 1 | E5: 1 | F5: 1 | G5: 1 | H5: 1 | I5: 1 | J5: 1 | K5: 1 | L5: 1 | M5: 1 | N5: 1
B6: Budget | C6: 1 | D6: 1 | E6: 1 | F6: 1 | G6: 1 | H6: 1 | I6: 1 | J6: 1 | K6: 1 | L6: 1 | M6: 1 | N6: 1
B7: Cost of Goods Sold | C7: 1 | D7: 1 | E7: 1 | F7: 1 | G7: 1 | H7: 1 | I7: 1 | J7: 1 | K7: 1 | L7: 1 | M7: 1 | N7: 1
B8: Budget | C8: 1 | D8: 1 | E8: 1 | F8: 1 | G8: 1 | H8: 1 | I8: 1 | J8: 1 | K8: 1 | L8: 1 | M8: 1 | N8: 1
B9: Gross Profit | C9: =C5-C7 -> 0 | D9: =D5-D7 -> 0 | E9: =E5-E7 -> 0 | F9: =F5-F7 -> 0 | G9: =G5-G7 -> 0 | H9: =H5-H7 -> 0 | I9: =I5-I7 -> 0 | J9: =J5-J7 -> 0 | ... N9: =N5-N7 -> 0
B10: Budget | C10: =C6-C8 -> 0 | D10: =D6-D8 -> 0 | E10: =E6-E8 -> 0 | F10: =F6-F8 -> 0 | G10: =G6-G8 -> 0 | H10: =H6-H8 -> 0 | I10: =I6-I8 -> 0 | J10: =J6-J8 -> 0 | ... N10: =N6-N8 -> 0
B12: Operating Expenses | C12: 1 | D12: 1 | E12: 1 | F12: 1 | G12: 1 | H12: 1 | I12: 1 | J12: 1 | K12: 1 | L12: 1 | M12: 1 | N12: 1
B13: Budget | C13: 1 | D13: 1 | E13: 1 | F13: 1 | G13: 1 | H13: 1 | I13: 1 | J13: 1 | K13: 1 | L13: 1 | M13: 1 | N13: 1
B15: EBITDA | C15: =C9-C12 -> -1 | D15: =D9-D12 -> -1 | E15: =E9-E12 -> -1 | F15: =F9-F12 -> -1 | G15: =G9-G12 -> -1 | H15: =H9-H12 -> -1 | I15: =I9-I12 -> -1 | J15: =J9-J12 -> -1 | ... N15: =N9-N12 -> -1
B16: Budget | C16: =C10-C13 -> -1 | D16: =D10-D13 -> -1 | E16: =E10-E13 -> -1 | F16: =F10-F13 -> -1 | G16: =G10-G13 -> -1 | H16: =H10-H13 -> -1 | I16: =I10-I13 -> -1 | J16: =J10-J13 -> -1 | ... N16: =N10-N13 -> -1
B18: EBITDA Adjustments
B19: Adj Type | C19: 45658 | D19: 45689 | E19: 45717 | F19: 45748 | G19: 45778 | H19: 45809 | I19: 45839 | J19: 45870 | K19: 45901 | L19: 45931 | M19: 45962 | N19: 45992 | O19: YTD
B20: 2 | C20: 1 | D20: 1 | E20: 1 | F20: 1 | G20: 1 | H20: 1 | I20: 1 | J20: 1 | K20: 1 | L20: 1 | M20: 1 | N20: 1 | O20: =SUM(C20:N20) -> 12
B21: 2 | C21: 1 | D21: 1 | E21: 1 | F21: 1 | G21: 1 | H21: 1 | I21: 1 | J21: 1 | K21: 1 | L21: 1 | M21: 1 | N21: 1 | O21: =SUM(C21:N21) -> 12
B22: 2 | C22: 1 | D22: 1 | E22: 1 | F22: 1 | G22: 1 | H22: 1 | I22: 1 | J22: 1 | K22: 1 | L22: 1 | M22: 1 | N22: 1 | O22: =SUM(C22:N22) -> 12
B23: 2 | C23: 1 | D23: 1 | E23: 1 | F23: 1 | G23: 1 | H23: 1 | I23: 1 | J23: 1 | K23: 1 | L23: 1 | M23: 1 | N23: 1 | O23: =SUM(C23:N23) -> 12
B24: 2 | C24: 1 | D24: 1 | E24: 1 | F24: 1 | G24: 1 | H24: 1 | I24: 1 | J24: 1 | K24: 1 | L24: 1 | M24: 1 | N24: 1 | O24: =SUM(C24:N24) -> 12
B25: 2 | C25: 1 | D25: 1 | E25: 1 | F25: 1 | G25: 1 | H25: 1 | I25: 1 | J25: 1 | K25: 1 | L25: 1 | M25: 1 | N25: 1 | O25: =SUM(C25:N25) -> 12
B26: 2 | C26: 1 | D26: 1 | E26: 1 | F26: 1 | G26: 1 | H26: 1 | I26: 1 | J26: 1 | K26: 1 | L26: 1 | M26: 1 | N26: 1 | O26: =SUM(C26:N26) -> 12
B27: 2 | C27: 1 | D27: 1 | E27: 1 | F27: 1 | G27: 1 | H27: 1 | I27: 1 | J27: 1 | K27: 1 | L27: 1 | M27: 1 | N27: 1 | O27: =SUM(C27:N27) -> 12
B28: Total Adjustments | C28: =SUM(C20:C27) -> 8 | D28: =SUM(D20:D27) -> 8 | E28: =SUM(E20:E27) -> 8 | F28: =SUM(F20:F27) -> 8 | G28: =SUM(G20:G27) -> 8 | H28: =SUM(H20:H27) -> 8 | I28: =SUM(I20:I27) -> 8 | J28: =SUM(J20:J27) -> 8 | ... O28: =SUM(O20:O27) -> 96
B29: Adjusted EBITDA | C29: =C15+C28 -> 7 | D29: =D15+D28 -> 7 | E29: =E15+E28 -> 7 | F29: =F15+F28 -> 7 | G29: =G15+G28 -> 7 | H29: =H15+H28 -> 7 | I29: =I15+I28 -> 7 | J29: =J15+J28 -> 7 | ... N29: =N15+N28 -> 7 | O29: =SUM(C29:N29) -> 84
B31: Depreciation | C31: 1 | D31: 1 | E31: 1 | F31: 1 | G31: 1 | H31: 1 | I31: 1 | J31: 1 | K31: 1 | L31: 1 | M31: 1 | N31: 1
B32: Budget | C32: 1 | D32: 1 | E32: 1 | F32: 1 | G32: 1 | H32: 1 | I32: 1 | J32: 1 | K32: 1 | L32: 1 | M32: 1 | N32: 1
B33: Amortization | C33: 1 | D33: 1 | E33: 1 | F33: 1 | G33: 1 | H33: 1 | I33: 1 | J33: 1 | K33: 1 | L33: 1 | M33: 1 | N33: 1
B34: Budget | C34: 1 | D34: 1 | E34: 1 | F34: 1 | G34: 1 | H34: 1 | I34: 1 | J34: 1 | K34: 1 | L34: 1 | M34: 1 | N34: 1
B35: EBIT | C35: =C15-C31-C33 -> -3 | D35: =C29-D31-D33 -> 5 | E35: =D29-E31-E33 -> 5 | F35: =E29-F31-F33 -> 5 | G35: =F29-G31-G33 -> 5 | H35: =G29-H31-H33 -> 5 | I35: =H29-I31-I33 -> 5 | J35: =I29-J31-J33 -> 5 | K35: =J29-K31-K33 -> 5 | ... M35: =L29-M31-M33 -> 5 | N35: =N29-N31-N33 -> 5
B36: Budget | C36: =C16-C32-C34 -> -3 | D36: =D16-D32-D34 -> -3 | E36: =E16-E32-E34 -> -3 | F36: =F16-F32-F34 -> -3 | G36: =G16-G32-G34 -> -3 | H36: =H16-H32-H34 -> -3 | I36: =I16-I32-I34 -> -3 | J36: =J16-J32-J34 -> -3 | ... N36: =N16-N32-N34 -> -3
B38: Interest Expense | C38: 1 | D38: 1 | E38: 1 | F38: 1 | G38: 1 | H38: 1 | I38: 1 | J38: 1 | K38: 1 | L38: 1 | M38: 1 | N38: 1
B39: Budget | C39: 1 | D39: 1 | E39: 1 | F39: 1 | G39: 1 | H39: 1 | I39: 1 | J39: 1 | K39: 1 | L39: 1 | M39: 1 | N39: 1
B40: Other Income / (Expense) | C40: 1 | D40: 1 | E40: 1 | F40: 1 | G40: 1 | H40: 1 | I40: 1 | J40: 1 | K40: 1 | L40: 1 | M40: 1 | N40: 1
B41: Budget | C41: 1 | D41: 1 | E41: 1 | F41: 1 | G41: 1 | H41: 1 | I41: 1 | J41: 1 | K41: 1 | L41: 1 | M41: 1 | N41: 1
B42: EBT | C42: =C35-C38+C40 -> -3 | D42: =D35-D38+D40 -> 5 | E42: =E35-E38+E40 -> 5 | F42: =F35-F38+F40 -> 5 | G42: =G35-G38+G40 -> 5 | H42: =H35-H38+H40 -> 5 | I42: =I35-I38+I40 -> 5 | J42: =J35-J38+J40 -> 5 | ... N42: =N35-N38+N40 -> 5
B43: Budget | C43: =C36-C39+C41 -> -3 | D43: =D36-D39+D41 -> -3 | E43: =E36-E39+E41 -> -3 | F43: =F36-F39+F41 -> -3 | G43: =G36-G39+G41 -> -3 | H43: =H36-H39+H41 -> -3 | I43: =I36-I39+I41 -> -3 | J43: =J36-J39+J41 -> -3 | ... N43: =N36-N39+N41 -> -3
B44: Tax Expense | C44: =C42*0.25 -> -0.75 | D44: =D42*0.25 -> 1.25 | E44: =E42*0.25 -> 1.25 | F44: =F42*0.25 -> 1.25 | G44: =G42*0.25 -> 1.25 | H44: =H42*0.25 -> 1.25 | I44: =I42*0.25 -> 1.25 | J44: =J42*0.25 -> 1.25 | ... N44: =N42*0.25 -> 1.25
B45: Budget | C45: =C43*0.25 -> -0.75 | D45: =D43*0.25 -> -0.75 | E45: =E43*0.25 -> -0.75 | F45: =F43*0.25 -> -0.75 | G45: =G43*0.25 -> -0.75 | H45: =H43*0.25 -> -0.75 | I45: =I43*0.25 -> -0.75 | J45: =J43*0.25 -> -0.75 | ... N45: =N43*0.25 -> -0.75
B46: Net Income | C46: =C42-C44 -> -2.25 | D46: =D42-D44 -> 3.75 | E46: =E42-E44 -> 3.75 | F46: =F42-F44 -> 3.75 | G46: =G42-G44 -> 3.75 | H46: =H42-H44 -> 3.75 | I46: =I42-I44 -> 3.75 | J46: =J42-J44 -> 3.75 | ... N46: =N42-N44 -> 3.75
...

Sheet BS
B2: Balance Sheet Flash Input
B3: [Company Name]
C4: 45658 | D4: 45689 | E4: 45717 | F4: 45748 | G4: 45778 | H4: 45809 | I4: 45839 | J4: 45870 | K4: 45901 | L4: 45931 | M4: 45962 | N4: 45992
B5: ASSETS
B6: Cash & Cash Equivalents | C6: 1 | D6: 1 | E6: 1 | F6: 1 | G6: 1 | H6: 1 | I6: 1 | J6: 1 | K6: 1 | L6: 1 | M6: 1 | N6: 1
B7: Budget | C7: 1 | D7: 1 | E7: 1 | F7: 1 | G7: 1 | H7: 1 | I7: 1 | J7: 1 | K7: 1 | L7: 1 | M7: 1 | N7: 1
B8: Accounts Receivable | C8: 1 | D8: 1 | E8: 1 | F8: 1 | G8: 1 | H8: 1 | I8: 1 | J8: 1 | K8: 1 | L8: 1 | M8: 1 | N8: 1
B9: Budget | C9: 1 | D9: 1 | E9: 1 | F9: 1 | G9: 1 | H9: 1 | I9: 1 | J9: 1 | K9: 1 | L9: 1 | M9: 1 | N9: 1
B10: Inventory | C10: 1 | D10: 1 | E10: 1 | F10: 1 | G10: 1 | H10: 1 | I10: 1 | J10: 1 | K10: 1 | L10: 1 | M10: 1 | N10: 1
B11: Budget | C11: 1 | D11: 1 | E11: 1 | F11: 1 | G11: 1 | H11: 1 | I11: 1 | J11: 1 | K11: 1 | L11: 1 | M11: 1 | N11: 1
B12: Prepaid Expenses | C12: 1 | D12: 1 | E12: 1 | F12: 1 | G12: 1 | H12: 1 | I12: 1 | J12: 1 | K12: 1 | L12: 1 | M12: 1 | N12: 1
B13: Budget | C13: 1 | D13: 1 | E13: 1 | F13: 1 | G13: 1 | H13: 1 | I13: 1 | J13: 1 | K13: 1 | L13: 1 | M13: 1 | N13: 1
B14: Total Current Assets | C14: =SUM(C6,C8,C10,C12) -> 4 | D14: =SUM(D6,D8,D10,D12) -> 4 | E14: =SUM(E6,E8,E10,E12) -> 4 | F14: =SUM(F6,F8,F10,F12) -> 4 | G14: =SUM(G6,G8,G10,G12) -> 4 | H14: =SUM(H6,H8,H10,H12) -> 4 | I14: =SUM(I6,I8,I10,I12) -> 4 | J14: =SUM(J6,J8,J10,J12) -> 4 | ... N14: =SUM(N6,N8,N10,N12) -> 4
B15: Budget | C15: =SUM(C7,C9,C11,C13) -> 4 | D15: =SUM(D7,D9,D11,D13) -> 4 | E15: =SUM(E7,E9,E11,E13) -> 4 | F15: =SUM(F7,F9,F11,F13) -> 4 | G15: =SUM(G7,G9,G11,G13) -> 4 | H15: =SUM(H7,H9,H11,H13) -> 4 | I15: =SUM(I7,I9,I11,I13) -> 4 | J15: =SUM(J7,J9,J11,J13) -> 4 | ... N15: =SUM(N7,N9,N11,N13) -> 4
B17: PP&E (Net) | C17: 1 | D17: 1 | E17: 1 | F17: 1 | G17: 1 | H17: 1 | I17: 1 | J17: 1 | K17: 1 | L17: 1 | M17: 1 | N17: 1
B18: Budget | C18: 1 | D18: 1 | E18: 1 | F18: 1 | G18: 1 | H18: 1 | I18: 1 | J18: 1 | K18: 1 | L18: 1 | M18: 1 | N18: 1
B19: Intangibles | C19: 1 | D19: 1 | E19: 1 | F19: 1 | G19: 1 | H19: 1 | I19: 1 | J19: 1 | K19: 1 | L19: 1 | M19: 1 | N19: 1
B20: Budget | C20: 1 | D20: 1 | E20: 1 | F20: 1 | G20: 1 | H20: 1 | I20: 1 | J20: 1 | K20: 1 | L20: 1 | M20: 1 | N20: 1
B21: Goodwill | C21: 1 | D21: 1 | E21: 1 | F21: 1 | G21: 1 | H21: 1 | I21: 1 | J21: 1 | K21: 1 | L21: 1 | M21: 1 | N21: 1
B22: Budget | C22: 1 | D22: 1 | E22: 1 | F22: 1 | G22: 1 | H22: 1 | I22: 1 | J22: 1 | K22: 1 | L22: 1 | M22: 1 | N22: 1
B23: Total Assets | C23: =C14+C17+C19+C21 -> 7 | D23: =D14+D17+D19+D21 -> 7 | E23: =E14+E17+E19+E21 -> 7 | F23: =F14+F17+F19+F21 -> 7 | G23: =G14+G17+G19+G21 -> 7 | H23: =H14+H17+H19+H21 -> 7 | I23: =I14+I17+I19+I21 -> 7 | J23: =J14+J17+J19+J21 -> 7 | ... N23: =N14+N17+N19+N21 -> 7
B24: Budget | C24: =C15+C18+C20+C22 -> 7 | D24: =D15+D18+D20+D22 -> 7 | E24: =E15+E18+E20+E22 -> 7 | F24: =F15+F18+F20+F22 -> 7 | G24: =G15+G18+G20+G22 -> 7 | H24: =H15+H18+H20+H22 -> 7 | I24: =I15+I18+I20+I22 -> 7 | J24: =J15+J18+J20+J22 -> 7 | ... N24: =N15+N18+N20+N22 -> 7
B26: LIABILITIES
B27: Accounts Payable | C27: 1 | D27: 1 | E27: 1 | F27: 1 | G27: 1 | H27: 1 | I27: 1 | J27: 1 | K27: 1 | L27: 1 | M27: 1 | N27: 1
B28: Budget | C28: 1 | D28: 1 | E28: 1 | F28: 1 | G28: 1 | H28: 1 | I28: 1 | J28: 1 | K28: 1 | L28: 1 | M28: 1 | N28: 1
B29: Accrued Expenses | C29: 1 | D29: 1 | E29: 1 | F29: 1 | G29: 1 | H29: 1 | I29: 1 | J29: 1 | K29: 1 | L29: 1 | M29: 1 | N29: 1
B30: Budget | C30: 1 | D30: 1 | E30: 1 | F30: 1 | G30: 1 | H30: 1 | I30: 1 | J30: 1 | K30: 1 | L30: 1 | M30: 1 | N30: 1
B31: Short-Term Debt | C31: 1 | D31: 1 | E31: 1 | F31: 1 | G31: 1 | H31: 1 | I31: 1 | J31: 1 | K31: 1 | L31: 1 | M31: 1 | N31: 1
B32: Budget | C32: 1 | D32: 1 | E32: 1 | F32: 1 | G32: 1 | H32: 1 | I32: 1 | J32: 1 | K32: 1 | L32: 1 | M32: 1 | N32: 1
B33: Total Current Liabilities | C33: =SUM(C27,C29,C31) -> 3 | D33: =SUM(D27,D29,D31) -> 3 | E33: =SUM(E27,E29,E31) -> 3 | F33: =SUM(F27,F29,F31) -> 3 | G33: =SUM(G27,G29,G31) -> 3 | H33: =SUM(H27,H29,H31) -> 3 | I33: =SUM(I27,I29,I31) -> 3 | J33: =SUM(J27,J29,J31) -> 3 | ... N33: =SUM(N27,N29,N31) -> 3
B34: Budget | C34: =SUM(C28,C30,C32) -> 3 | D34: =SUM(D28,D30,D32) -> 3 | E34: =SUM(E28,E30,E32) -> 3 | F34: =SUM(F28,F30,F32) -> 3 | G34: =SUM(G28,G30,G32) -> 3 | H34: =SUM(H28,H30,H32) -> 3 | I34: =SUM(I28,I30,I32) -> 3 | J34: =SUM(J28,J30,J32) -> 3 | ... N34: =SUM(N28,N30,N32) -> 3
B36: Long-Term Debt | C36: 1 | D36: 1 | E36: 1 | F36: 1 | G36: 1 | H36: 1 | I36: 1 | J36: 1 | K36: 1 | L36: 1 | M36: 1 | N36: 1
B37: Budget | C37: 1 | D37: 1 | E37: 1 | F37: 1 | G37: 1 | H37: 1 | I37: 1 | J37: 1 | K37: 1 | L37: 1 | M37: 1 | N37: 1
B38: Total Liabilities | C38: =C33+C36 -> 4 | D38: =D33+D36 -> 4 | E38: =E33+E36 -> 4 | F38: =F33+F36 -> 4 | G38: =G33+G36 -> 4 | H38: =H33+H36 -> 4 | I38: =I33+I36 -> 4 | J38: =J33+J36 -> 4 | ... N38: =N33+N36 -> 4
B39: Budget | C39: =C34+C37 -> 4 | D39: =D34+D37 -> 4 | E39: =E34+E37 -> 4 | F39: =F34+F37 -> 4 | G39: =G34+G37 -> 4 | H39: =H34+H37 -> 4 | I39: =I34+I37 -> 4 | J39: =J34+J37 -> 4 | ... N39: =N34+N37 -> 4
B41: EQUITY
B42: Total Equity | C42: =C23-C38 -> 3 | D42: =D23-D38 -> 3 | E42: =E23-E38 -> 3 | F42: =F23-F38 -> 3 | G42: =G23-G38 -> 3 | H42: =H23-H38 -> 3 | I42: =I23-I38 -> 3 | J42: =J23-J38 -> 3 | ... N42: =N23-N38 -> 3
B43: Budget | C43: =C24-C39 -> 3 | D43: =D24-D39 -> 3 | E43: =E24-E39 -> 3 | F43: =F24-F39 -> 3 | G43: =G24-G39 -> 3 | H43: =H24-H39 -> 3 | I43: =I24-I39 -> 3 | J43: =J24-J39 -> 3 | ... N43: =N24-N39 -> 3
B44: Total Liabilities & Equity | C44: =C38+C42 -> 7 | D44: =D38+D42 -> 7 | E44: =E38+E42 -> 7 | F44: =F38+F42 -> 7 | G44: =G38+G42 -> 7 | H44: =H38+H42 -> 7 | I44: =I38+I42 -> 7 | J44: =J38+J42 -> 7 | ... N44: =N38+N42 -> 7
B45: Budget | C45: =C39+C43 -> 7 | D45: =D39+D43 -> 7 | E45: =E39+E43 -> 7 | F45: =F39+F43 -> 7 | G45: =G39+G43 -> 7 | H45: =H39+H43 -> 7 | I45: =I39+I43 -> 7 | J45: =J39+J43 -> 7 | ... N45: =N39+N43 -> 7

Sheet Cash-Flow
B2: Cash Flow Flash Input
B3: [Company Name]
C4: 45658 | D4: 45689 | E4: 45717 | F4: 45748 | G4: 45778 | H4: 45809 | I4: 45839 | J4: 45870 | K4: 45901 | L4: 45931 | M4: 45962 | N4: 45992
B5: OPERATING ACTIVITIES
B6: Net Income | C6: 1 | D6: 1 | E6: 1 | F6: 1 | G6: 1 | H6: 1 | I6: 1 | J6: 1 | K6: 1 | L6: 1 | M6: 1 | N6: 1
B7: Budget | C7: 1 | D7: 1 | E7: 1 | F7: 1 | G7: 1 | H7: 1 | I7: 1 | J7: 1 | K7: 1 | L7: 1 | M7: 1 | N7: 1
B8: (+) Depreciation & Amort | C8: 1 | D8: 1 | E8: 1 | F8: 1 | G8: 1 | H8: 1 | I8: 1 | J8: 1 | K8: 1 | L8: 1 | M8: 1 | N8: 1
B9: Budget | C9: 1 | D9: 1 | E9: 1 | F9: 1 | G9: 1 | H9: 1 | I9: 1 | J9: 1 | K9: 1 | L9: 1 | M9: 1 | N9: 1
B10: (+/-) Working Capital Changes | C10: 1 | D10: 1 | E10: 1 | F10: 1 | G10: 1 | H10: 1 | I10: 1 | J10: 1 | K10: 1 | L10: 1 | M10: 1 | N10: 1
B11: Budget | C11: 1 | D11: 1 | E11: 1 | F11: 1 | G11: 1 | H11: 1 | I11: 1 | J11: 1 | K11: 1 | L11: 1 | M11: 1 | N11: 1
B12: Cash from Operations | C12: =SUM(C6,C8,C10) -> 3 | D12: =SUM(D6,D8,D10) -> 3 | E12: =SUM(E6,E8,E10) -> 3 | F12: =SUM(F6,F8,F10) -> 3 | G12: =SUM(G6,G8,G10) -> 3 | H12: =SUM(H6,H8,H10) -> 3 | I12: =SUM(I6,I8,I10) -> 3 | J12: =SUM(J6,J8,J10) -> 3 | ... N12: =SUM(N6,N8,N10) -> 3
B13: Budget | C13: =SUM(C7,C9,C11) -> 3 | D13: =SUM(D7,D9,D11) -> 3 | E13: =SUM(E7,E9,E11) -> 3 | F13: =SUM(F7,F9,F11) -> 3 | G13: =SUM(G7,G9,G11) -> 3 | H13: =SUM(H7,H9,H11) -> 3 | I13: =SUM(I7,I9,I11) -> 3 | J13: =SUM(J7,J9,J11) -> 3 | ... N13: =SUM(N7,N9,N11) -> 3
B15: INVESTING ACTIVITIES
B16: CapEx | C16: 1 | D16: 1 | E16: 1 | F16: 1 | G16: 1 | H16: 1 | I16: 1 | J16: 1 | K16: 1 | L16: 1 | M16: 1 | N16: 1
B17: Budget | C17: 1 | D17: 1 | E17: 1 | F17: 1 | G17: 1 | H17: 1 | I17: 1 | J17: 1 | K17: 1 | L17: 1 | M17: 1 | N17: 1
B18: Acquisitions / Disposals | C18: 1 | D18: 1 | E18: 1 | F18: 1 | G18: 1 | H18: 1 | I18: 1 | J18: 1 | K18: 1 | L18: 1 | M18: 1 | N18: 1
B19: Budget | C19: 1 | D19: 1 | E19: 1 | F19: 1 | G19: 1 | H19: 1 | I19: 1 | J19: 1 | K19: 1 | L19: 1 | M19: 1 | N19: 1
B20: Cash from Investing | C20: =SUM(C16,C18) -> 2 | D20: =SUM(D16,D18) -> 2 | E20: =SUM(E16,E18) -> 2 | F20: =SUM(F16,F18) -> 2 | G20: =SUM(G16,G18) -> 2 | H20: =SUM(H16,H18) -> 2 | I20: =SUM(I16,I18) -> 2 | J20: =SUM(J16,J18) -> 2 | ... N20: =SUM(N16,N18) -> 2
B21: Budget | C21: =SUM(C17,C19) -> 2 | D21: =SUM(D17,D19) -> 2 | E21: =SUM(E17,E19) -> 2 | F21: =SUM(F17,F19) -> 2 | G21: =SUM(G17,G19) -> 2 | H21: =SUM(H17,H19) -> 2 | I21: =SUM(I17,I19) -> 2 | J21: =SUM(J17,J19) -> 2 | ... N21: =SUM(N17,N19) -> 2
B23: FINANCING ACTIVITIES
B24: Debt Draws / (Repayments) | C24: 1 | D24: 1 | E24: 1 | F24: 1 | G24: 1 | H24: 1 | I24: 1 | J24: 1 | K24: 1 | L24: 1 | M24: 1 | N24: 1
B25: Budget | C25: 1 | D25: 1 | E25: 1 | F25: 1 | G25: 1 | H25: 1 | I25: 1 | J25: 1 | K25: 1 | L25: 1 | M25: 1 | N25: 1
B26: Dividends / Distributions | C26: 1 | D26: 1 | E26: 1 | F26: 1 | G26: 1 | H26: 1 | I26: 1 | J26: 1 | K26: 1 | L26: 1 | M26: 1 | N26: 1
B27: Budget | C27: 1 | D27: 1 | E27: 1 | F27: 1 | G27: 1 | H27: 1 | I27: 1 | J27: 1 | K27: 1 | L27: 1 | M27: 1 | N27: 1
B28: Cash from Financing | C28: =SUM(C24,C26) -> 2 | D28: =SUM(D24,D26) -> 2 | E28: =SUM(E24,E26) -> 2 | F28: =SUM(F24,F26) -> 2 | G28: =SUM(G24,G26) -> 2 | H28: =SUM(H24,H26) -> 2 | I28: =SUM(I24,I26) -> 2 | J28: =SUM(J24,J26) -> 2 | ... N28: =SUM(N24,N26) -> 2
B29: Budget | C29: =SUM(C25,C27) -> 2 | D29: =SUM(D25,D27) -> 2 | E29: =SUM(E25,E27) -> 2 | F29: =SUM(F25,F27) -> 2 | G29: =SUM(G25,G27) -> 2 | H29: =SUM(H25,H27) -> 2 | I29: =SUM(I25,I27) -> 2 | J29: =SUM(J25,J27) -> 2 | ... N29: =SUM(N25,N27) -> 2
B31: Net Change in Cash | C31: =C12+C20+C28 -> 7 | D31: =D12+D20+D28 -> 7 | E31: =E12+E20+E28 -> 7 | F31: =F12+F20+F28 -> 7 | G31: =G12+G20+G28 -> 7 | H31: =H12+H20+H28 -> 7 | I31: =I12+I20+I28 -> 7 | J31: =J12+J20+J28 -> 7 | ... N31: =N12+N20+N28 -> 7
B32: Budget | C32: =C13+C21+C29 -> 7 | D32: =D13+D21+D29 -> 7 | E32: =E13+E21+E29 -> 7 | F32: =F13+F21+F29 -> 7 | G32: =G13+G21+G29 -> 7 | H32: =H13+H21+H29 -> 7 | I32: =I13+I21+I29 -> 7 | J32: =J13+J21+J29 -> 7 | ... N32: =N13+N21+N29 -> 7
B33: Beginning Cash | C33: 1 | D33: 1 | E33: 1 | F33: 1 | G33: 1 | H33: 1 | I33: 1 | J33: 1 | K33: 1 | L33: 1 | M33: 1 | N33: 1
B34: Budget | C34: 1 | D34: 1 | E34: 1 | F34: 1 | G34: 1 | H34: 1 | I34: 1 | J34: 1 | K34: 1 | L34: 1 | M34: 1 | N34: 1
B35: Ending Cash | C35: =C33+C31 -> 8 | D35: =D33+D31 -> 8 | E35: =E33+E31 -> 8 | F35: =F33+F31 -> 8 | G35: =G33+G31 -> 8 | H35: =H33+H31 -> 8 | I35: =I33+I31 -> 8 | J35: =J33+J31 -> 8 | ... N35: =N33+N31 -> 8
B36: Budget | C36: =C34+C32 -> 8 | D36: =D34+D32 -> 8 | E36: =E34+E32 -> 8 | F36: =F34+F32 -> 8 | G36: =G34+G32 -> 8 | H36: =H34+H32 -> 8 | I36: =I34+I32 -> 8 | J36: =J34+J32 -> 8 | ... N36: =N34+N32 -> 8

Sheet KPI
B2: KPI Flash Input
B3: [Company Name]
C4: 45658 | D4: 45689 | E4: 45717 | F4: 45748 | G4: 45778 | H4: 45809 | I4: 45839 | J4: 45870 | K4: 45901 | L4: 45931 | M4: 45962 | N4: 45992
B5: FINANCIAL KPIs
B6: 2 | C6: 1 | D6: 1 | E6: 1 | F6: 1 | G6: 1 | H6: 1 | I6: 1 | J6: 1 | K6: 1 | L6: 1 | M6: 1 | N6: 1
B7: 2 | C7: 1 | D7: 1 | E7: 1 | F7: 1 | G7: 1 | H7: 1 | I7: 1 | J7: 1 | K7: 1 | L7: 1 | M7: 1 | N7: 1
B8: 2 | C8: 1 | D8: 1 | E8: 1 | F8: 1 | G8: 1 | H8: 1 | I8: 1 | J8: 1 | K8: 1 | L8: 1 | M8: 1 | N8: 1
B9: 2 | C9: 1 | D9: 1 | E9: 1 | F9: 1 | G9: 1 | H9: 1 | I9: 1 | J9: 1 | K9: 1 | L9: 1 | M9: 1 | N9: 1
B10: 2 | C10: 1 | D10: 1 | E10: 1 | F10: 1 | G10: 1 | H10: 1 | I10: 1 | J10: 1 | K10: 1 | L10: 1 | M10: 1 | N10: 1
B12: OPERATIONAL KPIs
B13: 2 | C13: 1 | D13: 1 | E13: 1 | F13: 1 | G13: 1 | H13: 1 | I13: 1 | J13: 1 | K13: 1 | L13: 1 | M13: 1 | N13: 1
B14: 2 | C14: 1 | D14: 1 | E14: 1 | F14: 1 | G14: 1 | H14: 1 | I14: 1 | J14: 1 | K14: 1 | L14: 1 | M14: 1 | N14: 1
B15: 2 | C15: 1 | D15: 1 | E15: 1 | F15: 1 | G15: 1 | H15: 1 | I15: 1 | J15: 1 | K15: 1 | L15: 1 | M15: 1 | N15: 1
B16: 2 | C16: 1 | D16: 1 | E16: 1 | F16: 1 | G16: 1 | H16: 1 | I16: 1 | J16: 1 | K16: 1 | L16: 1 | M16: 1 | N16: 1
B17: 2 | C17: 1 | D17: 1 | E17: 1 | F17: 1 | G17: 1 | H17: 1 | I17: 1 | J17: 1 | K17: 1 | L17: 1 | M17: 1 | N17: 1
B18: 2 | C18: 1 | D18: 1 | E18: 1 | F18: 1 | G18: 1 | H18: 1 | I18: 1 | J18: 1 | K18: 1 | L18: 1 | M18: 1 | N18: 1
B19: 2 | C19: 1 | D19: 1 | E19: 1 | F19: 1 | G19: 1 | H19: 1 | I19: 1 | J19: 1 | K19: 1 | L19: 1 | M19: 1 | N19: 1
B21: WORKING CAPITAL KPIs
B22: 2 | C22: 1 | D22: 1 | E22: 1 | F22: 1 | G22: 1 | H22: 1 | I22: 1 | J22: 1 | K22: 1 | L22: 1 | M22: 1 | N22: 1
B23: 2 | C23: 1 | D23: 1 | E23: 1 | F23: 1 | G23: 1 | H23: 1 | I23: 1 | J23: 1 | K23: 1 | L23: 1 | M23: 1 | N23: 1
B24: 2 | C24: 1 | D24: 1 | E24: 1 | F24: 1 | G24: 1 | H24: 1 | I24: 1 | J24: 1 | K24: 1 | L24: 1 | M24: 1 | N24: 1
B25: 2 | C25: 1 | D25: 1 | E25: 1 | F25: 1 | G25: 1 | H25: 1 | I25: 1 | J25: 1 | K25: 1 | L25: 1 | M25: 1 | N25: 1

Sheet Debt-Ratio
B2: Debt Ratio Flash Input
B3: [Company Name]
C4: 45658 | D4: 45689 | E4: 45717 | F4: 45748 | G4: 45778 | H4: 45809 | I4: 45839 | J4: 45870 | K4: 45901 | L4: 45931 | M4: 45962 | N4: 45992
B5: DEBT & CAPITAL METRICS
B6: Total Debt Outstanding | C6: {='Debt-Overview'!C25} -> 8 | D6: {='Debt-Overview'!D25} -> 8 | E6: {='Debt-Overview'!E25} -> 8 | F6: {='Debt-Overview'!F25} -> 8 | G6: {='Debt-Overview'!G25} -> 8 | H6: {='Debt-Overview'!H25} -> 8 | I6: {='Debt-Overview'!I25} -> 8 | J6: {='Debt-Overview'!J25} -> 8 | ... N6: {='Debt-Overview'!N25} -> 8
B7: Cash & Cash Equivalents | C7: {=BS!C6} -> 1 | D7: {=BS!D6} -> 1 | E7: {=BS!E6} -> 1 | F7: {=BS!F6} -> 1 | G7: {=BS!G6} -> 1 | H7: {=BS!H6} -> 1 | I7: {=BS!I6} -> 1 | J7: {=BS!J6} -> 1 | ... N7: {=BS!N6} -> 1
B8: Net Debt | C8: =C6-C7 -> 7 | D8: =D6-D7 -> 7 | E8: =E6-E7 -> 7 | F8: =F6-F7 -> 7 | G8: =G6-G7 -> 7 | H8: =H6-H7 -> 7 | I8: =I6-I7 -> 7 | J8: =J6-J7 -> 7 | ... N8: =N6-N7 -> 7
B9: Total Enterprise Value (TEV) | C9: 1 | D9: 1 | E9: 1 | F9: 1 | G9: 1 | H9: 1 | I9: 1 | J9: 1 | K9: 1 | L9: 1 | M9: 1 | N9: 1
B10: Equity Value (TEV - Net Debt) | C10: =C9-C8 -> -6 | D10: =D9-D8 -> -6 | E10: =E9-E8 -> -6 | F10: =F9-F8 -> -6 | G10: =G9-G8 -> -6 | H10: =H9-H8 -> -6 | I10: =I9-I8 -> -6 | J10: =J9-J8 -> -6 | ... N10: =N9-N8 -> -6
B12: EBITDA METRICS (Monthly)
B13: EBITDA (Reported) | C13: {='P&L'!C15} -> -1 | D13: {='P&L'!D15} -> -1 | E13: {='P&L'!E15} -> -1 | F13: {='P&L'!F15} -> -1 | G13: {='P&L'!G15} -> -1 | H13: {='P&L'!H15} -> -1 | I13: {='P&L'!I15} -> -1 | J13: {='P&L'!J15} -> -1 | ... N13: {='P&L'!N15} -> -1
B14: Adjusted EBITDA | C14: {='P&L'!C29} -> 7 | D14: {='P&L'!D29} -> 7 | E14: {='P&L'!E29} -> 7 | F14: {='P&L'!F29} -> 7 | G14: {='P&L'!G29} -> 7 | H14: {='P&L'!H29} -> 7 | I14: {='P&L'!I29} -> 7 | J14: {='P&L'!J29} -> 7 | ... N14: {='P&L'!N29} -> 7
B15: Run-Rate EBITDA (Input) | C15: 1 | D15: 1 | E15: 1 | F15: 1 | G15: 1 | H15: 1 | I15: 1 | J15: 1 | K15: 1 | L15: 1 | M15: 1 | N15: 1
B16: Revenue | C16: {='P&L'!C5} -> 1 | D16: {='P&L'!D5} -> 1 | E16: {='P&L'!E5} -> 1 | F16: {='P&L'!F5} -> 1 | G16: {='P&L'!G5} -> 1 | H16: {='P&L'!H5} -> 1 | I16: {='P&L'!I5} -> 1 | J16: {='P&L'!J5} -> 1 | ... N16: {='P&L'!N5} -> 1
B18: LEVERAGE RATIOS
B19: Gross Leverage (Debt / Adj EBITDA) | C19: =IF(C14=0,"",C6/C14) -> 1.1428571 | D19: =IF(D14=0,"",D6/D14) -> 1.1428571 | E19: =IF(E14=0,"",E6/E14) -> 1.1428571 | F19: =IF(F14=0,"",F6/F14) -> 1.1428571 | G19: =IF(G14=0,"",G6/G14) -> 1.1428571 | H19: =IF(H14=0,"",H6/H14) -> 1.1428571 | I19: =IF(I14=0,"",I6/I14) -> 1.1428571 | J19: =IF(J14=0,"",J6/J14) -> 1.1428571 | ... N19: =IF(N14=0,"",N6/N14) -> 1.1428571
B20: Net Leverage (Net Debt / Adj EBITDA) | C20: =IF(C14=0,"",C8/C14) -> 1 | D20: =IF(D14=0,"",D8/D14) -> 1 | E20: =IF(E14=0,"",E8/E14) -> 1 | F20: =IF(F14=0,"",F8/F14) -> 1 | G20: =IF(G14=0,"",G8/G14) -> 1 | H20: =IF(H14=0,"",H8/H14) -> 1 | I20: =IF(I14=0,"",I8/I14) -> 1 | J20: =IF(J14=0,"",J8/J14) -> 1 | ... N20: =IF(N14=0,"",N8/N14) -> 1
B21: Senior Leverage (if applicable) | C21: 1 | D21: 1 | E21: 1 | F21: 1 | G21: 1 | H21: 1 | I21: 1 | J21: 1 | K21: 1 | L21: 1 | M21: 1 | N21: 1
B22: First Lien Leverage | C22: 1 | D22: 1 | E22: 1 | F22: 1 | G22: 1 | H22: 1 | I22: 1 | J22: 1 | K22: 1 | L22: 1 | M22: 1 | N22: 1
B23: Secured Leverage | C23: 1 | D23: 1 | E23: 1 | F23: 1 | G23: 1 | H23: 1 | I23: 1 | J23: 1 | K23: 1 | L23: 1 | M23: 1 | N23: 1
B25: COVERAGE RATIOS
B26: Est. Monthly Cash Interest | C26: ='Debt-Overview'!C25*'Debt-Overview'!C33/12 -> 0.66666667 | D26: ='Debt-Overview'!D25*'Debt-Overview'!D33/12 -> 0.66666667 | E26: ='Debt-Overview'!E25*'Debt-Overview'!E33/12 -> 0.66666667 | F26: ='Debt-Overview'!F25*'Debt-Overview'!F33/12 -> 0.66666667 | G26: ='Debt-Overview'!G25*'Debt-Overview'!G33/12 -> 0.66666667 | H26: ='Debt-Overview'!H25*'Debt-Overview'!H33/12 -> 0.66666667 | I26: ='Debt-Overview'!I25*'Debt-Overview'!I33/12 -> 0.66666667 | J26: ='Debt-Overview'!J25*'Debt-Overview'!J33/12 -> 0.66666667 | ... N26: ='Debt-Overview'!N25*'Debt-Overview'!N33/12 -> 0.66666667
B27: Monthly Principal Amortization | C27: 1 | D27: 1 | E27: 1 | F27: 1 | G27: 1 | H27: 1 | I27: 1 | J27: 1 | K27: 1 | L27: 1 | M27: 1 | N27: 1
B28: Total Debt Service | C28: =C26+C27 -> 1.6666667 | D28: =D26+D27 -> 1.6666667 | E28: =E26+E27 -> 1.6666667 | F28: =F26+F27 -> 1.6666667 | G28: =G26+G27 -> 1.6666667 | H28: =H26+H27 -> 1.6666667 | I28: =I26+I27 -> 1.6666667 | J28: =J26+J27 -> 1.6666667 | ... N28: =N26+N27 -> 1.6666667
B29: Interest Coverage (EBITDA / Int) | C29: =IF(C26=0,"",C14/C26) -> 10.5 | D29: =IF(D26=0,"",D14/D26) -> 10.5 | E29: =IF(E26=0,"",E14/E26) -> 10.5 | F29: =IF(F26=0,"",F14/F26) -> 10.5 | G29: =IF(G26=0,"",G14/G26) -> 10.5 | H29: =IF(H26=0,"",H14/H26) -> 10.5 | I29: =IF(I26=0,"",I14/I26) -> 10.5 | J29: =IF(J26=0,"",J14/J26) -> 10.5 | ... N29: =IF(N26=0,"",N14/N26) -> 10.5
B30: Fixed Charge Coverage (EBITDA-CapEx)/DS | C30: =IF(C28=0,"",(C14-C35)/C28) -> 3.6 | D30: =IF(D28=0,"",(D14-D35)/D28) -> 3.6 | E30: =IF(E28=0,"",(E14-E35)/E28) -> 3.6 | F30: =IF(F28=0,"",(F14-F35)/F28) -> 3.6 | G30: =IF(G28=0,"",(G14-G35)/G28) -> 3.6 | H30: =IF(H28=0,"",(H14-H35)/H28) -> 3.6 | I30: =IF(I28=0,"",(I14-I35)/I28) -> 3.6 | J30: =IF(J28=0,"",(J14-J35)/J28) -> 3.6 | ... N30: =IF(N28=0,"",(N14-N35)/N28) -> 3.6
B31: Cash Interest / EBITDA (%) | C31: =IF(C14=0,"",C26/C14) -> 0.095238095 | D31: =IF(D14=0,"",D26/D14) -> 0.095238095 | E31: =IF(E14=0,"",E26/E14) -> 0.095238095 | F31: =IF(F14=0,"",F26/F14) -> 0.095238095 | G31: =IF(G14=0,"",G26/G14) -> 0.095238095 | H31: =IF(H14=0,"",H26/H14) -> 0.095238095 | I31: =IF(I14=0,"",I26/I14) -> 0.095238095 | J31: =IF(J14=0,"",J26/J14) -> 0.095238095 | ... N31: =IF(N14=0,"",N26/N14) -> 0.095238095
B33: CASH FLOW METRICS
B34: Operating Cash Flow | C34: {='Cash-Flow'!C12} -> 3 | D34: {='Cash-Flow'!D12} -> 3 | E34: {='Cash-Flow'!E12} -> 3 | F34: {='Cash-Flow'!F12} -> 3 | G34: {='Cash-Flow'!G12} -> 3 | H34: {='Cash-Flow'!H12} -> 3 | I34: {='Cash-Flow'!I12} -> 3 | J34: {='Cash-Flow'!J12} -> 3 | ... N34: {='Cash-Flow'!N12} -> 3
B35: CapEx | C35: =ABS('Cash-Flow'!C16) -> 1 | D35: =ABS('Cash-Flow'!D16) -> 1 | E35: =ABS('Cash-Flow'!E16) -> 1 | F35: =ABS('Cash-Flow'!F16) -> 1 | G35: =ABS('Cash-Flow'!G16) -> 1 | H35: =ABS('Cash-Flow'!H16) -> 1 | I35: =ABS('Cash-Flow'!I16) -> 1 | J35: =ABS('Cash-Flow'!J16) -> 1 | ... N35: =ABS('Cash-Flow'!N16) -> 1
B36: Free Cash Flow (OCF - CapEx) | C36: =C34-C35 -> 2 | D36: =D34-D35 -> 2 | E36: =E34-E35 -> 2 | F36: =F34-F35 -> 2 | G36: =G34-G35 -> 2 | H36: =H34-H35 -> 2 | I36: =I34-I35 -> 2 | J36: =J34-J35 -> 2 | ... N36: =N34-N35 -> 2
B37: FCF / Debt Service (%) | C37: =IF(C28=0,"",C36/C28) -> 1.2 | D37: =IF(D28=0,"",D36/D28) -> 1.2 | E37: =IF(E28=0,"",E36/E28) -> 1.2 | F37: =IF(F28=0,"",F36/F28) -> 1.2 | G37: =IF(G28=0,"",G36/G28) -> 1.2 | H37: =IF(H28=0,"",H36/H28) -> 1.2 | I37: =IF(I28=0,"",I36/I28) -> 1.2 | J37: =IF(J28=0,"",J36/J28) -> 1.2 | ... N37: =IF(N28=0,"",N36/N28) -> 1.2
B38: Cash Conversion (FCF / Adj EBITDA) | C38: =IF(C14=0,"",C36/C14) -> 0.28571429 | D38: =IF(D14=0,"",D36/D14) -> 0.28571429 | E38: =IF(E14=0,"",E36/E14) -> 0.28571429 | F38: =IF(F14=0,"",F36/F14) -> 0.28571429 | G38: =IF(G14=0,"",G36/G14) -> 0.28571429 | H38: =IF(H14=0,"",H36/H14) -> 0.28571429 | I38: =IF(I14=0,"",I36/I14) -> 0.28571429 | J38: =IF(J14=0,"",J36/J14) -> 0.28571429 | ... N38: =IF(N14=0,"",N36/N14) -> 0.28571429
B39: Debt Paydown Capacity (FCF / Debt) | C39: =IF(C6=0,"",C36/C6) -> 0.25 | D39: =IF(D6=0,"",D36/D6) -> 0.25 | E39: =IF(E6=0,"",E36/E6) -> 0.25 | F39: =IF(F6=0,"",F36/F6) -> 0.25 | G39: =IF(G6=0,"",G36/G6) -> 0.25 | H39: =IF(H6=0,"",H36/H6) -> 0.25 | I39: =IF(I6=0,"",I36/I6) -> 0.25 | J39: =IF(J6=0,"",J36/J6) -> 0.25 | ... N39: =IF(N6=0,"",N36/N6) -> 0.25
B41: VALUATION METRICS
B42: TEV / Adj EBITDA | C42: =IF(C14=0,"",C9/C14) -> 0.14285714 | D42: =IF(D14=0,"",D9/D14) -> 0.14285714 | E42: =IF(E14=0,"",E9/E14) -> 0.14285714 | F42: =IF(F14=0,"",F9/F14) -> 0.14285714 | G42: =IF(G14=0,"",G9/G14) -> 0.14285714 | H42: =IF(H14=0,"",H9/H14) -> 0.14285714 | I42: =IF(I14=0,"",I9/I14) -> 0.14285714 | J42: =IF(J14=0,"",J9/J14) -> 0.14285714 | ... N42: =IF(N14=0,"",N9/N14) -> 0.14285714
B43: TEV / Run-Rate EBITDA | C43: =IF(C15=0,"",C9/C15) -> 1 | D43: =IF(D15=0,"",D9/D15) -> 1 | E43: =IF(E15=0,"",E9/E15) -> 1 | F43: =IF(F15=0,"",F9/F15) -> 1 | G43: =IF(G15=0,"",G9/G15) -> 1 | H43: =IF(H15=0,"",H9/H15) -> 1 | I43: =IF(I15=0,"",I9/I15) -> 1 | J43: =IF(J15=0,"",J9/J15) -> 1 | ... N43: =IF(N15=0,"",N9/N15) -> 1
B44: TEV / Revenue | C44: =IF(C16=0,"",C9/C16) -> 1 | D44: =IF(D16=0,"",D9/D16) -> 1 | E44: =IF(E16=0,"",E9/E16) -> 1 | F44: =IF(F16=0,"",F9/F16) -> 1 | G44: =IF(G16=0,"",G9/G16) -> 1 | H44: =IF(H16=0,"",H9/H16) -> 1 | I44: =IF(I16=0,"",I9/I16) -> 1 | J44: =IF(J16=0,"",J9/J16) -> 1 | ... N44: =IF(N16=0,"",N9/N16) -> 1
B45: Equity / Adj EBITDA | C45: =IF(C14=0,"",C10/C14) -> -0.85714286 | D45: =IF(D14=0,"",D10/D14) -> -0.85714286 | E45: =IF(E14=0,"",E10/E14) -> -0.85714286 | F45: =IF(F14=0,"",F10/F14) -> -0.85714286 | G45: =IF(G14=0,"",G10/G14) -> -0.85714286 | H45: =IF(H14=0,"",H10/H14) -> -0.85714286 | I45: =IF(I14=0,"",I10/I14) -> -0.85714286 | J45: =IF(J14=0,"",J10/J14) -> -0.85714286 | ... N45: =IF(N14=0,"",N10/N14) -> -0.85714286
B47: COVENANT COMPLIANCE
...

Sheet Debt-Overview
B2: Debt Overview Flash Input
B3: [Company Name]
C4: 45658 | D4: 45689 | E4: 45717 | F4: 45748 | G4: 45778 | H4: 45809 | I4: 45839 | J4: 45870 | K4: 45901 | L4: 45931 | M4: 45962 | N4: 45992
B5: SENIOR SECURED DEBT
B6: Revolver - Commitment | C6: 1 | D6: 1 | E6: 1 | F6: 1 | G6: 1 | H6: 1 | I6: 1 | J6: 1 | K6: 1 | L6: 1 | M6: 1 | N6: 1
B7: Revolver - Drawn | C7: 1 | D7: 1 | E7: 1 | F7: 1 | G7: 1 | H7: 1 | I7: 1 | J7: 1 | K7: 1 | L7: 1 | M7: 1 | N7: 1
B8: Revolver - Available | C8: =C6-C7 -> 0 | D8: =D6-D7 -> 0 | E8: =E6-E7 -> 0 | F8: =F6-F7 -> 0 | G8: =G6-G7 -> 0 | H8: =H6-H7 -> 0 | I8: =I6-I7 -> 0 | J8: =J6-J7 -> 0 | ... N8: =N6-N7 -> 0
B9: Term Loan A - Outstanding | C9: 1 | D9: 1 | E9: 1 | F9: 1 | G9: 1 | H9: 1 | I9: 1 | J9: 1 | K9: 1 | L9: 1 | M9: 1 | N9: 1
B10: Term Loan B - Outstanding | C10: 1 | D10: 1 | E10: 1 | F10: 1 | G10: 1 | H10: 1 | I10: 1 | J10: 1 | K10: 1 | L10: 1 | M10: 1 | N10: 1
B11: Total Senior Secured | C11: =C7+C9+C10 -> 3 | D11: =D7+D9+D10 -> 3 | E11: =E7+E9+E10 -> 3 | F11: =F7+F9+F10 -> 3 | G11: =G7+G9+G10 -> 3 | H11: =H7+H9+H10 -> 3 | I11: =I7+I9+I10 -> 3 | J11: =J7+J9+J10 -> 3 | ... N11: =N7+N9+N10 -> 3
B13: SUBORDINATED / MEZZ DEBT
B14: Second Lien - Outstanding | C14: 1 | D14: 1 | E14: 1 | F14: 1 | G14: 1 | H14: 1 | I14: 1 | J14: 1 | K14: 1 | L14: 1 | M14: 1 | N14: 1
B15: Mezzanine - Outstanding | C15: 1 | D15: 1 | E15: 1 | F15: 1 | G15: 1 | H15: 1 | I15: 1 | J15: 1 | K15: 1 | L15: 1 | M15: 1 | N15: 1
B16: Total Subordinated | C16: =C14+C15 -> 2 | D16: =D14+D15 -> 2 | E16: =E14+E15 -> 2 | F16: =F14+F15 -> 2 | G16: =G14+G15 -> 2 | H16: =H14+H15 -> 2 | I16: =I14+I15 -> 2 | J16: =J14+J15 -> 2 | ... N16: =N14+N15 -> 2
B18: OTHER DEBT
B19: Capital Lease Obligations | C19: 1 | D19: 1 | E19: 1 | F19: 1 | G19: 1 | H19: 1 | I19: 1 | J19: 1 | K19: 1 | L19: 1 | M19: 1 | N19: 1
B20: Seller Notes | C20: 1 | D20: 1 | E20: 1 | F20: 1 | G20: 1 | H20: 1 | I20: 1 | J20: 1 | K20: 1 | L20: 1 | M20: 1 | N20: 1
B21: Other Debt | C21: 1 | D21: 1 | E21: 1 | F21: 1 | G21: 1 | H21: 1 | I21: 1 | J21: 1 | K21: 1 | L21: 1 | M21: 1 | N21: 1
B22: Total Other Debt | C22: =SUM(C19:C21) -> 3 | D22: =SUM(D19:D21) -> 3 | E22: =SUM(E19:E21) -> 3 | F22: =SUM(F19:F21) -> 3 | G22: =SUM(G19:G21) -> 3 | H22: =SUM(H19:H21) -> 3 | I22: =SUM(I19:I21) -> 3 | J22: =SUM(J19:J21) -> 3 | ... N22: =SUM(N19:N21) -> 3
B24: TOTAL DEBT SUMMARY
B25: Total Debt Outstanding | C25: =C11+C16+C22 -> 8 | D25: =D11+D16+D22 -> 8 | E25: =E11+E16+E22 -> 8 | F25: =F11+F16+F22 -> 8 | G25: =G11+G16+G22 -> 8 | H25: =H11+H16+H22 -> 8 | I25: =I11+I16+I22 -> 8 | J25: =J11+J16+J22 -> 8 | ... N25: =N11+N16+N22 -> 8
B26: (-) Cash & Equivalents | C26: {=BS!C6} -> 1 | D26: {=BS!D6} -> 1 | E26: {=BS!E6} -> 1 | F26: {=BS!F6} -> 1 | G26: {=BS!G6} -> 1 | H26: {=BS!H6} -> 1 | I26: {=BS!I6} -> 1 | J26: {=BS!J6} -> 1 | ... N26: {=BS!N6} -> 1
B27: Net Debt | C27: =C25-C26 -> 7 | D27: =D25-D26 -> 7 | E27: =E25-E26 -> 7 | F27: =F25-F26 -> 7 | G27: =G25-G26 -> 7 | H27: =H25-H26 -> 7 | I27: =I25-I26 -> 7 | J27: =J25-J26 -> 7 | ... N27: =N25-N26 -> 7
B29: INTEREST RATE SUMMARY
B30: Revolver Rate (%) | C30: 1 | D30: 1 | E30: 1 | F30: 1 | G30: 1 | H30: 1 | I30: 1 | J30: 1 | K30: 1 | L30: 1 | M30: 1 | N30: 1
B31: TLA Rate (%) | C31: 1 | D31: 1 | E31: 1 | F31: 1 | G31: 1 | H31: 1 | I31: 1 | J31: 1 | K31: 1 | L31: 1 | M31: 1 | N31: 1
B32: TLB Rate (%) | C32: 1 | D32: 1 | E32: 1 | F32: 1 | G32: 1 | H32: 1 | I32: 1 | J32: 1 | K32: 1 | L32: 1 | M32: 1 | N32: 1
B33: Blended Interest Rate (%) | C33: =(C7*C30+C9*C31+C10*C32)/C11 -> 1 | D33: =(D7*D30+D9*D31+D10*D32)/D11 -> 1 | E33: =(E7*E30+E9*E31+E10*E32)/E11 -> 1 | F33: =(F7*F30+F9*F31+F10*F32)/F11 -> 1 | G33: =(G7*G30+G9*G31+G10*G32)/G11 -> 1 | H33: =(H7*H30+H9*H31+H10*H32)/H11 -> 1 | I33: =(I7*I30+I9*I31+I10*I32)/I11 -> 1 | J33: =(J7*J30+J9*J31+J10*J32)/J11 -> 1 | ... N33: =(N7*N30+N9*N31+N10*N32)/N11 -> 1

Sheet Adjustment-Types
B2: EBITDA Adjustment Types Reference
B4: Adjustment Code | C4: Adjustment Type | D4: Description | E4: Direction
B5: ADD-01 | C5: One-Time Restructuring | D5: Severance, facility closure costs, reorganization expenses | E5: Add-back (+)
B6: ADD-02 | C6: Transaction Costs | D6: M&A fees, legal, accounting, due diligence costs | E6: Add-back (+)
B7: ADD-03 | C7: Non-Cash Stock Comp | D7: Stock-based compensation expense | E7: Add-back (+)
B8: ADD-04 | C8: Management Fees | D8: Sponsor management/monitoring fees | E8: Add-back (+)
B9: ADD-05 | C9: Non-Recurring Legal | D9: Litigation settlements, unusual legal costs | E9: Add-back (+)
B10: ADD-06 | C10: Asset Impairment | D10: Non-cash goodwill/asset write-downs | E10: Add-back (+)
B11: ADD-07 | C11: FX Losses (Non-Cash) | D11: Unrealized foreign exchange losses | E11: Add-back (+)
B12: ADD-08 | C12: Integration Costs | D12: Post-acquisition integration expenses | E12: Add-back (+)
B13: ADD-09 | C13: Start-Up Costs | D13: New facility/product launch expenses | E13: Add-back (+)
B14: ADD-10 | C14: Natural Disaster | D14: One-time costs from floods, fires, etc. | E14: Add-back (+)
B15: DED-01 | C15: One-Time Gains | D15: Non-recurring income or gains | E15: Deduction (-)
... B33: MA2-06 | C33: Carve-Out Costs | D33: One-time separation costs for divestitures | E33: Add-back (+)
B35: Note: LFL = Like-for-Like (organic growth analysis). MA2 = M&A Type 2 (credit agreement / covenant adjustments).

Sheet Input-Summary
B2: PE Portfolio Company Flash Input Summary
B3: [Company Name]
B5: Sheet | C5: Metric | D5: December Cell Ref | E5: Description
B6: P&L | C6: Revenue | D6: P&L!N5 | E6: Monthly revenue from sales/services
B7: P&L | C7: Revenue Budget | D7: P&L!N6 | E7: Budgeted monthly revenue
B8: P&L | C8: Cost of Goods Sold | D8: P&L!N7 | E8: Direct costs of products/services sold
B9: P&L | C9: COGS Budget | D9: P&L!N8 | E9: Budgeted COGS
B10: P&L | C10: Operating Expenses | D10: P&L!N12 | E10: SG&A, R&D, and other operating costs
B11: P&L | C11: OpEx Budget | D11: P&L!N13 | E11: Budgeted operating expenses
B12: P&L | C12: EBITDA Adj Type | D12: P&L!B20:B27 | E12: Select adjustment type from dropdown (One-Time Restructuring, Transaction Costs, etc.)
B13: P&L | C13: EBITDA Adj Description | D13: P&L!C20:C27 | E13: Brief description of adjustment
B14: P&L | C14: EBITDA Adj Values | D14: P&L!D20:O27 | E14: Monthly adjustment amounts (positive = add-back, negative = deduction)
B15: P&L | C15: Depreciation | D15: P&L!N31 | E15: Monthly depreciation expense
B16: P&L | C16: Depreciation Budget | D16: P&L!N32 | E16: Budgeted depreciation
... B99: Debt-Overview | C99: TLB Rate (%) | D99: Debt-Overview!N32 | E99: Interest rate on Term Loan B
