Workbook
Name array_displayUnit: tbl_displayUnit[UnitName]
Name array_timeline: _xlfn.ANCHORARRAY(Developer!$B$97)
Name array_typeIAdj: _xlfn.ANCHORARRAY(Developer!$B$164)
Name COMPANY_ENTITY_ID: PM_Support[COMPANY_ENTITY_ID]
Name Company_selector: _xlfn.ANCHORARRAY(Developer!$J$410)
Name CVC.PACK: _xlfn.LAMBDA(_xlpm.Array,_xlfn.TEXTJOIN("¶",FALSE,_xlfn.BYROW(_xlpm.Array,_xlfn.LAMBDA(_xlpm.row,_xlfn.TEXTJOIN("|",FALSE,_xlpm.row)))))
Name CX_ENTITY: Developer!$A$7
Name debt_ouput_replay_schedule: _xlfn.ANCHORARRAY(DebtOverview!$BZ$64)
Name debt_output_db: _xlfn.ANCHORARRAY(DebtOverview!$BK$67)
Name DebtRatio_Normal: DebtOverview!$C$8
Name fx_attrConverter: _xlfn.LAMBDA(_xlpm.Input,_xlop.EnablePOC,_xlpm.Input)
Name fx_getLTM: _xlfn.LAMBDA(_xlpm.Array,_xlpm.endDate,_xlpm.Periods,_xlfn.TAKE(_xlfn.DROP(_xlpm.Array,,_xlfn.XMATCH(_xlpm.endDate,array_timeline,0)-_xlpm.Periods),1,_xlpm.Periods))
Name fx_hasCX: _xlfn.LAMBDA(_xlpm.x,SEARCH("CX.",_xlfn.FORMULATEXT(_xlpm.x))>0)
Name fx_ProtectPush: TRUE
Name fx_trailingPeriods: _xlfn.LAMBDA(_xlpm.Periods,_xlpm.EndMonth,EOMONTH(_xlpm.EndMonth,_xlfn.SEQUENCE(1,_xlpm.Periods,-_xlpm.Periods+1,1)))
Name fxVal_normal: DebtOverview!$C$8
Name fxVal_normal: _xlfn.XLOOKUP(val_displayUnit,tbl_displayUnit[UnitName],tbl_displayUnit[Number],1)
Name fxVal_sign: _xlfn.LAMBDA(_xlpm.ID,1)
Name icon_lock: fx_getIcon("lock")
Name icon_unlock: fx_getIcon("unlock")
Name IFBLANK: _xlfn.LAMBDA(_xlpm.Primary,_xlpm.Alternative,IF(_xlpm.Primary="",_xlpm.Alternative,_xlpm.Primary))
Name img_cvc: Developer!$E$158
Name IQ_CH: 110000
Name IQ_CQ: 5000
Name IQ_CY: 10000
Name IQ_DAILY: 500000
Name IQ_FH: 100000
Name IQ_FQ: 500
Name IQ_FY: 1000
Name IQ_LTM: 2000
Name IQ_MONTH: 15000
Name IQ_NTM: 6000
Name IQ_WEEK: 50000
Name IQ_YTD: 3000
Name ISBLANKTAB: _xlfn.LAMBDA(_xlpm.tableStr,TRIM(SUBSTITUTE(SUBSTITUTE(_xlpm.tableStr,"|",""),"¶",""))="")
Name loc_adjExample: AdjustmtType!$C$4
Name LTM: fx_trailingPeriods(12,val_asOfDate)
Name PACK: _xlfn.LAMBDA(_xlpm.tbl,_xlfn.TEXTJOIN("¶",FALSE,_xlfn.BYROW(_xlpm.tbl,_xlfn.LAMBDA(_xlpm.row,_xlfn.TEXTJOIN("|",FALSE,_xlpm.row)))))
Name pqToday: pquery_today[Date]
Name protectStatus: "!$O$4"
Name reportingdate: Developer!$R$2
Name TODECIMAL: _xlfn.LAMBDA(_xlpm.Input,_xlop.NormaliseFactor,_xlfn.LET(_xlpm.Norm,IF(_xlfn.ISOMITTED(_xlpm.NormaliseFactor),1,_xlpm.NormaliseFactor),IF(ISNUMBER(_xlpm.Input),_xlpm.Input/_xlpm.Norm,_xlpm.Input)))
Name UNPACK: _xlfn.LAMBDA(_xlpm.CXReturn,_xlfn.LET(_xlpm.Res,IF(_xlpm.CXReturn="","",_xlfn.TEXTSPLIT(_xlpm.CXReturn,"|","¶",FALSE)),IFERROR(_xlfn.NUMBERVALUE(_xlpm.Res),_xlpm.Res)))
Name UNPACK_ROW: _xlfn.LAMBDA(_xlpm.PackedString,_xlpm.Nth,IF(_xlpm.PackedString="","",IF(ISNUMBER(SEARCH("|",_xlpm.PackedString)),INDEX(_xlfn.TEXTSPLIT(_xlpm.PackedString,"|",,FALSE),_xlpm.Nth),_xlpm.PackedString)))
Name val_asOfDate: PL!$AG$6
Name val_blankRefText: _PL!$S$12
Name val_company: Developer!$A$8
Name val_currentFYE: _PL!$AK$6
Name val_displayUnit: PL!$AL$6
Name val_enablePOC: Developer!$A$11
Name val_priorQtrEnd: _xlfn.LET(_xlpm.GetQtr,_xlfn.LAMBDA(_xlpm.date,EOMONTH(_xlpm.date,3-ROUNDUP(MONTH(_xlpm.date)/3,0)+1)),EOMONTH(_xlpm.GetQtr(val_asOfDate),-3))
Name val_reportingCurrency: _PL!$AM$6

Sheet EVAL LEGEND
B1: Classification eval — Flash Collection_MasterTemplate_2.1.6_PROD
B2: Every cell you marked (1/2) is coloured by what the system did with it:
B4: GREEN | C4: agreement — system fills this marked cell | E4: 5826
B5: RED | C5: MISSED — invisible to the system (no fact, no region) | E5: 90
B6: ORANGE | C6: marked but holds a FORMULA — system never writes formulas | E6: 2158
B7: BLUE | C7: recognized as extensible-region slot (add-line path) | E7: 5
B8: PURPLE | C8: seen but classified config/staging (control/placeholder) | E8: 0
B9: YELLOW | C9: NOT marked by you, but the system would fill it | E9: 1201
B10: PALE GREEN | C10: system FILLS it — your marking is indistinguishable from the template's own value (collision), so unverifiable | E10: 53
B11: PALE PINK | C11: system does NOT fill it — marking/value collision, unverifiable | E11: 1138
B13: Note: YELLOW skips cells whose marking collides with a placeholder value (CLASSIFIED == NORMAL == 1/2) — ground truth is ambiguous there.
B14: Marked cells scored: 8079

Sheet Introduction
A1: unprotected | B1: 2025-12-23T03:33:24.755Z
G3: =_xlfn.IMAGE(INDEX(PM_Support[COMPANY_LOGO_URL],MATCH(val_company,PM_Support[COMPANY_NAME],0))) -> #VALUE!
G6: Introduction to the Monthly Flash Sheets
G10: Introduction
G19: Core Financial Data Collection
G42: Key Performance Indicators (KPIs)
G49: Debt Analysis Section

Sheet AdjustmentReview
A1: unprotected | B1: 2025-12-23T03:33:24.755Z
K3: DO NOT SKIP
F4: Flash Data
F5: Like-for-Like Adjustments Review
F9: Perimeter changes distort year-over-year comparisons. LFL adjustments hold the perimeter constant so you compare the same businesses across periods—either by: > Excluding acquired/disposed contributions in the comparison window, or > Restating the base period on a pro-forma basis to simulate today’s perimeter.
F15: Example. If we bought a business in May, we will add last year’s May–Dec sales as if we’d owned it then. Either way, we’re comparing the same footprint across both years.
AR19: Past FY | AS19: =AU19-1 -> #NAME? | AU19: =YEAR(AU20) -> #NAME?
AR20: FY Ending | AS20: {=EOMONTH(val_currentFYE,-12)} -> #NAME? | AU20: {=val_currentFYE} -> #NAME?
AR21: FY Starting | AS21: =EOMONTH(AS20,-12)+1 -> #NAME? | AU21: =EOMONTH(AU20,-12)+1 -> #NAME?
AQ32: ="AS OF "&UPPER(TEXT(val_asOfDate,"mmm-yy"))&" ("&val_reportingCurrency&" M)" -> #NAME?
AQ33: Branch | AR33: Metric | AS33: =PL!$CE$12 -> #NAME? | AT33: =PL!CN12 -> #NAME? | AU33: =PL!CQ12 -> #NAME?
AQ34: NO | AR34: Top Line | AT34: {=_xlfn.LET(_xlpm.Res,IFBLANK(PL!$CN$148,PL!$CM$148),IF(_xlpm.Res="","-",_xlpm.Res*fxVal_normal/1000000))} -> 1 | AU34: {=_xlfn.LET(_xlpm.Res,IFBLANK(PL!$CQ$148,PL!$CP$148),IF(_xlpm.Res="","-",_xlpm.Res*fxVal_normal/1000000))} -> 1
AQ35: NO | AR35: Earning | AT35: {=_xlfn.LET(_xlpm.Res,IFBLANK(PL!$CN$162,PL!$CM$162),IF(_xlpm.Res="","-",_xlpm.Res*fxVal_normal/1000000))} -> 1 | AU35: {=_xlfn.LET(_xlpm.Res,IFBLANK(PL!$CQ$162,PL!$CP$162),IF(_xlpm.Res="","-",_xlpm.Res*fxVal_normal/1000000))} -> 1
AQ36: NO | AR36: Valuation | AT36: {=_xlfn.LET(_xlpm.Res,IFBLANK(PL!$CN$176,PL!$CM$176),IF(_xlpm.Res="","-",_xlpm.Res*fxVal_normal/1000000))} -> 1 | AU36: {=_xlfn.LET(_xlpm.Res,IFBLANK(PL!$CQ$176,PL!$CP$176),IF(_xlpm.Res="","-",_xlpm.Res*fxVal_normal/1000000))} -> 1
AQ37: YES | AR37: Top Line | AS37: {=IF(OR(_xlfn.VSTACK(PL!$CE$154,PL!$CE$147)=""),"-",IFERROR((PL!$CE$154-PL!$CE$147)*fxVal_normal/1000000,"-"))} -> #NAME? | AT37: {=_xlfn.LET(_xlpm.Res,IFBLANK(PL!$CN$149,PL!$CM$149),IF(_xlpm.Res="","-",_xlpm.Res*fxVal_normal/1000000))} -> 1 | AU37: {=_xlfn.LET(_xlpm.Res,IFBLANK(PL!$CQ$149,PL!$CP$149),IF(_xlpm.Res="","-",_xlpm.Res*fxVal_normal/1000000))} -> 1
AQ38: YES | AR38: Earning | AS38: {=IF(OR(_xlfn.VSTACK(PL!$CE$168,PL!$CE$161)=""),"-",IFERROR((PL!$CE$168-PL!$CE$161)*fxVal_normal/1000000,"-"))} -> #NAME? | AT38: {=_xlfn.LET(_xlpm.Res,IFBLANK(PL!$CN$163,PL!$CM$163),IF(_xlpm.Res="","-",_xlpm.Res*fxVal_normal/1000000))} -> 1 | AU38: {=_xlfn.LET(_xlpm.Res,IFBLANK(PL!$CQ$163,PL!$CP$163),IF(_xlpm.Res="","-",_xlpm.Res*fxVal_normal/1000000))} -> 1
AQ39: YES | AR39: Valuation | AS39: {=IF(OR(_xlfn.VSTACK(PL!$CE$182,PL!$CE$175)=""),"-",(PL!$CE$182-PL!$CE$175)*fxVal_normal/1000000)} -> #NAME? | AT39: {=_xlfn.LET(_xlpm.Res,IFBLANK(PL!$CN$177,PL!$CM$177),IF(_xlpm.Res="","-",_xlpm.Res*fxVal_normal/1000000))} -> 1 | AU39: {=_xlfn.LET(_xlpm.Res,IFBLANK(PL!$CQ$177,PL!$CP$177),IF(_xlpm.Res="","-",_xlpm.Res*fxVal_normal/1000000))} -> 1
F52: Example 1: Deal closed in May 2025, not reflected in the FY2025 Budget.
F89: Example 2: Portfolio company budgeting a perimeter change for an add-on expected to happen during the year, not yet closed.

Sheet PL
A1: unprotected | B1: 2025-12-23T03:33:24.755Z
N3: USER GUIDE
O4: {=IF(LEFT($A$1,3)="unp",icon_unlock,icon_lock)} -> #VALUE! | S4: #VALUE! | Y4: =_xlfn.IMAGE(INDEX(PM_Support[COMPANY_LOGO_URL],MATCH(val_company,PM_Support[COMPANY_NAME],0))) -> #VALUE!
S5: Worksheet Completion Guidance | Y5: Profit and Loss (OpCo) | AE5: =CX_ENTITY -> W06f9Irq7 | AG5: As of Date | AJ5: Fiscal Year End | AK5: Current FYE | AL5: Unit | AM5: Currency | DD5: =HYPERLINK(DD6,"Check CX") -> Check CX
S6: Hide grouping to minimise | AE6: =_PL!AE6 -> Therme Horizon | AG6: 46022 | AJ6: =_PL!AJ6 -> #NAME? | AK6: {=val_currentFYE} -> #NAME? | AL6: Millions | AM6: =val_reportingCurrency -> #NAME? | DD6: ="https://cvc.chronograph.pe/company-show/"&CX_ENTITY&"/analytics" -> https://cvc.chronograph.pe/company-show/W06f9Irq7/analytics
AK7: 46022 | CD7: Annual Summary | CM7: Forward Looking Data Collection
E9: Date | F9: Push | Y9: =IF(SUBTOTAL(103,W16:W124)=2,"Reported Actual & Budget","") | CJ9: {=DATEDIFF(PL!CJ$11,val_asOfDate,"M")} -> 1 | CK9: {=DATEDIFF(PL!CK$11,val_asOfDate,"M")} -> 0
B10: Developer Console | C10: Template Version Push | E10: =val_asOfDate -> 46022 | F10: {=_xldudf_CX_PUSH(pqToday,CX_ENTITY,"Flash Latest Version Date",val_asOfDate,"As of",W20)} -> #NAME? | H10: Colour | I10: Format | J10: Unpivot | K10: Push? | CD10: Full Financial Year | CG10: Financial Year To Date | CJ10: Last 12 Months | CM10: Current FY | CP10: Next FY
B11: PUSH NOTICE | C11: Flash Task Date Push | E11: =EOMONTH(val_asOfDate,1) -> 46053 | F11: {=_xldudf_CX_PUSH(pqToday,CX_ENTITY,"Flash Task Date",EOMONTH(val_asOfDate,1),"As of",W20)} -> #NAME? | X11: =IF(SUBTOTAL(103,$W$12:$W$14)>0,"Assistance","Summary") -> Assistance | Z11: =IF(SUBTOTAL(103,$W$12:$W$14)>0,"Completion","Requirement") -> Completion | AB11: Financial Period Ending | AD11: {=array_timeline} -> 44926 | AE11: 44957 | AF11: 44985 | AG11: 45016 | AH11: 45046 | AI11: 45077 | AJ11: 45107 | AK11: 45138 | AL11: 45169 | AM11: 45199 | AN11: 45230 | AO11: 45260 | AP11: 45291 | AQ11: 45322 | AR11: 45351 | AS11: 45382 | AT11: 45412 | AU11: 45443 | AV11: 45473 | AW11: 45504 | AX11: 45535 | AY11: 45565 | AZ11: 45596 | BA11: 45626 | BB11: 45657 | BC11: 45688 | BD11: 45716 | BE11: 45747 | BF11: 45777 | BG11: 45808 | BH11: 45838 | BI11: 45869 | BJ11: 45900 | BK11: 45930 | BL11: 45961 | BM11: 45991 | BN11: 46022 | CD11: {=EOMONTH(val_currentFYE,-24)} -> #NAME? | CE11: {=EOMONTH(val_currentFYE,-12)} -> #NAME? | CG11: =EOMONTH(val_asOfDate,-1) -> 45991 | CH11: =EOMONTH(val_asOfDate,0) -> 46022 | CJ11: =EOMONTH(val_asOfDate,-1) -> 45991 | CK11: =EOMONTH(val_asOfDate,0) -> 46022 | CM11: {=val_currentFYE} -> #NAME? | CN11: {=val_currentFYE} -> #NAME? | CP11: {=EOMONTH(val_currentFYE,12)} -> #NAME? | CQ11: {=EOMONTH(val_currentFYE,12)} -> #NAME?
B12: As part of process, the push operation should push Field values to CX against the folloiwng parameters Task month (as of date) and the month following. | S12: Input (White shading, black font) | T12: Refer to the definitions in columns X–Y for all mandatory fields. | W12: Dropdown | X12: {=fx_getIcon("select")} -> #VALUE! | Y12: Required | Z12: {=_xlfn.SWITCH(TRUE,_BS!$L31=TRUE,1,_BS!$L31=FALSE,-1,_BS!$L31=-1,0,"")} -> 1 | AB12: Financial Period | AD12: =EOMONTH(AD11,12-MONTH(val_currentFYE)) -> #NAME? | AE12: {=EOMONTH(AE11,12-MONTH(val_currentFYE))} -> #NAME? | AF12: {=EOMONTH(AF11,12-MONTH(val_currentFYE))} -> #NAME? | AG12: {=EOMONTH(AG11,12-MONTH(val_currentFYE))} -> #NAME? | AH12: {=EOMONTH(AH11,12-MONTH(val_currentFYE))} -> #NAME? | AI12: {=EOMONTH(AI11,12-MONTH(val_currentFYE))} -> #NAME? | AJ12: {=EOMONTH(AJ11,12-MONTH(val_currentFYE))} -> #NAME? | AK12: {=EOMONTH(AK11,12-MONTH(val_currentFYE))} -> #NAME? | AL12: {=EOMONTH(AL11,12-MONTH(val_currentFYE))} -> #NAME? | ... BN12: {=EOMONTH(BN11,12-MONTH(val_currentFYE))} -> #NAME? | CD12: {=YEAR(val_currentFYE)-2} -> #NAME? | CE12: {=YEAR(val_currentFYE)-1} -> #NAME? | CG12: =YEAR(EOMONTH(CG$11,12-MONTH(val_currentFYE))) -> #NAME? | CH12: =YEAR(EOMONTH(CH$11,12-MONTH(val_currentFYE))) -> #NAME? | CJ12: LTM | CK12: LTM | CM12: {=YEAR(val_currentFYE)} -> #NAME? | CN12: {=YEAR(val_currentFYE)} -> #NAME? | CP12: {=YEAR(val_currentFYE)+1} -> #NAME? | CQ12: {=YEAR(val_currentFYE)+1} -> #NAME?
B13: As | H13: 2-blue | I13: 1 num | J13: 1 Req, 0 Opt, -1 Auto | S13: Formula (Off-blue shading, blue font) | T13: Summary type of formula | W13: Sign | X13: a | Y13: Optional | Z13: -1 | AB13: Months prior | AD13: {=_xlfn.SEQUENCE(1,37,-36,1)} -> -36 | AE13: -35 | AF13: -34 | AG13: -33 | AH13: -32 | AI13: -31 | AJ13: -30 | AK13: -29 | AL13: -28 | AM13: -27 | AN13: -26 | AO13: -25 | AP13: -24 | AQ13: -23 | AR13: -22 | AS13: -21 | AT13: -20 | AU13: -19 | AV13: -18 | AW13: -17 | AX13: -16 | AY13: -15 | AZ13: -14 | BA13: -13 | BB13: -12 | BC13: -11 | BD13: -10 | BE13: -9 | BF13: -8 | BG13: -7 | BH13: -6 | BI13: -5 | BJ13: -4 | BK13: -3 | BL13: -2 | BM13: -1 | BN13: 0
A14: FALSE | B14: Show Unprotected Cell | D14: Modify with caution! | I14: 2 pct | J14: Blank - not upload | S14: Formula (Grey shading, black font) | T14: Prefilled formula | W14: Total/Ref | X14: 0 | Y14: Calculated | Z14: 0 | AB14: Period Type | AD14: Month | AE14: =$AD$14 -> Month | AF14: =$AD$14 -> Month | AG14: =$AD$14 -> Month | AH14: =$AD$14 -> Month | AI14: =$AD$14 -> Month | AJ14: =$AD$14 -> Month | AK14: =$AD$14 -> Month | AL14: =$AD$14 -> Month | ... BN14: =$AD$14 -> Month | CD14: FY | CE14: FY | CG14: FYTD | CH14: FYTD | CJ14: LTM | CK14: LTM | CM14: LTM | CN14: LTM | CP14: LTM | CQ14: LTM
D15: Column below used for filtering dropdown in segments | I15: 3 date | S15: {=fx_getIcon("find")} -> #VALUE! | T15: (Icon Only) Suggesting Definition for the term is available | AB15: Conditional formatting | AD15: {=IF(MONTH(AD11)=MONTH(val_currentFYE),1,IF(MOD(MONTH(AD$11)-MONTH(val_currentFYE),3)=0,2,0))} -> #NAME? | AE15: {=IF(MONTH(AE11)=MONTH(val_currentFYE),1,IF(MOD(MONTH(AE$11)-MONTH(val_currentFYE),3)=0,2,0))} -> #NAME? | AF15: {=IF(MONTH(AF11)=MONTH(val_currentFYE),1,IF(MOD(MONTH(AF$11)-MONTH(val_currentFYE),3)=0,2,0))} -> #NAME? | AG15: {=IF(MONTH(AG11)=MONTH(val_currentFYE),1,IF(MOD(MONTH(AG$11)-MONTH(val_currentFYE),3)=0,2,0))} -> #NAME? | AH15: {=IF(MONTH(AH11)=MONTH(val_currentFYE),1,IF(MOD(MONTH(AH$11)-MONTH(val_currentFYE),3)=0,2,0))} -> #NAME? | AI15: {=IF(MONTH(AI11)=MONTH(val_currentFYE),1,IF(MOD(MONTH(AI$11)-MONTH(val_currentFYE),3)=0,2,0))} -> #NAME? | AJ15: {=IF(MONTH(AJ11)=MONTH(val_currentFYE),1,IF(MOD(MONTH(AJ$11)-MONTH(val_currentFYE),3)=0,2,0))} -> #NAME? | AK15: {=IF(MONTH(AK11)=MONTH(val_currentFYE),1,IF(MOD(MONTH(AK$11)-MONTH(val_currentFYE),3)=0,2,0))} -> #NAME? | ... BN15: {=IF(MONTH(BN11)=MONTH(val_currentFYE),1,IF(MOD(MONTH(BN$11)-MONTH(val_currentFYE),3)=0,2,0))} -> #NAME?
W17: =_PL!W17 -> Actual | Y17: Monthly P&L | Z17: [Required] | AB17: Completion Indicator | AD17: {=fx_checkComp(AD20:AD41)} -> 100 | AE17: {=fx_checkComp(AE20:AE41)} -> 100 | AF17: {=fx_checkComp(AF20:AF41)} -> 100 | AG17: {=fx_checkComp(AG20:AG41)} -> 100 | AH17: {=fx_checkComp(AH20:AH41)} -> 100 | AI17: {=fx_checkComp(AI20:AI41)} -> 100 | AJ17: {=fx_checkComp(AJ20:AJ41)} -> 100 | AK17: {=fx_checkComp(AK20:AK41)} -> 100 | ... BN17: {=fx_checkComp(BN20:BN41)} -> 100 | CM17: {=fx_checkComp(CM20:CM41)} -> 100 | CN17: {=fx_checkComp(CN20:CN41)} -> 100 | CP17: {=fx_checkComp(CP20:CP41)} -> 100 | CQ17: {=fx_checkComp(CQ20:CQ41)} -> 100
AB18: Type: Completed / Total | AD18: O: 6 / 6 | AE18: O: 6 / 6 | AF18: O: 6 / 6 | AG18: O: 6 / 6 | AH18: O: 6 / 6 | AI18: O: 6 / 6 | AJ18: O: 6 / 6 | AK18: O: 6 / 6 | AL18: O: 6 / 6 | AM18: O: 6 / 6 | AN18: O: 6 / 6 | AO18: O: 6 / 6 | AP18: O: 6 / 6 | AQ18: O: 6 / 6 | AR18: O: 6 / 6 | AS18: O: 6 / 6 | AT18: O: 6 / 6 | AU18: O: 6 / 6 | AV18: O: 6 / 6 | AW18: O: 6 / 6 | AX18: O: 6 / 6 | AY18: O: 6 / 6 | AZ18: O: 6 / 6 | BA18: O: 6 / 6 | BB18: O: 6 / 6 | BC18: O: 6 / 6 | BD18: O: 6 / 6 | BE18: O: 6 / 6 | BF18: O: 6 / 6 | BG18: O: 6 / 6 | BH18: O: 6 / 6 | BI18: O: 6 / 6 | BJ18: O: 6 / 6 | BK18: O: 6 / 6 | BL18: O: 6 / 6 | BM18: O: 6 / 6 | BN18: O: 6 / 6 | CM18: O: 6 / 6 | CN18: O: 6 / 6 | CP18: O: 6 / 6 | CQ18: O: 6 / 6
B19: Metric Attribute | C19: Field Attribute | D19: Utility Column (Prefilled Text) - Please ignore | E19: TOTAL | F19: NOT BLANK | G19: TYPE | H19: BgFill | I19: Fmt | J19: Required | K19: To Push | W19: Scenario | X19: =_PL!X19 -> a | Y19: =val_company&" P&L Accounts" -> Therme Horizon P&L Accounts | AB19: CVC Standard P&L A/C | AD19: =$W$17 -> Actual | AE19: =$W$17 -> Actual | AF19: =$W$17 -> Actual | AG19: =$W$17 -> Actual | AH19: =$W$17 -> Actual | AI19: =$W$17 -> Actual | AJ19: =$W$17 -> Actual | AK19: =$W$17 -> Actual | ... BN19: =$W$17 -> Actual | CD19: =$W$17 -> Actual | CE19: =$W$17 -> Actual | CG19: {=fx_scenarioConverter($W17)} -> Actual | CH19: {=fx_scenarioConverter($W17)} -> Actual | CJ19: {=fx_scenarioConverter($W17)} -> Actual | CK19: {=fx_scenarioConverter($W17)} -> Actual | CM19: {=fx_scenarioConverter("Original Budget")} -> Original Budget | CN19: {=fx_scenarioConverter("LE")} -> LE | CP19: {=fx_scenarioConverter("Original Budget")} -> Original Budget | CQ19: {=fx_scenarioConverter("LE")} -> LE | CT19: {=RIGHT(CELL("filename",A1),LEN(CELL("filename",A1))-FIND("]",CELL("filename",A1)))&" "&"Label PUSH"&TEXT(val_asOfDate," MMm-YY")} -> PL Label PUSH Dec-25 | CU19: {=RIGHT(CELL("filename",A1),LEN(CELL("filename",A1))-FIND("]",CELL("filename",A1)))&" "&"Label PUSH"&TEXT(EOMONTH(val_asOfDate,1)," MMMM-YY")} -> PL Label PUSH January-26 | CV19: {=RIGHT(CELL("filename",B1),LEN(CELL("filename",B1))-FIND("]",CELL("filename",B1)))&" "&"Label PUSH"&TEXT(EOMONTH(val_asOfDate,2)," MMMM-YY")} -> PL Label PUSH February-26 | CW19: {=RIGHT(CELL("filename",B1),LEN(CELL("filename",B1))-FIND("]",CELL("filename",B1)))&" "&"Label PUSH"&TEXT(EOMONTH(val_asOfDate,2)," MMMM-YY")} -> PL Label PUSH February-26 | CY19: {=RIGHT(CELL("filename",A1),LEN(CELL("filename",A1))-FIND("]",CELL("filename",A1)))&" "&$CM$10&" PUSH"} -> PL Current FY PUSH | CZ19: {=RIGHT(CELL("filename",A1),LEN(CELL("filename",A1))-FIND("]",CELL("filename",A1)))&" "&$CM$10&" PUSH"} -> PL Current FY PUSH | DA19: {=RIGHT(CELL("filename",C1),LEN(CELL("filename",C1))-FIND("]",CELL("filename",C1)))&" "&$CP$10&" PUSH"} -> PL Next FY PUSH | DB19: {=RIGHT(CELL("filename",C1),LEN(CELL("filename",C1))-FIND("]",CELL("filename",C1)))&" "&$CP$10&" PUSH"} -> PL Next FY PUSH | DD19: {=RIGHT(CELL("filename",$A$1),LEN(CELL("filename",$A$1))-FIND("]",CELL("filename",$A$1)))&" PUSH"} -> PL PUSH | DE19: {=RIGHT(CELL("filename",$A$1),LEN(CELL("filename",$A$1))-FIND("]",CELL("filename",$A$1)))&" PUSH"} -> PL PUSH | DF19: {=RIGHT(CELL("filename",$A$1),LEN(CELL("filename",$A$1))-FIND("]",CELL("filename",$A$1)))&" PUSH"} -> PL PUSH | DG19: {=RIGHT(CELL("filename",$A$1),LEN(CELL("filename",$A$1))-FIND("]",CELL("filename",$A$1)))&" PUSH"} -> PL PUSH | DH19: {=RIGHT(CELL("filename",$A$1),LEN(CELL("filename",$A$1))-FIND("]",CELL("filename",$A$1)))&" PUSH"} -> PL PUSH | DI19: {=RIGHT(CELL("filename",$A$1),LEN(CELL("filename",$A$1))-FIND("]",CELL("filename",$A$1)))&" PUSH"} -> PL PUSH | DJ19: {=RIGHT(CELL("filename",$A$1),LEN(CELL("filename",$A$1))-FIND("]",CELL("filename",$A$1)))&" PUSH"} -> PL PUSH | DK19: {=RIGHT(CELL("filename",$A$1),LEN(CELL("filename",$A$1))-FIND("]",CELL("filename",$A$1)))&" PUSH"} -> PL PUSH | ... EN19: {=RIGHT(CELL("filename",$A$1),LEN(CELL("filename",$A$1))-FIND("]",CELL("filename",$A$1)))&" PUSH"} -> PL PUSH
A20: F | B20: =_xlfn.LET(_xlpm.IsNotAttrDynamic,D20="",_xlpm.Attr,_PL!F20,_xlpm.NotInUse,Y20=D20,_xlpm.RESULT,IF(_xlpm.IsNotAttrDynamic,_xlpm.Attr,IF(_xlpm.NotInUse,"",Y20)),IF(_xlpm.RESULT="","",_xlpm.RESULT)) -> Net Revenue | C20: {=IFBLANK(_PL!C20,"")} -> Net Revenue (Company View) | E20: {=_xlfn.LAMBDA(_xlpm.Array,_xlop.Type,_xlfn.LET(_xlpm._type,IF(_xlfn.ISOMITTED(_xlpm.Type),0,_xlpm.Type),_xlpm.R,ROWS(_xlpm.Array),_xlpm.C,COLUMNS(_xlpm.Array),_xlpm.Unlocked,_xlfn.MAKEARRAY(_xlpm.R,_xlpm.C,_xlfn.LAMBDA(_xlpm.i,_xlpm.j,--(CELL("protect",INDEX(_xlpm.Array,_xlpm.i,_xlpm.j))=0))),_xlpm.IsUnlocked,_xlfn.MAKEARRAY(_xlpm.R,_xlpm.C,_xlfn.LAMBDA(_xlpm.i,_xlpm.j,CELL("protect",INDEX(_xlpm.Array,_xlpm.i,_xlpm.j))=0)),_xlpm.HasData,_xlpm.Array<>"",_xlpm.Total,SUM(_xlpm.Unlocked),_xlpm.Completed,SUM(--(_xlpm.IsUnlocked*_xlpm.HasData)),_xlpm.type_display,_xlfn.SWITCH(_xlpm._type,1,"R",-1,"O",0,"A",""),_xlfn.HSTACK(_xlpm.Total,_xlpm.Completed,_xlpm.type_display)))($AD20:$CQ20,Z20)} -> #NAME? | H20: 0 | I20: 1 | J20: =IF(OR(ISNUMBER(SEARCH("required",Z20)),ISNUMBER(SEARCH("optional",Z20))),"",Z20) -> 1 | K20: =IFERROR(IF(LEN(AB20)=0,"No",IF(LEN(J20)>0,"Yes","No")),"") -> Yes | W20: {=fx_scenarioConverter($W$17)} -> Actual | X20: =_PL!X20 -> 1 | Y20: 2 | Z20: {=_xlfn.SWITCH(TRUE,_PL!$L20=TRUE,1,_PL!$L20=FALSE,-1,_PL!$L20=-1,0,"")} -> 1 | AB20: =_PL!AB20 -> Net Revenue | AC20: {=_xlfn.LET(_xlpm._termname,$AB20,_xlpm._iconname,"find",_xlpm._icon,fx_getIcon(_xlpm._iconname),_xlpm._location,_xlfn.XLOOKUP(LOWER(_xlpm._termname),LOWER(tbl_acctDef[Term]),tbl_acctDef[Term]),_xlpm._hyperlink,HYPERLINK("#"&CELL("address",_xlpm._location),_xlpm._icon),IFERROR(_xlpm._hyperlink,""))} -> #VALUE! | AD20: 1 | AE20: 1 | AF20: 1 | AG20: 1 | AH20: 1 | AI20: 1 | AJ20: 1 | AK20: 1 | AL20: 1 | AM20: 1 | AN20: 1 | AO20: 1 | AP20: 1 | AQ20: 1 | AR20: 1 | AS20: 1 | AT20: 1 | AU20: 1 | AV20: 1 | AW20: 1 | AX20: 1 | AY20: 1 | AZ20: 1 | BA20: 1 | BB20: 1 | BC20: 1 | BD20: 1 | BE20: 1 | BF20: 1 | BG20: 1 | BH20: 1 | BI20: 1 | BJ20: 1 | BK20: 1 | BL20: 1 | BM20: 1 | BN20: 1 | CD20: {=_xlfn.LET(_xlpm.CheckBlank,SUM(PL!$AD20:$BN20)=0,IF(_xlpm.CheckBlank,"",SUM(_xlfn._xlws.FILTER(PL!$AD20:$BN20,(YEAR(PL!$AD$12:$BN$12)=PL!CD$12)*(array_timeline<=PL!CD$11)))))} -> #NAME? | CE20: {=_xlfn.LET(_xlpm.CheckBlank,SUM(PL!$AD20:$BN20)=0,IF(_xlpm.CheckBlank,"",SUM(_xlfn._xlws.FILTER(PL!$AD20:$BN20,(YEAR(PL!$AD$12:$BN$12)=PL!CE$12)*(array_timeline<=PL!CE$11)))))} -> #NAME? | CG20: {=IFERROR(_xlfn.LET(_xlpm.CheckBlank,SUM(PL!$AD20:$BN20)=0,IF(_xlpm.CheckBlank,"",SUM(_xlfn._xlws.FILTER(PL!$AD20:$BN20,(YEAR(PL!$AD$12:$BN$12)=PL!CG$12)*(array_timeline<=PL!CG$11))))),"n/a")} -> n/a | CH20: {=_xlfn.LET(_xlpm.CheckBlank,SUM(PL!$AD20:$BN20)=0,IF(_xlpm.CheckBlank,"",SUM(_xlfn._xlws.FILTER(PL!$AD20:$BN20,(YEAR(PL!$AD$12:$BN$12)=PL!CH$12)*(array_timeline<=PL!CH$11)))))} -> #NAME? | CJ20: {=_xlfn.LET(_xlpm.CheckBlank,SUM(PL!$AD20:$BN20)=0,IF(_xlpm.CheckBlank,"",SUM(_xlfn.TAKE(_xlfn.DROP(PL!$AD20:$BN20,,-DATEDIFF(PL!CJ$11,val_asOfDate,"M")),1,-12))))} -> 12 | CK20: {=_xlfn.LET(_xlpm.CheckBlank,SUM(PL!$AD20:$BN20)=0,IF(_xlpm.CheckBlank,"",SUM(_xlfn.TAKE(_xlfn.DROP(PL!$AD20:$BN20,,-DATEDIFF(PL!CK$11,val_asOfDate,"M")),1,-12))))} -> 12 | CM20: 1 | CN20: 1 | CP20: 1 | CQ20: 1 | CT20: {=IF(K20<>"Yes","",IF(OR(Y20="Select, enter text or leave as blank.",Y20="Set from Actual section above!",Y20="Please select or type in or leave as blank",Y20="Select, enter text or leave as blank",Y20="Please select your Top Line Metric",Y20="Check Sum",Y20="Please name your Like-for-Like Revenue",Y20="Please name your Like-for-like Earning Metric",Y20="Valuation Metric",Y20="Please name your Like-for-like Valuation Metric",Y20="Please select your Valuation Metric",Y20="Please select the metric for segmentation",Y20="Untitled Segmentation II",Y20="Untitled Segmentation III"),"",IF(OR(Y20<>AB20,AND(LEN(B20)=0,NOT(OR(Y20="Select, enter text or leave as blank.",Y20="Set from Actual section above!",Y20="Please select or type in or leave as blank",Y20="Select, enter text or leave as blank",Y20="Please select your Top Line Metric",Y20="Check Sum",Y20="Please name your Like-for-Like Revenue",Y20="Please name your Like-for-like Earning Metric",Y20="Valuation Metric",Y20="Please name your Like-for-like Valuation Metric",Y20="Please select your Valuation Metric",Y20="Please select the metric for segmentation",Y20="Untitled Segmentation II",Y20="Untitled Segmentation III")))),_xldudf_CX_PUSH(Y20,CX_ENTITY,C20,EOMONTH(val_asOfDate,0)),"")))} -> #NAME? | CU20: {=IF(K20<>"Yes","",IF(OR(Y20="Select, enter text or leave as blank.",Y20="Set from Actual section above!",Y20="Please select or type in or leave as blank",Y20="Select, enter text or leave as blank",Y20="Please select your Top Line Metric",Y20="Check Sum",Y20="Please name your Like-for-Like Revenue",Y20="Please name your Like-for-like Earning Metric",Y20="Valuation Metric",Y20="Please name your Like-for-like Valuation Metric",Y20="Please select your Valuation Metric",Y20="Please select the metric for segmentation",Y20="Untitled Segmentation II",Y20="Untitled Segmentation III"),"",IF(OR(Y20<>AB20,AND(LEN(B20)=0,NOT(OR(Y20="Select, enter text or leave as blank.",Y20="Set from Actual section above!",Y20="Please select or type in or leave as blank",Y20="Select, enter text or leave as blank",Y20="Please select your Top Line Metric",Y20="Check Sum",Y20="Please name your Like-for-Like Revenue",Y20="Please name your Like-for-like Earning Metric",Y20="Valuation Metric",Y20="Please name your Like-for-like Valuation Metric",Y20="Please select your Valuation Metric",Y20="Please select the metric for segmentation",Y20="Untitled Segmentation II",Y20="Untitled Segmentation III")))),_xldudf_CX_PUSH(Y20,CX_ENTITY,C20,EOMONTH(val_asOfDate,1)),"")))} -> #NAME? | CV20: {=IF(K20<>"Yes","",IF(OR(Y20="Select, enter text or leave as blank.",Y20="Set from Actual section above!",Y20="Please select or type in or leave as blank",Y20="Select, enter text or leave as blank",Y20="Please select your Top Line Metric",Y20="Check Sum",Y20="Please name your Like-for-Like Revenue",Y20="Please name your Like-for-like Earning Metric",Y20="Valuation Metric",Y20="Please name your Like-for-like Valuation Metric",Y20="Please select your Valuation Metric",Y20="Please select the metric for segmentation",Y20="Untitled Segmentation II",Y20="Untitled Segmentation III"),"",IF(OR(Y20<>AB20,AND(LEN(B20)=0,NOT(OR(Y20="Select, enter text or leave as blank.",Y20="Set from Actual section above!",Y20="Please select or type in or leave as blank",Y20="Select, enter text or leave as blank",Y20="Please select your Top Line Metric",Y20="Check Sum",Y20="Please name your Like-for-Like Revenue",Y20="Please name your Like-for-like Earning Metric",Y20="Valuation Metric",Y20="Please name your Like-for-like Valuation Metric",Y20="Please select your Valuation Metric",Y20="Please select the metric for segmentation",Y20="Untitled Segmentation II",Y20="Untitled Segmentation III")))),_xldudf_CX_PUSH(Y20,CX_ENTITY,C20,EOMONTH(val_asOfDate,2)),"")))} -> #NAME? | CW20: {=IF(K20<>"Yes","",IF(OR(Y20="Select, enter text or leave as blank.",Y20="Set from Actual section above!",Y20="Please select or type in or leave as blank",Y20="Select, enter text or leave as blank",Y20="Please select your Top Line Metric",Y20="Check Sum",Y20="Please name your Like-for-Like Revenue",Y20="Please name your Like-for-like Earning Metric",Y20="Valuation Metric",Y20="Please name your Like-for-like Valuation Metric",Y20="Please select your Valuation Metric",Y20="Please select the metric for segmentation",Y20="Untitled Segmentation II",Y20="Untitled Segmentation III"),"",IF(OR(Y20<>AB20,AND(LEN(B20)=0,NOT(OR(Y20="Select, enter text or leave as blank.",Y20="Set from Actual section above!",Y20="Please select or type in or leave as blank",Y20="Select, enter text or leave as blank",Y20="Please select your Top Line Metric",Y20="Check Sum",Y20="Please name your Like-for-Like Revenue",Y20="Please name your Like-for-like Earning Metric",Y20="Valuation Metric",Y20="Please name your Like-for-like Valuation Metric",Y20="Please select your Valuation Metric",Y20="Please select the metric for segmentation",Y20="Untitled Segmentation II",Y20="Untitled Segmentation III")))),_xldudf_CX_PUSH(Y20,CX_ENTITY,C20,EOMONTH(val_asOfDate,3)),"")))} -> #NAME? | CY20: {=IFERROR(IF(CM20*fxVal_normal=_PL!CM20,"",IF(OR($CM20="",$CM20=0,NOT(ISNUMBER($CM20)),ISERROR($CM20),$B20=""),"",IF($I20=1,IFBLANK(_xldudf_CX_PUSH($CM20*fxVal_normal,CX_ENTITY,$B20,$CM$11,$CM$14,$CM$19,),""),IF($I20=2,IFBLANK(_xldudf_CX_PUSH($CM20,CX_ENTITY,$B20,$CM$11,$CM$14,$CM$19,),""),IF($I20=3,"",IFBLANK(_xldudf_CX_PUSH($CM20,CX_ENTITY,$B20,$CM$11,$CM$14,$CM$19,),"")))))),"")} | CZ20: {=IFERROR(IF(CN20*fxVal_normal=_PL!CN20,"",IF(OR($CN20="",$CN20=0,NOT(ISNUMBER($CN20)),ISERROR($CN20),$B20=""),"",IF($I20=1,IFBLANK(_xldudf_CX_PUSH($CN20*fxVal_normal,CX_ENTITY,$B20,$CN$11,$CN$14,$CN$19,),""),IF($I20=2,IFBLANK(_xldudf_CX_PUSH($CN20,CX_ENTITY,$B20,$CN$11,$CN$14,$CN$19,),""),IF($I20=3,"",IFBLANK(_xldudf_CX_PUSH($CN20,CX_ENTITY,$B20,$CN$11,$CN$14,$CN$19,),"")))))),"")} | DA20: {=IFERROR(IF(CP20*fxVal_normal=_PL!CP20,"",IF(OR($CP20="",$CP20=0,NOT(ISNUMBER($CP20)),ISERROR($CP20),$B20=""),"",IF($I20=1,IFBLANK(_xldudf_CX_PUSH($CP20*fxVal_normal,CX_ENTITY,$B20,$CP$11,$CP$14,$CP$19,),""),IF($I20=2,IFBLANK(_xldudf_CX_PUSH($CP20,CX_ENTITY,$B20,$CP$11,$CP$14,$CP$19,),""),IF($I20=3,"",IFBLANK(_xldudf_CX_PUSH($CP20,CX_ENTITY,$B20,$CP$11,$CP$14,$CP$19,),"")))))),"")} | DB20: {=IFERROR(IF(CQ20*fxVal_normal=_PL!CQ20,"",IF(OR($CQ20="",$CQ20=0,NOT(ISNUMBER($CQ20)),ISERROR($CQ20),$B20=""),"",IF($I20=1,IFBLANK(_xldudf_CX_PUSH($CQ20*fxVal_normal,CX_ENTITY,$B20,$CQ$11,$CQ$14,$CQ$19,),""),IF($I20=2,IFBLANK(_xldudf_CX_PUSH($CQ20,CX_ENTITY,$B20,$CQ$11,$CQ$14,$CQ$19,),""),IF($I20=3,"",IFBLANK(_xldudf_CX_PUSH($CQ20,CX_ENTITY,$B20,$CQ$11,$CQ$14,$CQ$19,),"")))))),"")} | DD20: {=IFERROR(IF(AD20*fxVal_normal=_PL!AD20,"",IF(OR(AD20="",NOT(ISNUMBER(AD20)),ISERROR(AD20),$B20=""),"",IF($I20=1,IFBLANK(_xldudf_CX_PUSH(AD20*fxVal_normal,CX_ENTITY,$B20,AD$11,AD$14,AD$19,),""),IF($I20=2,IFBLANK(_xldudf_CX_PUSH(AD20,CX_ENTITY,$B20,AD$11,AD$14,AD$19,),""),IF($I20=3,"",IFBLANK(_xldudf_CX_PUSH(AD20,CX_ENTITY,$B20,AD$11,AD$14,AD$19,),"")))))),"")} | DE20: {=IFERROR(IF(AE20*fxVal_normal=_PL!AE20,"",IF(OR(AE20="",NOT(ISNUMBER(AE20)),ISERROR(AE20),$B20=""),"",IF($I20=1,IFBLANK(_xldudf_CX_PUSH(AE20*fxVal_normal,CX_ENTITY,$B20,AE$11,AE$14,AE$19,),""),IF($I20=2,IFBLANK(_xldudf_CX_PUSH(AE20,CX_ENTITY,$B20,AE$11,AE$14,AE$19,),""),IF($I20=3,"",IFBLANK(_xldudf_CX_PUSH(AE20,CX_ENTITY,$B20,AE$11,AE$14,AE$19,),"")))))),"")} | DF20: {=IFERROR(IF(AF20*fxVal_normal=_PL!AF20,"",IF(OR(AF20="",NOT(ISNUMBER(AF20)),ISERROR(AF20),$B20=""),"",IF($I20=1,IFBLANK(_xldudf_CX_PUSH(AF20*fxVal_normal,CX_ENTITY,$B20,AF$11,AF$14,AF$19,),""),IF($I20=2,IFBLANK(_xldudf_CX_PUSH(AF20,CX_ENTITY,$B20,AF$11,AF$14,AF$19,),""),IF($I20=3,"",IFBLANK(_xldudf_CX_PUSH(AF20,CX_ENTITY,$B20,AF$11,AF$14,AF$19,),"")))))),"")} | DG20: {=IFERROR(IF(AG20*fxVal_normal=_PL!AG20,"",IF(OR(AG20="",NOT(ISNUMBER(AG20)),ISERROR(AG20),$B20=""),"",IF($I20=1,IFBLANK(_xldudf_CX_PUSH(AG20*fxVal_normal,CX_ENTITY,$B20,AG$11,AG$14,AG$19,),""),IF($I20=2,IFBLANK(_xldudf_CX_PUSH(AG20,CX_ENTITY,$B20,AG$11,AG$14,AG$19,),""),IF($I20=3,"",IFBLANK(_xldudf_CX_PUSH(AG20,CX_ENTITY,$B20,AG$11,AG$14,AG$19,),"")))))),"")} | DH20: {=IFERROR(IF(AH20*fxVal_normal=_PL!AH20,"",IF(OR(AH20="",NOT(ISNUMBER(AH20)),ISERROR(AH20),$B20=""),"",IF($I20=1,IFBLANK(_xldudf_CX_PUSH(AH20*fxVal_normal,CX_ENTITY,$B20,AH$11,AH$14,AH$19,),""),IF($I20=2,IFBLANK(_xldudf_CX_PUSH(AH20,CX_ENTITY,$B20,AH$11,AH$14,AH$19,),""),IF($I20=3,"",IFBLANK(_xldudf_CX_PUSH(AH20,CX_ENTITY,$B20,AH$11,AH$14,AH$19,),"")))))),"")} | DI20: {=IFERROR(IF(AI20*fxVal_normal=_PL!AI20,"",IF(OR(AI20="",NOT(ISNUMBER(AI20)),ISERROR(AI20),$B20=""),"",IF($I20=1,IFBLANK(_xldudf_CX_PUSH(AI20*fxVal_normal,CX_ENTITY,$B20,AI$11,AI$14,AI$19,),""),IF($I20=2,IFBLANK(_xldudf_CX_PUSH(AI20,CX_ENTITY,$B20,AI$11,AI$14,AI$19,),""),IF($I20=3,"",IFBLANK(_xldudf_CX_PUSH(AI20,CX_ENTITY,$B20,AI$11,AI$14,AI$19,),"")))))),"")} | DJ20: {=IFERROR(IF(AJ20*fxVal_normal=_PL!AJ20,"",IF(OR(AJ20="",NOT(ISNUMBER(AJ20)),ISERROR(AJ20),$B20=""),"",IF($I20=1,IFBLANK(_xldudf_CX_PUSH(AJ20*fxVal_normal,CX_ENTITY,$B20,AJ$11,AJ$14,AJ$19,),""),IF($I20=2,IFBLANK(_xldudf_CX_PUSH(AJ20,CX_ENTITY,$B20,AJ$11,AJ$14,AJ$19,),""),IF($I20=3,"",IFBLANK(_xldudf_CX_PUSH(AJ20,CX_ENTITY,$B20,AJ$11,AJ$14,AJ$19,),"")))))),"")} | DK20: {=IFERROR(IF(AK20*fxVal_normal=_PL!AK20,"",IF(OR(AK20="",NOT(ISNUMBER(AK20)),ISERROR(AK20),$B20=""),"",IF($I20=1,IFBLANK(_xldudf_CX_PUSH(AK20*fxVal_normal,CX_ENTITY,$B20,AK$11,AK$14,AK$19,),""),IF($I20=2,IFBLANK(_xldudf_CX_PUSH(AK20,CX_ENTITY,$B20,AK$11,AK$14,AK$19,),""),IF($I20=3,"",IFBLANK(_xldudf_CX_PUSH(AK20,CX_ENTITY,$B20,AK$11,AK$14,AK$19,),"")))))),"")} | ... EN20: {=IFERROR(IF(BN20*fxVal_normal=_PL!BN20,"",IF(OR(BN20="",NOT(ISNUMBER(BN20)),ISERROR(BN20),$B20=""),"",IF($I20=1,IFBLANK(_xldudf_CX_PUSH(BN20*fxVal_normal,CX_ENTITY,$B20,BN$11,BN$14,BN$19,),""),IF($I20=2,IFBLANK(_xldudf_CX_PUSH(BN20,CX_ENTITY,$B20,BN$11,BN$14,BN$19,),""),IF($I20=3,"",IFBLANK(_xldudf_CX_PUSH(BN20,CX_ENTITY,$B20,BN$11,BN$14,BN$19,),"")))))),"")}
B21: =_xlfn.LET(_xlpm.IsNotAttrDynamic,D21="",_xlpm.Attr,_PL!F21,_xlpm.NotInUse,Y21=D21,_xlpm.RESULT,IF(_xlpm.IsNotAttrDynamic,_xlpm.Attr,IF(_xlpm.NotInUse,"",Y21)),IF(_xlpm.RESULT="","",_xlpm.RESULT)) -> Cost of Sales | C21: {=IFBLANK(_PL!C21,"")} -> Cost of Sales (Company View) | E21: {=_xlfn.LAMBDA(_xlpm.Array,_xlop.Type,_xlfn.LET(_xlpm._type,IF(_xlfn.ISOMITTED(_xlpm.Type),0,_xlpm.Type),_xlpm.R,ROWS(_xlpm.Array),_xlpm.C,COLUMNS(_xlpm.Array),_xlpm.Unlocked,_xlfn.MAKEARRAY(_xlpm.R,_xlpm.C,_xlfn.LAMBDA(_xlpm.i,_xlpm.j,--(CELL("protect",INDEX(_xlpm.Array,_xlpm.i,_xlpm.j))=0))),_xlpm.IsUnlocked,_xlfn.MAKEARRAY(_xlpm.R,_xlpm.C,_xlfn.LAMBDA(_xlpm.i,_xlpm.j,CELL("protect",INDEX(_xlpm.Array,_xlpm.i,_xlpm.j))=0)),_xlpm.HasData,_xlpm.Array<>"",_xlpm.Total,SUM(_xlpm.Unlocked),_xlpm.Completed,SUM(--(_xlpm.IsUnlocked*_xlpm.HasData)),_xlpm.type_display,_xlfn.SWITCH(_xlpm._type,1,"R",-1,"O",0,"A",""),_xlfn.HSTACK(_xlpm.Total,_xlpm.Completed,_xlpm.type_display)))($AD21:$CQ21,Z21)} -> #NAME? | H21: 0 | I21: 1 | J21: {=IFBLANK(Z21,"")} -> 1 | K21: =IFERROR(IF(LEN(AB21)=0,"No",IF(LEN(J21)>0,"Yes","No")),"") -> Yes | W21: =$W$20 -> Actual | X21: =_PL!X21 -> -1 | Y21: 2 | Z21: {=_xlfn.SWITCH(TRUE,_PL!$L21=TRUE,1,_PL!$L21=FALSE,-1,_PL!$L21=-1,0,"")} -> 1 | AB21: =_PL!AB21 -> Cost of Sales | AC21: {=_xlfn.LET(_xlpm._termname,$AB21,_xlpm._iconname,"find",_xlpm._icon,fx_getIcon(_xlpm._iconname),_xlpm._location,_xlfn.XLOOKUP(LOWER(_xlpm._termname),LOWER(tbl_acctDef[Term]),tbl_acctDef[Term]),_xlpm._hyperlink,HYPERLINK("#"&CELL("address",_xlpm._location),_xlpm._icon),IFERROR(_xlpm._hyperlink,""))} -> #VALUE! | AD21: 1 | AE21: 1 | AF21: 1 | AG21: 1 | AH21: 1 | AI21: 1 | AJ21: 1 | AK21: 1 | AL21: 1 | AM21: 1 | AN21: 1 | AO21: 1 | AP21: 1 | AQ21: 1 | AR21: 1 | AS21: 1 | AT21: 1 | AU21: 1 | AV21: 1 | AW21: 1 | AX21: 1 | AY21: 1 | AZ21: 1 | BA21: 1 | BB21: 1 | BC21: 1 | BD21: 1 | BE21: 1 | BF21: 1 | BG21: 1 | BH21: 1 | BI21: 1 | BJ21: 1 | BK21: 1 | BL21: 1 | BM21: 1 | BN21: 1 | CD21: {=_xlfn.LET(_xlpm.CheckBlank,SUM(PL!$AD21:$BN21)=0,IF(_xlpm.CheckBlank,"",SUM(_xlfn._xlws.FILTER(PL!$AD21:$BN21,(YEAR(PL!$AD$12:$BN$12)=PL!CD$12)*(array_timeline<=PL!CD$11)))))} -> #NAME? | CE21: {=_xlfn.LET(_xlpm.CheckBlank,SUM(PL!$AD21:$BN21)=0,IF(_xlpm.CheckBlank,"",SUM(_xlfn._xlws.FILTER(PL!$AD21:$BN21,(YEAR(PL!$AD$12:$BN$12)=PL!CE$12)*(array_timeline<=PL!CE$11)))))} -> #NAME? | CG21: {=IFERROR(_xlfn.LET(_xlpm.CheckBlank,SUM(PL!$AD21:$BN21)=0,IF(_xlpm.CheckBlank,"",SUM(_xlfn._xlws.FILTER(PL!$AD21:$BN21,(YEAR(PL!$AD$12:$BN$12)=PL!CG$12)*(array_timeline<=PL!CG$11))))),"n/a")} -> n/a | CH21: {=_xlfn.LET(_xlpm.CheckBlank,SUM(PL!$AD21:$BN21)=0,IF(_xlpm.CheckBlank,"",SUM(_xlfn._xlws.FILTER(PL!$AD21:$BN21,(YEAR(PL!$AD$12:$BN$12)=PL!CH$12)*(array_timeline<=PL!CH$11)))))} -> #NAME? | CJ21: {=_xlfn.LET(_xlpm.CheckBlank,SUM(PL!$AD21:$BN21)=0,IF(_xlpm.CheckBlank,"",SUM(_xlfn.TAKE(_xlfn.DROP(PL!$AD21:$BN21,,-DATEDIFF(PL!CJ$11,val_asOfDate,"M")),1,-12))))} -> 12 | CK21: {=_xlfn.LET(_xlpm.CheckBlank,SUM(PL!$AD21:$BN21)=0,IF(_xlpm.CheckBlank,"",SUM(_xlfn.TAKE(_xlfn.DROP(PL!$AD21:$BN21,,-DATEDIFF(PL!CK$11,val_asOfDate,"M")),1,-12))))} -> 12 | CM21: 1 | CN21: 1 | CP21: 1 | CQ21: 1 | CT21: {=IF(K21<>"Yes","",IF(OR(Y21="Select, enter text or leave as blank.",Y21="Set from Actual section above!",Y21="Please select or type in or leave as blank",Y21="Select, enter text or leave as blank",Y21="Please select your Top Line Metric",Y21="Check Sum",Y21="Please name your Like-for-Like Revenue",Y21="Please name your Like-for-like Earning Metric",Y21="Valuation Metric",Y21="Please name your Like-for-like Valuation Metric",Y21="Please select your Valuation Metric",Y21="Please select the metric for segmentation",Y21="Untitled Segmentation II",Y21="Untitled Segmentation III"),"",IF(OR(Y21<>AB21,AND(LEN(B21)=0,NOT(OR(Y21="Select, enter text or leave as blank.",Y21="Set from Actual section above!",Y21="Please select or type in or leave as blank",Y21="Select, enter text or leave as blank",Y21="Please select your Top Line Metric",Y21="Check Sum",Y21="Please name your Like-for-Like Revenue",Y21="Please name your Like-for-like Earning Metric",Y21="Valuation Metric",Y21="Please name your Like-for-like Valuation Metric",Y21="Please select your Valuation Metric",Y21="Please select the metric for segmentation",Y21="Untitled Segmentation II",Y21="Untitled Segmentation III")))),_xldudf_CX_PUSH(Y21,CX_ENTITY,C21,EOMONTH(val_asOfDate,0)),"")))} -> #NAME? | CU21: {=IF(K21<>"Yes","",IF(OR(Y21="Select, enter text or leave as blank.",Y21="Set from Actual section above!",Y21="Please select or type in or leave as blank",Y21="Select, enter text or leave as blank",Y21="Please select your Top Line Metric",Y21="Check Sum",Y21="Please name your Like-for-Like Revenue",Y21="Please name your Like-for-like Earning Metric",Y21="Valuation Metric",Y21="Please name your Like-for-like Valuation Metric",Y21="Please select your Valuation Metric",Y21="Please select the metric for segmentation",Y21="Untitled Segmentation II",Y21="Untitled Segmentation III"),"",IF(OR(Y21<>AB21,AND(LEN(B21)=0,NOT(OR(Y21="Select, enter text or leave as blank.",Y21="Set from Actual section above!",Y21="Please select or type in or leave as blank",Y21="Select, enter text or leave as blank",Y21="Please select your Top Line Metric",Y21="Check Sum",Y21="Please name your Like-for-Like Revenue",Y21="Please name your Like-for-like Earning Metric",Y21="Valuation Metric",Y21="Please name your Like-for-like Valuation Metric",Y21="Please select your Valuation Metric",Y21="Please select the metric for segmentation",Y21="Untitled Segmentation II",Y21="Untitled Segmentation III")))),_xldudf_CX_PUSH(Y21,CX_ENTITY,C21,EOMONTH(val_asOfDate,1)),"")))} -> #NAME? | CV21: {=IF(K21<>"Yes","",IF(OR(Y21="Select, enter text or leave as blank.",Y21="Set from Actual section above!",Y21="Please select or type in or leave as blank",Y21="Select, enter text or leave as blank",Y21="Please select your Top Line Metric",Y21="Check Sum",Y21="Please name your Like-for-Like Revenue",Y21="Please name your Like-for-like Earning Metric",Y21="Valuation Metric",Y21="Please name your Like-for-like Valuation Metric",Y21="Please select your Valuation Metric",Y21="Please select the metric for segmentation",Y21="Untitled Segmentation II",Y21="Untitled Segmentation III"),"",IF(OR(Y21<>AB21,AND(LEN(B21)=0,NOT(OR(Y21="Select, enter text or leave as blank.",Y21="Set from Actual section above!",Y21="Please select or type in or leave as blank",Y21="Select, enter text or leave as blank",Y21="Please select your Top Line Metric",Y21="Check Sum",Y21="Please name your Like-for-Like Revenue",Y21="Please name your Like-for-like Earning Metric",Y21="Valuation Metric",Y21="Please name your Like-for-like Valuation Metric",Y21="Please select your Valuation Metric",Y21="Please select the metric for segmentation",Y21="Untitled Segmentation II",Y21="Untitled Segmentation III")))),_xldudf_CX_PUSH(Y21,CX_ENTITY,C21,EOMONTH(val_asOfDate,2)),"")))} -> #NAME? | CW21: {=IF(K21<>"Yes","",IF(OR(Y21="Select, enter text or leave as blank.",Y21="Set from Actual section above!",Y21="Please select or type in or leave as blank",Y21="Select, enter text or leave as blank",Y21="Please select your Top Line Metric",Y21="Check Sum",Y21="Please name your Like-for-Like Revenue",Y21="Please name your Like-for-like Earning Metric",Y21="Valuation Metric",Y21="Please name your Like-for-like Valuation Metric",Y21="Please select your Valuation Metric",Y21="Please select the metric for segmentation",Y21="Untitled Segmentation II",Y21="Untitled Segmentation III"),"",IF(OR(Y21<>AB21,AND(LEN(B21)=0,NOT(OR(Y21="Select, enter text or leave as blank.",Y21="Set from Actual section above!",Y21="Please select or type in or leave as blank",Y21="Select, enter text or leave as blank",Y21="Please select your Top Line Metric",Y21="Check Sum",Y21="Please name your Like-for-Like Revenue",Y21="Please name your Like-for-like Earning Metric",Y21="Valuation Metric",Y21="Please name your Like-for-like Valuation Metric",Y21="Please select your Valuation Metric",Y21="Please select the metric for segmentation",Y21="Untitled Segmentation II",Y21="Untitled Segmentation III")))),_xldudf_CX_PUSH(Y21,CX_ENTITY,C21,EOMONTH(val_asOfDate,3)),"")))} -> #NAME? | CY21: {=IFERROR(IF(CM21*fxVal_normal=_PL!CM21,"",IF(OR($CM21="",$CM21=0,NOT(ISNUMBER($CM21)),ISERROR($CM21),$B21=""),"",IF($I21=1,IFBLANK(_xldudf_CX_PUSH($CM21*fxVal_normal,CX_ENTITY,$B21,$CM$11,$CM$14,$CM$19,),""),IF($I21=2,IFBLANK(_xldudf_CX_PUSH($CM21,CX_ENTITY,$B21,$CM$11,$CM$14,$CM$19,),""),IF($I21=3,"",IFBLANK(_xldudf_CX_PUSH($CM21,CX_ENTITY,$B21,$CM$11,$CM$14,$CM$19,),"")))))),"")} | CZ21: {=IFERROR(IF(CN21*fxVal_normal=_PL!CN21,"",IF(OR($CN21="",$CN21=0,NOT(ISNUMBER($CN21)),ISERROR($CN21),$B21=""),"",IF($I21=1,IFBLANK(_xldudf_CX_PUSH($CN21*fxVal_normal,CX_ENTITY,$B21,$CN$11,$CN$14,$CN$19,),""),IF($I21=2,IFBLANK(_xldudf_CX_PUSH($CN21,CX_ENTITY,$B21,$CN$11,$CN$14,$CN$19,),""),IF($I21=3,"",IFBLANK(_xldudf_CX_PUSH($CN21,CX_ENTITY,$B21,$CN$11,$CN$14,$CN$19,),"")))))),"")} | DA21: {=IFERROR(IF(CP21*fxVal_normal=_PL!CP21,"",IF(OR($CP21="",$CP21=0,NOT(ISNUMBER($CP21)),ISERROR($CP21),$B21=""),"",IF($I21=1,IFBLANK(_xldudf_CX_PUSH($CP21*fxVal_normal,CX_ENTITY,$B21,$CP$11,$CP$14,$CP$19,),""),IF($I21=2,IFBLANK(_xldudf_CX_PUSH($CP21,CX_ENTITY,$B21,$CP$11,$CP$14,$CP$19,),""),IF($I21=3,"",IFBLANK(_xldudf_CX_PUSH($CP21,CX_ENTITY,$B21,$CP$11,$CP$14,$CP$19,),"")))))),"")} | DB21: {=IFERROR(IF(CQ21*fxVal_normal=_PL!CQ21,"",IF(OR($CQ21="",$CQ21=0,NOT(ISNUMBER($CQ21)),ISERROR($CQ21),$B21=""),"",IF($I21=1,IFBLANK(_xldudf_CX_PUSH($CQ21*fxVal_normal,CX_ENTITY,$B21,$CQ$11,$CQ$14,$CQ$19,),""),IF($I21=2,IFBLANK(_xldudf_CX_PUSH($CQ21,CX_ENTITY,$B21,$CQ$11,$CQ$14,$CQ$19,),""),IF($I21=3,"",IFBLANK(_xldudf_CX_PUSH($CQ21,CX_ENTITY,$B21,$CQ$11,$CQ$14,$CQ$19,),"")))))),"")} | DD21: {=IFERROR(IF(AD21*fxVal_normal=_PL!AD21,"",IF(OR(AD21="",NOT(ISNUMBER(AD21)),ISERROR(AD21),$B21=""),"",IF($I21=1,IFBLANK(_xldudf_CX_PUSH(AD21*fxVal_normal,CX_ENTITY,$B21,AD$11,AD$14,AD$19,),""),IF($I21=2,IFBLANK(_xldudf_CX_PUSH(AD21,CX_ENTITY,$B21,AD$11,AD$14,AD$19,),""),IF($I21=3,"",IFBLANK(_xldudf_CX_PUSH(AD21,CX_ENTITY,$B21,AD$11,AD$14,AD$19,),"")))))),"")} | DE21: {=IFERROR(IF(AE21*fxVal_normal=_PL!AE21,"",IF(OR(AE21="",NOT(ISNUMBER(AE21)),ISERROR(AE21),$B21=""),"",IF($I21=1,IFBLANK(_xldudf_CX_PUSH(AE21*fxVal_normal,CX_ENTITY,$B21,AE$11,AE$14,AE$19,),""),IF($I21=2,IFBLANK(_xldudf_CX_PUSH(AE21,CX_ENTITY,$B21,AE$11,AE$14,AE$19,),""),IF($I21=3,"",IFBLANK(_xldudf_CX_PUSH(AE21,CX_ENTITY,$B21,AE$11,AE$14,AE$19,),"")))))),"")} | DF21: {=IFERROR(IF(AF21*fxVal_normal=_PL!AF21,"",IF(OR(AF21="",NOT(ISNUMBER(AF21)),ISERROR(AF21),$B21=""),"",IF($I21=1,IFBLANK(_xldudf_CX_PUSH(AF21*fxVal_normal,CX_ENTITY,$B21,AF$11,AF$14,AF$19,),""),IF($I21=2,IFBLANK(_xldudf_CX_PUSH(AF21,CX_ENTITY,$B21,AF$11,AF$14,AF$19,),""),IF($I21=3,"",IFBLANK(_xldudf_CX_PUSH(AF21,CX_ENTITY,$B21,AF$11,AF$14,AF$19,),"")))))),"")} | DG21: {=IFERROR(IF(AG21*fxVal_normal=_PL!AG21,"",IF(OR(AG21="",NOT(ISNUMBER(AG21)),ISERROR(AG21),$B21=""),"",IF($I21=1,IFBLANK(_xldudf_CX_PUSH(AG21*fxVal_normal,CX_ENTITY,$B21,AG$11,AG$14,AG$19,),""),IF($I21=2,IFBLANK(_xldudf_CX_PUSH(AG21,CX_ENTITY,$B21,AG$11,AG$14,AG$19,),""),IF($I21=3,"",IFBLANK(_xldudf_CX_PUSH(AG21,CX_ENTITY,$B21,AG$11,AG$14,AG$19,),"")))))),"")} | DH21: {=IFERROR(IF(AH21*fxVal_normal=_PL!AH21,"",IF(OR(AH21="",NOT(ISNUMBER(AH21)),ISERROR(AH21),$B21=""),"",IF($I21=1,IFBLANK(_xldudf_CX_PUSH(AH21*fxVal_normal,CX_ENTITY,$B21,AH$11,AH$14,AH$19,),""),IF($I21=2,IFBLANK(_xldudf_CX_PUSH(AH21,CX_ENTITY,$B21,AH$11,AH$14,AH$19,),""),IF($I21=3,"",IFBLANK(_xldudf_CX_PUSH(AH21,CX_ENTITY,$B21,AH$11,AH$14,AH$19,),"")))))),"")} | DI21: {=IFERROR(IF(AI21*fxVal_normal=_PL!AI21,"",IF(OR(AI21="",NOT(ISNUMBER(AI21)),ISERROR(AI21),$B21=""),"",IF($I21=1,IFBLANK(_xldudf_CX_PUSH(AI21*fxVal_normal,CX_ENTITY,$B21,AI$11,AI$14,AI$19,),""),IF($I21=2,IFBLANK(_xldudf_CX_PUSH(AI21,CX_ENTITY,$B21,AI$11,AI$14,AI$19,),""),IF($I21=3,"",IFBLANK(_xldudf_CX_PUSH(AI21,CX_ENTITY,$B21,AI$11,AI$14,AI$19,),"")))))),"")} | DJ21: {=IFERROR(IF(AJ21*fxVal_normal=_PL!AJ21,"",IF(OR(AJ21="",NOT(ISNUMBER(AJ21)),ISERROR(AJ21),$B21=""),"",IF($I21=1,IFBLANK(_xldudf_CX_PUSH(AJ21*fxVal_normal,CX_ENTITY,$B21,AJ$11,AJ$14,AJ$19,),""),IF($I21=2,IFBLANK(_xldudf_CX_PUSH(AJ21,CX_ENTITY,$B21,AJ$11,AJ$14,AJ$19,),""),IF($I21=3,"",IFBLANK(_xldudf_CX_PUSH(AJ21,CX_ENTITY,$B21,AJ$11,AJ$14,AJ$19,),"")))))),"")} | DK21: {=IFERROR(IF(AK21*fxVal_normal=_PL!AK21,"",IF(OR(AK21="",NOT(ISNUMBER(AK21)),ISERROR(AK21),$B21=""),"",IF($I21=1,IFBLANK(_xldudf_CX_PUSH(AK21*fxVal_normal,CX_ENTITY,$B21,AK$11,AK$14,AK$19,),""),IF($I21=2,IFBLANK(_xldudf_CX_PUSH(AK21,CX_ENTITY,$B21,AK$11,AK$14,AK$19,),""),IF($I21=3,"",IFBLANK(_xldudf_CX_PUSH(AK21,CX_ENTITY,$B21,AK$11,AK$14,AK$19,),"")))))),"")} | ... EN21: {=IFERROR(IF(BN21*fxVal_normal=_PL!BN21,"",IF(OR(BN21="",NOT(ISNUMBER(BN21)),ISERROR(BN21),$B21=""),"",IF($I21=1,IFBLANK(_xldudf_CX_PUSH(BN21*fxVal_normal,CX_ENTITY,$B21,BN$11,BN$14,BN$19,),""),IF($I21=2,IFBLANK(_xldudf_CX_PUSH(BN21,CX_ENTITY,$B21,BN$11,BN$14,BN$19,),""),IF($I21=3,"",IFBLANK(_xldudf_CX_PUSH(BN21,CX_ENTITY,$B21,BN$11,BN$14,BN$19,),"")))))),"")}
B22: =_xlfn.LET(_xlpm.IsNotAttrDynamic,D22="",_xlpm.Attr,_PL!F22,_xlpm.NotInUse,Y22=D22,_xlpm.RESULT,IF(_xlpm.IsNotAttrDynamic,_xlpm.Attr,IF(_xlpm.NotInUse,"",Y22)),IF(_xlpm.RESULT="","",_xlpm.RESULT)) -> Gross Profit | C22: {=IFBLANK(_PL!C22,"")} -> Gross Profit (Company View) | E22: {=_xlfn.LAMBDA(_xlpm.Array,_xlop.Type,_xlfn.LET(_xlpm._type,IF(_xlfn.ISOMITTED(_xlpm.Type),0,_xlpm.Type),_xlpm.R,ROWS(_xlpm.Array),_xlpm.C,COLUMNS(_xlpm.Array),_xlpm.Unlocked,_xlfn.MAKEARRAY(_xlpm.R,_xlpm.C,_xlfn.LAMBDA(_xlpm.i,_xlpm.j,--(CELL("protect",INDEX(_xlpm.Array,_xlpm.i,_xlpm.j))=0))),_xlpm.IsUnlocked,_xlfn.MAKEARRAY(_xlpm.R,_xlpm.C,_xlfn.LAMBDA(_xlpm.i,_xlpm.j,CELL("protect",INDEX(_xlpm.Array,_xlpm.i,_xlpm.j))=0)),_xlpm.HasData,_xlpm.Array<>"",_xlpm.Total,SUM(_xlpm.Unlocked),_xlpm.Completed,SUM(--(_xlpm.IsUnlocked*_xlpm.HasData)),_xlpm.type_display,_xlfn.SWITCH(_xlpm._type,1,"R",-1,"O",0,"A",""),_xlfn.HSTACK(_xlpm.Total,_xlpm.Completed,_xlpm.type_display)))($AD22:$CQ22,Z22)} -> #NAME? | H22: 2 | I22: 1 | J22: {=IFBLANK(Z22,"")} -> 0 | K22: =IFERROR(IF(LEN(AB22)=0,"No",IF(LEN(J22)>0,"Yes","No")),"") -> Yes | W22: =$W$20 -> Actual | X22: =_PL!X22 -> 0 | Y22: =IF(_PL!Y22="Error","",_PL!Y22) -> #NAME? | Z22: {=_xlfn.SWITCH(TRUE,_PL!$L22=TRUE,1,_PL!$L22=FALSE,-1,_PL!$L22=-1,0,"")} -> 0 | AB22: =_PL!AB22 -> Gross Profit | AC22: {=_xlfn.LET(_xlpm._termname,$AB22,_xlpm._iconname,"find",_xlpm._icon,fx_getIcon(_xlpm._iconname),_xlpm._location,_xlfn.XLOOKUP(LOWER(_xlpm._termname),LOWER(tbl_acctDef[Term]),tbl_acctDef[Term]),_xlpm._hyperlink,HYPERLINK("#"&CELL("address",_xlpm._location),_xlpm._icon),IFERROR(_xlpm._hyperlink,""))} -> #VALUE! | AD22: =SUBTOTAL(9,AD20:AD21) -> 2 | AE22: =SUBTOTAL(9,AE20:AE21) -> 2 | AF22: =SUBTOTAL(9,AF20:AF21) -> 2 | AG22: =SUBTOTAL(9,AG20:AG21) -> 2 | AH22: =SUBTOTAL(9,AH20:AH21) -> 2 | AI22: =SUBTOTAL(9,AI20:AI21) -> 2 | AJ22: =SUBTOTAL(9,AJ20:AJ21) -> 2 | AK22: =SUBTOTAL(9,AK20:AK21) -> 2 | ... BN22: =SUBTOTAL(9,BN20:BN21) -> 2 | CD22: {=_xlfn.LET(_xlpm.CheckBlank,SUM(PL!$AD22:$BN22)=0,IF(_xlpm.CheckBlank,"",SUM(_xlfn._xlws.FILTER(PL!$AD22:$BN22,(YEAR(PL!$AD$12:$BN$12)=PL!CD$12)*(array_timeline<=PL!CD$11)))))} -> #NAME? | CE22: {=_xlfn.LET(_xlpm.CheckBlank,SUM(PL!$AD22:$BN22)=0,IF(_xlpm.CheckBlank,"",SUM(_xlfn._xlws.FILTER(PL!$AD22:$BN22,(YEAR(PL!$AD$12:$BN$12)=PL!CE$12)*(array_timeline<=PL!CE$11)))))} -> #NAME? | CG22: {=IFERROR(_xlfn.LET(_xlpm.CheckBlank,SUM(PL!$AD22:$BN22)=0,IF(_xlpm.CheckBlank,"",SUM(_xlfn._xlws.FILTER(PL!$AD22:$BN22,(YEAR(PL!$AD$12:$BN$12)=PL!CG$12)*(array_timeline<=PL!CG$11))))),"n/a")} -> n/a | CH22: {=_xlfn.LET(_xlpm.CheckBlank,SUM(PL!$AD22:$BN22)=0,IF(_xlpm.CheckBlank,"",SUM(_xlfn._xlws.FILTER(PL!$AD22:$BN22,(YEAR(PL!$AD$12:$BN$12)=PL!CH$12)*(array_timeline<=PL!CH$11)))))} -> #NAME? | CJ22: {=_xlfn.LET(_xlpm.CheckBlank,SUM(PL!$AD22:$BN22)=0,IF(_xlpm.CheckBlank,"",SUM(_xlfn.TAKE(_xlfn.DROP(PL!$AD22:$BN22,,-DATEDIFF(PL!CJ$11,val_asOfDate,"M")),1,-12))))} -> 24 | CK22: {=_xlfn.LET(_xlpm.CheckBlank,SUM(PL!$AD22:$BN22)=0,IF(_xlpm.CheckBlank,"",SUM(_xlfn.TAKE(_xlfn.DROP(PL!$AD22:$BN22,,-DATEDIFF(PL!CK$11,val_asOfDate,"M")),1,-12))))} -> 24 | CM22: =SUBTOTAL(9,CM20:CM21) -> 2 | CN22: =SUBTOTAL(9,CN20:CN21) -> 2 | CP22: =SUBTOTAL(9,CP20:CP21) -> 2 | CQ22: =SUBTOTAL(9,CQ20:CQ21) -> 2 | CT22: {=IF(K22<>"Yes","",IF(OR(Y22="Select, enter text or leave as blank.",Y22="Set from Actual section above!",Y22="Please select or type in or leave as blank",Y22="Select, enter text or leave as blank",Y22="Please select your Top Line Metric",Y22="Check Sum",Y22="Please name your Like-for-Like Revenue",Y22="Please name your Like-for-like Earning Metric",Y22="Valuation Metric",Y22="Please name your Like-for-like Valuation Metric",Y22="Please select your Valuation Metric",Y22="Please select the metric for segmentation",Y22="Untitled Segmentation II",Y22="Untitled Segmentation III"),"",IF(OR(Y22<>AB22,AND(LEN(B22)=0,NOT(OR(Y22="Select, enter text or leave as blank.",Y22="Set from Actual section above!",Y22="Please select or type in or leave as blank",Y22="Select, enter text or leave as blank",Y22="Please select your Top Line Metric",Y22="Check Sum",Y22="Please name your Like-for-Like Revenue",Y22="Please name your Like-for-like Earning Metric",Y22="Valuation Metric",Y22="Please name your Like-for-like Valuation Metric",Y22="Please select your Valuation Metric",Y22="Please select the metric for segmentation",Y22="Untitled Segmentation II",Y22="Untitled Segmentation III")))),_xldudf_CX_PUSH(Y22,CX_ENTITY,C22,EOMONTH(val_asOfDate,0)),"")))} -> #NAME? | CU22: {=IF(K22<>"Yes","",IF(OR(Y22="Select, enter text or leave as blank.",Y22="Set from Actual section above!",Y22="Please select or type in or leave as blank",Y22="Select, enter text or leave as blank",Y22="Please select your Top Line Metric",Y22="Check Sum",Y22="Please name your Like-for-Like Revenue",Y22="Please name your Like-for-like Earning Metric",Y22="Valuation Metric",Y22="Please name your Like-for-like Valuation Metric",Y22="Please select your Valuation Metric",Y22="Please select the metric for segmentation",Y22="Untitled Segmentation II",Y22="Untitled Segmentation III"),"",IF(OR(Y22<>AB22,AND(LEN(B22)=0,NOT(OR(Y22="Select, enter text or leave as blank.",Y22="Set from Actual section above!",Y22="Please select or type in or leave as blank",Y22="Select, enter text or leave as blank",Y22="Please select your Top Line Metric",Y22="Check Sum",Y22="Please name your Like-for-Like Revenue",Y22="Please name your Like-for-like Earning Metric",Y22="Valuation Metric",Y22="Please name your Like-for-like Valuation Metric",Y22="Please select your Valuation Metric",Y22="Please select the metric for segmentation",Y22="Untitled Segmentation II",Y22="Untitled Segmentation III")))),_xldudf_CX_PUSH(Y22,CX_ENTITY,C22,EOMONTH(val_asOfDate,1)),"")))} -> #NAME? | CV22: {=IF(K22<>"Yes","",IF(OR(Y22="Select, enter text or leave as blank.",Y22="Set from Actual section above!",Y22="Please select or type in or leave as blank",Y22="Select, enter text or leave as blank",Y22="Please select your Top Line Metric",Y22="Check Sum",Y22="Please name your Like-for-Like Revenue",Y22="Please name your Like-for-like Earning Metric",Y22="Valuation Metric",Y22="Please name your Like-for-like Valuation Metric",Y22="Please select your Valuation Metric",Y22="Please select the metric for segmentation",Y22="Untitled Segmentation II",Y22="Untitled Segmentation III"),"",IF(OR(Y22<>AB22,AND(LEN(B22)=0,NOT(OR(Y22="Select, enter text or leave as blank.",Y22="Set from Actual section above!",Y22="Please select or type in or leave as blank",Y22="Select, enter text or leave as blank",Y22="Please select your Top Line Metric",Y22="Check Sum",Y22="Please name your Like-for-Like Revenue",Y22="Please name your Like-for-like Earning Metric",Y22="Valuation Metric",Y22="Please name your Like-for-like Valuation Metric",Y22="Please select your Valuation Metric",Y22="Please select the metric for segmentation",Y22="Untitled Segmentation II",Y22="Untitled Segmentation III")))),_xldudf_CX_PUSH(Y22,CX_ENTITY,C22,EOMONTH(val_asOfDate,2)),"")))} -> #NAME? | CW22: {=IF(K22<>"Yes","",IF(OR(Y22="Select, enter text or leave as blank.",Y22="Set from Actual section above!",Y22="Please select or type in or leave as blank",Y22="Select, enter text or leave as blank",Y22="Please select your Top Line Metric",Y22="Check Sum",Y22="Please name your Like-for-Like Revenue",Y22="Please name your Like-for-like Earning Metric",Y22="Valuation Metric",Y22="Please name your Like-for-like Valuation Metric",Y22="Please select your Valuation Metric",Y22="Please select the metric for segmentation",Y22="Untitled Segmentation II",Y22="Untitled Segmentation III"),"",IF(OR(Y22<>AB22,AND(LEN(B22)=0,NOT(OR(Y22="Select, enter text or leave as blank.",Y22="Set from Actual section above!",Y22="Please select or type in or leave as blank",Y22="Select, enter text or leave as blank",Y22="Please select your Top Line Metric",Y22="Check Sum",Y22="Please name your Like-for-Like Revenue",Y22="Please name your Like-for-like Earning Metric",Y22="Valuation Metric",Y22="Please name your Like-for-like Valuation Metric",Y22="Please select your Valuation Metric",Y22="Please select the metric for segmentation",Y22="Untitled Segmentation II",Y22="Untitled Segmentation III")))),_xldudf_CX_PUSH(Y22,CX_ENTITY,C22,EOMONTH(val_asOfDate,3)),"")))} -> #NAME? | CY22: {=IFERROR(IF(CM22*fxVal_normal=_PL!CM22,"",IF(OR($CM22="",$CM22=0,NOT(ISNUMBER($CM22)),ISERROR($CM22),$B22=""),"",IF($I22=1,IFBLANK(_xldudf_CX_PUSH($CM22*fxVal_normal,CX_ENTITY,$B22,$CM$11,$CM$14,$CM$19,),""),IF($I22=2,IFBLANK(_xldudf_CX_PUSH($CM22,CX_ENTITY,$B22,$CM$11,$CM$14,$CM$19,),""),IF($I22=3,"",IFBLANK(_xldudf_CX_PUSH($CM22,CX_ENTITY,$B22,$CM$11,$CM$14,$CM$19,),"")))))),"")} | CZ22: {=IFERROR(IF(CN22*fxVal_normal=_PL!CN22,"",IF(OR($CN22="",$CN22=0,NOT(ISNUMBER($CN22)),ISERROR($CN22),$B22=""),"",IF($I22=1,IFBLANK(_xldudf_CX_PUSH($CN22*fxVal_normal,CX_ENTITY,$B22,$CN$11,$CN$14,$CN$19,),""),IF($I22=2,IFBLANK(_xldudf_CX_PUSH($CN22,CX_ENTITY,$B22,$CN$11,$CN$14,$CN$19,),""),IF($I22=3,"",IFBLANK(_xldudf_CX_PUSH($CN22,CX_ENTITY,$B22,$CN$11,$CN$14,$CN$19,),"")))))),"")} | DA22: {=IFERROR(IF(CP22*fxVal_normal=_PL!CP22,"",IF(OR($CP22="",$CP22=0,NOT(ISNUMBER($CP22)),ISERROR($CP22),$B22=""),"",IF($I22=1,IFBLANK(_xldudf_CX_PUSH($CP22*fxVal_normal,CX_ENTITY,$B22,$CP$11,$CP$14,$CP$19,),""),IF($I22=2,IFBLANK(_xldudf_CX_PUSH($CP22,CX_ENTITY,$B22,$CP$11,$CP$14,$CP$19,),""),IF($I22=3,"",IFBLANK(_xldudf_CX_PUSH($CP22,CX_ENTITY,$B22,$CP$11,$CP$14,$CP$19,),"")))))),"")} | DB22: {=IFERROR(IF(CQ22*fxVal_normal=_PL!CQ22,"",IF(OR($CQ22="",$CQ22=0,NOT(ISNUMBER($CQ22)),ISERROR($CQ22),$B22=""),"",IF($I22=1,IFBLANK(_xldudf_CX_PUSH($CQ22*fxVal_normal,CX_ENTITY,$B22,$CQ$11,$CQ$14,$CQ$19,),""),IF($I22=2,IFBLANK(_xldudf_CX_PUSH($CQ22,CX_ENTITY,$B22,$CQ$11,$CQ$14,$CQ$19,),""),IF($I22=3,"",IFBLANK(_xldudf_CX_PUSH($CQ22,CX_ENTITY,$B22,$CQ$11,$CQ$14,$CQ$19,),"")))))),"")} | DD22: {=IFERROR(IF(AD22*fxVal_normal=_PL!AD22,"",IF(OR(AD22="",NOT(ISNUMBER(AD22)),ISERROR(AD22),$B22=""),"",IF($I22=1,IFBLANK(_xldudf_CX_PUSH(AD22*fxVal_normal,CX_ENTITY,$B22,AD$11,AD$14,AD$19,),""),IF($I22=2,IFBLANK(_xldudf_CX_PUSH(AD22,CX_ENTITY,$B22,AD$11,AD$14,AD$19,),""),IF($I22=3,"",IFBLANK(_xldudf_CX_PUSH(AD22,CX_ENTITY,$B22,AD$11,AD$14,AD$19,),"")))))),"")} | DE22: {=IFERROR(IF(AE22*fxVal_normal=_PL!AE22,"",IF(OR(AE22="",NOT(ISNUMBER(AE22)),ISERROR(AE22),$B22=""),"",IF($I22=1,IFBLANK(_xldudf_CX_PUSH(AE22*fxVal_normal,CX_ENTITY,$B22,AE$11,AE$14,AE$19,),""),IF($I22=2,IFBLANK(_xldudf_CX_PUSH(AE22,CX_ENTITY,$B22,AE$11,AE$14,AE$19,),""),IF($I22=3,"",IFBLANK(_xldudf_CX_PUSH(AE22,CX_ENTITY,$B22,AE$11,AE$14,AE$19,),"")))))),"")} | DF22: {=IFERROR(IF(AF22*fxVal_normal=_PL!AF22,"",IF(OR(AF22="",NOT(ISNUMBER(AF22)),ISERROR(AF22),$B22=""),"",IF($I22=1,IFBLANK(_xldudf_CX_PUSH(AF22*fxVal_normal,CX_ENTITY,$B22,AF$11,AF$14,AF$19,),""),IF($I22=2,IFBLANK(_xldudf_CX_PUSH(AF22,CX_ENTITY,$B22,AF$11,AF$14,AF$19,),""),IF($I22=3,"",IFBLANK(_xldudf_CX_PUSH(AF22,CX_ENTITY,$B22,AF$11,AF$14,AF$19,),"")))))),"")} | DG22: {=IFERROR(IF(AG22*fxVal_normal=_PL!AG22,"",IF(OR(AG22="",NOT(ISNUMBER(AG22)),ISERROR(AG22),$B22=""),"",IF($I22=1,IFBLANK(_xldudf_CX_PUSH(AG22*fxVal_normal,CX_ENTITY,$B22,AG$11,AG$14,AG$19,),""),IF($I22=2,IFBLANK(_xldudf_CX_PUSH(AG22,CX_ENTITY,$B22,AG$11,AG$14,AG$19,),""),IF($I22=3,"",IFBLANK(_xldudf_CX_PUSH(AG22,CX_ENTITY,$B22,AG$11,AG$14,AG$19,),"")))))),"")} | DH22: {=IFERROR(IF(AH22*fxVal_normal=_PL!AH22,"",IF(OR(AH22="",NOT(ISNUMBER(AH22)),ISERROR(AH22),$B22=""),"",IF($I22=1,IFBLANK(_xldudf_CX_PUSH(AH22*fxVal_normal,CX_ENTITY,$B22,AH$11,AH$14,AH$19,),""),IF($I22=2,IFBLANK(_xldudf_CX_PUSH(AH22,CX_ENTITY,$B22,AH$11,AH$14,AH$19,),""),IF($I22=3,"",IFBLANK(_xldudf_CX_PUSH(AH22,CX_ENTITY,$B22,AH$11,AH$14,AH$19,),"")))))),"")} | DI22: {=IFERROR(IF(AI22*fxVal_normal=_PL!AI22,"",IF(OR(AI22="",NOT(ISNUMBER(AI22)),ISERROR(AI22),$B22=""),"",IF($I22=1,IFBLANK(_xldudf_CX_PUSH(AI22*fxVal_normal,CX_ENTITY,$B22,AI$11,AI$14,AI$19,),""),IF($I22=2,IFBLANK(_xldudf_CX_PUSH(AI22,CX_ENTITY,$B22,AI$11,AI$14,AI$19,),""),IF($I22=3,"",IFBLANK(_xldudf_CX_PUSH(AI22,CX_ENTITY,$B22,AI$11,AI$14,AI$19,),"")))))),"")} | DJ22: {=IFERROR(IF(AJ22*fxVal_normal=_PL!AJ22,"",IF(OR(AJ22="",NOT(ISNUMBER(AJ22)),ISERROR(AJ22),$B22=""),"",IF($I22=1,IFBLANK(_xldudf_CX_PUSH(AJ22*fxVal_normal,CX_ENTITY,$B22,AJ$11,AJ$14,AJ$19,),""),IF($I22=2,IFBLANK(_xldudf_CX_PUSH(AJ22,CX_ENTITY,$B22,AJ$11,AJ$14,AJ$19,),""),IF($I22=3,"",IFBLANK(_xldudf_CX_PUSH(AJ22,CX_ENTITY,$B22,AJ$11,AJ$14,AJ$19,),"")))))),"")} | DK22: {=IFERROR(IF(AK22*fxVal_normal=_PL!AK22,"",IF(OR(AK22="",NOT(ISNUMBER(AK22)),ISERROR(AK22),$B22=""),"",IF($I22=1,IFBLANK(_xldudf_CX_PUSH(AK22*fxVal_normal,CX_ENTITY,$B22,AK$11,AK$14,AK$19,),""),IF($I22=2,IFBLANK(_xldudf_CX_PUSH(AK22,CX_ENTITY,$B22,AK$11,AK$14,AK$19,),""),IF($I22=3,"",IFBLANK(_xldudf_CX_PUSH(AK22,CX_ENTITY,$B22,AK$11,AK$14,AK$19,),"")))))),"")} | ... EN22: {=IFERROR(IF(BN22*fxVal_normal=_PL!BN22,"",IF(OR(BN22="",NOT(ISNUMBER(BN22)),ISERROR(BN22),$B22=""),"",IF($I22=1,IFBLANK(_xldudf_CX_PUSH(BN22*fxVal_normal,CX_ENTITY,$B22,BN$11,BN$14,BN$19,),""),IF($I22=2,IFBLANK(_xldudf_CX_PUSH(BN22,CX_ENTITY,$B22,BN$11,BN$14,BN$19,),""),IF($I22=3,"",IFBLANK(_xldudf_CX_PUSH(BN22,CX_ENTITY,$B22,BN$11,BN$14,BN$19,),"")))))),"")}
